2024-10-02 16:50:32 - Server listening on ('0.0.0.0', 31026)
2024-10-02 16:50:32 - Main thread: before accepting ...
2024-10-02 16:50:40 - New Client number 1 from ('127.0.0.1', 57749)
2024-10-02 17:23:00 - Server listening on ('0.0.0.0', 31026)
2024-10-02 17:23:00 - Main thread: before accepting ...
2024-10-02 17:23:03 - New Client number 1 from ('127.0.0.1', 58019)
2024-10-02 17:23:23 - Traceback (most recent call last):
  File "c:\Users\idanh\Desktop\Cyber\My Projects\Final Project\Main\server\server.py", line 747, in handle_request
    to_send = protocol_build_reply(request, tid, sock)
              ^^^^^^^^^^^^^^^^^^^^^^^^^^^^^^^^^^^^^^^^
  File "c:\Users\idanh\Desktop\Cyber\My Projects\Final Project\Main\server\server.py", line 474, in protocol_build_reply
    files = cr.get_files(clients[tid].id, directory, search_filter)
            ^^^^^^^^^^^^^^^^^^^^^^^^^^^^^^^^^^^^^^^^^^^^^^^^^^^^^^^
  File "c:\Users\idanh\Desktop\Cyber\My Projects\Final Project\Main\server\modules\client_requests.py", line 347, in get_files
    to_add += "~" + "~".join(get_perms(owner_id, file.id))
                    ^^^^^^^^^^^^^^^^^^^^^^^^^^^^^^^^^^^^^^
TypeError: can only join an iterable
2024-10-02 17:23:57 - Server listening on ('0.0.0.0', 31026)
2024-10-02 17:23:58 - Main thread: before accepting ...
2024-10-02 17:23:58 - New Client number 1 from ('127.0.0.1', 58042)
2024-10-02 17:28:48 - Client 1 Exit
2024-10-02 17:28:49 - New Client number 2 from ('127.0.0.1', 58074)
2024-10-02 17:29:10 - Client 2 Exit
2024-10-02 17:29:11 - New Client number 3 from ('127.0.0.1', 58090)
2024-10-02 17:29:19 - Client 3 Exit
2024-10-02 17:29:20 - New Client number 4 from ('127.0.0.1', 58098)
2024-10-02 17:30:40 - Client 4 Exit
2024-10-02 17:30:41 - New Client number 5 from ('127.0.0.1', 58111)
2024-10-02 17:30:58 - Client 5 Exit
2024-10-02 17:30:59 - New Client number 6 from ('127.0.0.1', 58120)
2024-10-02 17:33:14 - Client 6 Exit
2024-10-02 17:33:15 - New Client number 7 from ('127.0.0.1', 58160)
2024-10-02 17:33:49 - Client 7 Exit
2024-10-02 17:33:50 - New Client number 8 from ('127.0.0.1', 58173)
2024-10-02 17:34:23 - Client 8 Exit
2024-10-02 17:34:24 - New Client number 9 from ('127.0.0.1', 58185)
2024-10-02 17:35:32 - Client 9 Exit
2024-10-02 17:35:33 - New Client number 10 from ('127.0.0.1', 58199)
2024-10-02 17:35:41 - Client 10 Exit
2024-10-02 17:35:42 - New Client number 11 from ('127.0.0.1', 58208)
2024-10-02 17:36:18 - Client 11 Exit
2024-10-02 17:36:19 - New Client number 12 from ('127.0.0.1', 58216)
2024-10-02 17:37:08 - Client 12 Exit
2024-10-02 17:37:09 - New Client number 13 from ('127.0.0.1', 58229)
2024-10-02 17:37:42 - Client 13 Exit
2024-10-02 17:37:43 - New Client number 14 from ('127.0.0.1', 58238)
2024-10-02 17:37:49 - Client 14 Exit
2024-10-02 17:37:50 - New Client number 15 from ('127.0.0.1', 58248)
2024-10-02 17:38:15 - Client 15 Exit
2024-10-02 17:38:16 - New Client number 16 from ('127.0.0.1', 58262)
2024-10-02 17:38:34 - Client 16 Exit
2024-10-02 17:38:34 - New Client number 17 from ('127.0.0.1', 58276)
2024-10-02 17:41:04 - Client 17 Exit
2024-10-02 17:41:04 - New Client number 18 from ('127.0.0.1', 58293)
2024-10-02 17:41:15 - Client 18 Exit
2024-10-02 17:41:16 - New Client number 19 from ('127.0.0.1', 58304)
2024-10-02 17:41:27 - Client 19 Exit
2024-10-02 17:41:28 - New Client number 20 from ('127.0.0.1', 58312)
2024-10-02 17:41:37 - Client 20 Exit
2024-10-02 17:41:38 - New Client number 21 from ('127.0.0.1', 58325)
2024-10-02 17:41:45 - Client 21 Exit
2024-10-02 17:41:46 - New Client number 22 from ('127.0.0.1', 58336)
2024-10-02 17:41:53 - Client 22 Exit
2024-10-02 17:41:53 - New Client number 23 from ('127.0.0.1', 58347)
2024-10-02 17:42:03 - Client 23 Exit
2024-10-02 17:42:03 - New Client number 24 from ('127.0.0.1', 58358)
2024-10-02 17:42:09 - Client 24 Exit
2024-10-02 17:42:10 - New Client number 25 from ('127.0.0.1', 58366)
2024-10-02 17:42:18 - Client 25 Exit
2024-10-02 17:42:19 - New Client number 26 from ('127.0.0.1', 58375)
2024-10-02 17:49:24 - Server listening on ('0.0.0.0', 31026)
2024-10-02 17:49:24 - Main thread: before accepting ...
2024-10-02 17:49:27 - New Client number 1 from ('127.0.0.1', 58449)
2024-10-02 17:49:30 - Traceback (most recent call last):
  File "c:\Users\idanh\Desktop\Cyber\My Projects\Final Project\Main\server\server.py", line 747, in handle_request
    to_send = protocol_build_reply(request, tid, sock)
              ^^^^^^^^^^^^^^^^^^^^^^^^^^^^^^^^^^^^^^^^
  File "c:\Users\idanh\Desktop\Cyber\My Projects\Final Project\Main\server\server.py", line 625, in protocol_build_reply
    used_storage = cr.get_user_storage(clients[tid].id)
                   ^^^^^^^^^^^^^^^^^^^^^^^^^^^^^^^^^^^^
  File "c:\Users\idanh\Desktop\Cyber\My Projects\Final Project\Main\server\modules\client_requests.py", line 551, in get_user_storage
    total += directory_size(id, "")
             ^^^^^^^^^^^^^^^^^^^^^^
  File "c:\Users\idanh\Desktop\Cyber\My Projects\Final Project\Main\server\modules\client_requests.py", line 539, in directory_size
    files = db.get_user_directory_files(user_id, id)
            ^^^^^^^^^^^^^^^^^^^^^^^^^^^^^^^^^^^^^^^^
  File "c:\Users\idanh\Desktop\Cyber\My Projects\Final Project\Main\server\modules\database_handling.py", line 370, in get_user_directory_files
    cursor.execute(f"SELECT * FROM {files_table} WHERE owner_id = ? parent = ?", (user_id, parent_id))
sqlite3.OperationalError: near "parent": syntax error
2024-10-02 17:50:07 - Traceback (most recent call last):
  File "c:\Users\idanh\Desktop\Cyber\My Projects\Final Project\Main\server\server.py", line 747, in handle_request
    to_send = protocol_build_reply(request, tid, sock)
              ^^^^^^^^^^^^^^^^^^^^^^^^^^^^^^^^^^^^^^^^
  File "c:\Users\idanh\Desktop\Cyber\My Projects\Final Project\Main\server\server.py", line 625, in protocol_build_reply
    used_storage = cr.get_user_storage(clients[tid].id)
                   ^^^^^^^^^^^^^^^^^^^^^^^^^^^^^^^^^^^^
  File "c:\Users\idanh\Desktop\Cyber\My Projects\Final Project\Main\server\modules\client_requests.py", line 551, in get_user_storage
    total += directory_size(id, "")
             ^^^^^^^^^^^^^^^^^^^^^^
  File "c:\Users\idanh\Desktop\Cyber\My Projects\Final Project\Main\server\modules\client_requests.py", line 539, in directory_size
    files = db.get_user_directory_files(user_id, id)
            ^^^^^^^^^^^^^^^^^^^^^^^^^^^^^^^^^^^^^^^^
  File "c:\Users\idanh\Desktop\Cyber\My Projects\Final Project\Main\server\modules\database_handling.py", line 370, in get_user_directory_files
    cursor.execute(f"SELECT * FROM {files_table} WHERE owner_id = ? parent = ?", (user_id, parent_id))
sqlite3.OperationalError: near "parent": syntax error
2024-10-02 17:50:15 - Traceback (most recent call last):
  File "c:\Users\idanh\Desktop\Cyber\My Projects\Final Project\Main\server\server.py", line 747, in handle_request
    to_send = protocol_build_reply(request, tid, sock)
              ^^^^^^^^^^^^^^^^^^^^^^^^^^^^^^^^^^^^^^^^
  File "c:\Users\idanh\Desktop\Cyber\My Projects\Final Project\Main\server\server.py", line 625, in protocol_build_reply
    used_storage = cr.get_user_storage(clients[tid].id)
                   ^^^^^^^^^^^^^^^^^^^^^^^^^^^^^^^^^^^^
  File "c:\Users\idanh\Desktop\Cyber\My Projects\Final Project\Main\server\modules\client_requests.py", line 551, in get_user_storage
    total += directory_size(id, "")
             ^^^^^^^^^^^^^^^^^^^^^^
  File "c:\Users\idanh\Desktop\Cyber\My Projects\Final Project\Main\server\modules\client_requests.py", line 539, in directory_size
    files = db.get_user_directory_files(user_id, id)
            ^^^^^^^^^^^^^^^^^^^^^^^^^^^^^^^^^^^^^^^^
  File "c:\Users\idanh\Desktop\Cyber\My Projects\Final Project\Main\server\modules\database_handling.py", line 370, in get_user_directory_files
    cursor.execute(f"SELECT * FROM {files_table} WHERE owner_id = ? parent = ?", (user_id, parent_id))
sqlite3.OperationalError: near "parent": syntax error
2024-10-02 17:50:48 - Traceback (most recent call last):
  File "c:\Users\idanh\Desktop\Cyber\My Projects\Final Project\Main\server\server.py", line 747, in handle_request
    to_send = protocol_build_reply(request, tid, sock)
              ^^^^^^^^^^^^^^^^^^^^^^^^^^^^^^^^^^^^^^^^
  File "c:\Users\idanh\Desktop\Cyber\My Projects\Final Project\Main\server\server.py", line 625, in protocol_build_reply
    used_storage = cr.get_user_storage(clients[tid].id)
                   ^^^^^^^^^^^^^^^^^^^^^^^^^^^^^^^^^^^^
  File "c:\Users\idanh\Desktop\Cyber\My Projects\Final Project\Main\server\modules\client_requests.py", line 551, in get_user_storage
    total += directory_size(id, "")
             ^^^^^^^^^^^^^^^^^^^^^^
  File "c:\Users\idanh\Desktop\Cyber\My Projects\Final Project\Main\server\modules\client_requests.py", line 539, in directory_size
    files = db.get_user_directory_files(user_id, id)
            ^^^^^^^^^^^^^^^^^^^^^^^^^^^^^^^^^^^^^^^^
  File "c:\Users\idanh\Desktop\Cyber\My Projects\Final Project\Main\server\modules\database_handling.py", line 370, in get_user_directory_files
    cursor.execute(f"SELECT * FROM {files_table} WHERE owner_id = ? parent = ?", (user_id, parent_id))
sqlite3.OperationalError: near "parent": syntax error
2024-10-02 17:51:34 - Server listening on ('0.0.0.0', 31026)
2024-10-02 17:51:35 - Main thread: before accepting ...
2024-10-02 17:51:35 - New Client number 1 from ('127.0.0.1', 58477)
2024-10-02 17:55:00 - Server listening on ('0.0.0.0', 31026)
2024-10-02 17:55:00 - Main thread: before accepting ...
2024-10-03 18:59:41 - Server listening on ('0.0.0.0', 31026)
2024-10-03 18:59:41 - Main thread: before accepting ...
2024-10-03 18:59:44 - New Client number 1 from ('127.0.0.1', 53628)
2024-10-03 19:02:38 - Client 1 Exit
2024-10-03 19:02:42 - New Client number 2 from ('127.0.0.1', 53681)
2024-10-03 19:12:27 - Server listening on ('0.0.0.0', 31026)
2024-10-03 19:12:27 - Main thread: before accepting ...
2024-10-03 19:12:27 - New Client number 1 from ('127.0.0.1', 53752)
2024-10-03 19:13:17 - Server listening on ('0.0.0.0', 31026)
2024-10-03 19:13:18 - Main thread: before accepting ...
2024-10-03 19:13:18 - New Client number 1 from ('127.0.0.1', 53774)
2024-10-03 19:14:30 - Server listening on ('0.0.0.0', 31026)
2024-10-03 19:14:30 - Main thread: before accepting ...
2024-10-03 19:14:31 - New Client number 1 from ('127.0.0.1', 53800)
2024-10-03 19:16:47 - Client 1 Exit
2024-10-03 19:21:41 - Server listening on ('0.0.0.0', 31026)
2024-10-03 19:21:41 - Main thread: before accepting ...
2024-10-03 19:21:44 - New Client number 1 from ('127.0.0.1', 54413)
2024-10-03 19:24:05 - Server listening on ('0.0.0.0', 31026)
2024-10-03 19:24:05 - Main thread: before accepting ...
2024-10-03 19:24:05 - New Client number 1 from ('127.0.0.1', 54440)
2024-10-03 19:24:47 - Client 1 Exit
2024-10-03 19:24:48 - New Client number 2 from ('127.0.0.1', 54448)
2024-10-03 19:28:50 - Client 2 Exit
2024-10-03 19:28:51 - New Client number 3 from ('127.0.0.1', 54474)
2024-10-03 19:40:30 - Client 3 Exit
2024-10-03 19:40:31 - New Client number 4 from ('127.0.0.1', 54580)
2024-10-03 19:43:38 - Client 4 Exit
2024-10-03 19:43:39 - New Client number 5 from ('127.0.0.1', 54594)
2024-10-03 19:44:52 - Client 5 Exit
2024-10-03 19:44:53 - New Client number 6 from ('127.0.0.1', 54626)
2024-10-03 19:45:10 - Client 6 Exit
2024-10-03 19:45:11 - New Client number 7 from ('127.0.0.1', 54641)
2024-10-03 19:52:39 - Client 7 Exit
2024-10-03 19:52:40 - New Client number 8 from ('127.0.0.1', 54747)
2024-10-03 19:59:52 - Client 8 Exit
2024-10-03 19:59:53 - New Client number 9 from ('127.0.0.1', 54777)
2024-10-03 20:00:24 - Client 9 Exit
2024-10-03 20:00:25 - New Client number 10 from ('127.0.0.1', 54803)
2024-10-03 20:15:39 - Client 10 Exit
2024-10-03 20:18:48 - New Client number 11 from ('127.0.0.1', 54972)
2024-10-03 20:18:51 - Client 11 Exit
2024-10-03 20:19:18 - New Client number 12 from ('127.0.0.1', 54983)
2024-10-03 20:20:39 - Server listening on ('0.0.0.0', 31026)
2024-10-03 20:20:40 - Main thread: before accepting ...
2024-10-03 20:20:40 - New Client number 1 from ('127.0.0.1', 55007)
2024-10-03 20:23:22 - Client 1 Exit
2024-10-03 20:23:23 - New Client number 2 from ('127.0.0.1', 55027)
2024-10-03 20:23:29 - Client 2 Exit
2024-10-03 20:23:39 - New Client number 3 from ('127.0.0.1', 55040)
2024-10-03 20:24:16 - Client 3 Exit
2024-10-03 20:24:17 - New Client number 4 from ('127.0.0.1', 55053)
2024-10-03 20:25:27 - Client 4 Exit
2024-10-03 20:25:28 - New Client number 5 from ('127.0.0.1', 55069)
2024-10-03 20:25:35 - Client 5 Exit
2024-10-03 20:25:36 - New Client number 6 from ('127.0.0.1', 55077)
2024-10-03 20:25:42 - Client 6 Exit
2024-10-03 20:27:01 - New Client number 7 from ('127.0.0.1', 55095)
2024-10-03 20:27:21 - Client 7 Exit
2024-10-03 20:27:21 - New Client number 8 from ('127.0.0.1', 55105)
2024-10-03 20:27:27 - Client 8 Exit
2024-10-03 20:27:35 - New Client number 9 from ('127.0.0.1', 55115)
2024-10-03 20:27:40 - Client 9 Exit
2024-10-03 20:27:56 - New Client number 10 from ('127.0.0.1', 55127)
2024-10-03 20:43:12 - Client 10 Exit
2024-10-03 20:43:13 - New Client number 11 from ('127.0.0.1', 55279)
2024-10-03 20:44:00 - Client 11 Exit
2024-10-03 20:44:00 - New Client number 12 from ('127.0.0.1', 55291)
2024-10-03 20:44:36 - Client 12 Exit
2024-10-03 20:44:37 - New Client number 13 from ('127.0.0.1', 55303)
2024-10-03 20:45:20 - Client 13 Exit
2024-10-03 20:45:21 - New Client number 14 from ('127.0.0.1', 55324)
2024-10-03 20:45:36 - Client 14 Exit
2024-10-03 20:45:36 - New Client number 15 from ('127.0.0.1', 55335)
2024-10-03 20:46:38 - Client 15 Exit
2024-10-03 20:46:39 - New Client number 16 from ('127.0.0.1', 55349)
2024-10-03 20:48:46 - Client 16 Exit
2024-10-03 20:48:47 - New Client number 17 from ('127.0.0.1', 55407)
2024-10-03 20:49:14 - Client 17 Exit
2024-10-03 20:49:15 - New Client number 18 from ('127.0.0.1', 55419)
2024-10-03 20:51:04 - Client 18 Exit
2024-10-03 20:51:05 - New Client number 19 from ('127.0.0.1', 55446)
2024-10-03 20:51:42 - Client 19 Exit
2024-10-03 20:51:43 - New Client number 20 from ('127.0.0.1', 55455)
2024-10-03 20:53:01 - Client 20 Exit
2024-10-03 20:53:01 - New Client number 21 from ('127.0.0.1', 55471)
2024-10-04 00:34:57 - Client 21 Exit
2024-10-04 00:34:57 - New Client number 22 from ('127.0.0.1', 55705)
2024-10-04 00:35:28 - Client 22 Exit
2024-10-04 00:35:29 - New Client number 23 from ('127.0.0.1', 55714)
2024-10-04 00:35:37 - Client 23 Exit
2024-10-04 00:35:38 - New Client number 24 from ('127.0.0.1', 55723)
2024-10-04 00:36:44 - Client 24 Exit
2024-10-04 00:36:45 - New Client number 25 from ('127.0.0.1', 55735)
2024-10-04 00:36:50 - Client 25 Exit
2024-10-04 00:37:17 - New Client number 26 from ('127.0.0.1', 55759)
2024-10-04 00:37:23 - Client 26 Exit
2024-10-04 00:38:35 - New Client number 27 from ('127.0.0.1', 55776)
2024-10-04 00:38:39 - Client 27 Exit
2024-10-04 00:38:45 - New Client number 28 from ('127.0.0.1', 55788)
2024-10-04 00:43:01 - New Client number 29 from ('127.0.0.1', 55820)
2024-10-04 00:43:24 - New Client number 30 from ('127.0.0.1', 55836)
2024-10-04 00:51:35 - Client 30 Exit
2024-10-04 00:51:36 - Client 29 Exit
2024-10-04 00:51:36 - Client 28 Exit
2024-10-04 00:51:38 - New Client number 31 from ('127.0.0.1', 55946)
2024-10-04 00:51:40 - Client 31 Exit
2024-10-04 00:51:59 - New Client number 32 from ('127.0.0.1', 55961)
2024-10-04 00:56:57 - Client 32 Exit
2024-10-04 00:57:25 - New Client number 33 from ('127.0.0.1', 56001)
2024-10-04 00:57:30 - Client 33 Exit
2024-10-04 00:57:34 - New Client number 34 from ('127.0.0.1', 56011)
2024-10-04 00:58:54 - New Client number 35 from ('127.0.0.1', 56023)
2024-10-04 00:59:36 - New Client number 36 from ('127.0.0.1', 56037)
2024-10-04 00:59:41 - Client 36 Exit
2024-10-04 01:04:34 - Client 34 Exit
2024-10-04 01:04:35 - Client 35 Exit
2024-10-04 01:04:43 - New Client number 37 from ('127.0.0.1', 56117)
2024-10-04 01:10:54 - Client 37 Exit
2024-10-04 01:10:55 - New Client number 38 from ('127.0.0.1', 56251)
2024-10-04 01:11:19 - Client 38 Exit
2024-10-04 01:11:19 - New Client number 39 from ('127.0.0.1', 56259)
2024-10-04 01:11:39 - Client 39 Exit
2024-10-04 01:11:39 - New Client number 40 from ('127.0.0.1', 56276)
2024-10-04 01:14:17 - Client 40 Exit
2024-10-04 01:14:17 - New Client number 41 from ('127.0.0.1', 56314)
2024-10-04 01:14:49 - Client 41 Exit
2024-10-04 01:14:50 - New Client number 42 from ('127.0.0.1', 56324)
2024-10-04 01:15:54 - Client 42 Exit
2024-10-04 01:15:55 - New Client number 43 from ('127.0.0.1', 56342)
2024-10-04 01:16:07 - Client 43 Exit
2024-10-04 01:16:07 - New Client number 44 from ('127.0.0.1', 56354)
2024-10-04 01:16:29 - Client 44 Exit
2024-10-04 01:16:30 - New Client number 45 from ('127.0.0.1', 56368)
2024-10-04 01:17:04 - Client 45 Exit
2024-10-04 01:17:04 - New Client number 46 from ('127.0.0.1', 56378)
2024-10-04 01:18:14 - Client 46 Exit
2024-10-04 01:18:14 - New Client number 47 from ('127.0.0.1', 56397)
2024-10-04 01:19:09 - Client 47 Exit
2024-10-04 01:19:09 - New Client number 48 from ('127.0.0.1', 56417)
2024-10-04 01:21:08 - Client 48 Exit
2024-10-04 01:21:09 - New Client number 49 from ('127.0.0.1', 56440)
2024-10-04 01:21:13 - Client 49 Exit
2024-10-04 01:22:00 - New Client number 50 from ('127.0.0.1', 56461)
2024-10-04 01:22:48 - Client 50 Exit
2024-10-04 01:22:49 - New Client number 51 from ('127.0.0.1', 56474)
2024-10-04 01:22:54 - Client 51 Exit
2024-10-04 01:23:21 - New Client number 52 from ('127.0.0.1', 56486)
2024-10-04 01:23:26 - Client 52 Exit
2024-10-04 01:23:55 - New Client number 53 from ('127.0.0.1', 56499)
2024-10-04 01:24:28 - Client 53 Exit
2024-10-04 01:24:29 - New Client number 54 from ('127.0.0.1', 56509)
2024-10-04 01:25:03 - Client 54 Exit
2024-10-04 01:25:04 - New Client number 55 from ('127.0.0.1', 56519)
2024-10-04 01:26:02 - Client 55 Exit
2024-10-04 01:26:02 - New Client number 56 from ('127.0.0.1', 56534)
2024-10-04 01:27:19 - Client 56 Exit
2024-10-04 01:27:20 - New Client number 57 from ('127.0.0.1', 56550)
2024-10-04 01:27:53 - Client 57 Exit
2024-10-04 01:27:54 - New Client number 58 from ('127.0.0.1', 56567)
2024-10-04 01:28:40 - Client 58 Exit
2024-10-04 01:28:41 - New Client number 59 from ('127.0.0.1', 56581)
2024-10-04 01:31:58 - Client 59 Exit
2024-10-04 01:31:59 - New Client number 60 from ('127.0.0.1', 56612)
2024-10-04 01:32:18 - Client 60 Exit
2024-10-04 01:32:19 - New Client number 61 from ('127.0.0.1', 56623)
2024-10-04 01:34:04 - Client 61 Exit
2024-10-04 01:34:05 - New Client number 62 from ('127.0.0.1', 56635)
2024-10-04 01:35:08 - Client 62 Exit
2024-10-04 01:35:08 - New Client number 63 from ('127.0.0.1', 56649)
2024-10-04 01:35:21 - Client 63 Exit
2024-10-04 01:35:21 - New Client number 64 from ('127.0.0.1', 56661)
2024-10-04 01:36:24 - Client 64 Exit
2024-10-04 01:36:24 - New Client number 65 from ('127.0.0.1', 56680)
2024-10-04 01:36:28 - Client 65 Exit
2024-10-04 01:36:56 - New Client number 66 from ('127.0.0.1', 56692)
2024-10-04 01:39:25 - Client 66 Exit
2024-10-04 01:39:25 - New Client number 67 from ('127.0.0.1', 56715)
2024-10-04 01:40:14 - Client 67 Exit
2024-10-04 01:40:15 - New Client number 68 from ('127.0.0.1', 56728)
2024-10-04 01:41:56 - Client 68 Exit
2024-10-04 01:41:57 - New Client number 69 from ('127.0.0.1', 56745)
2024-10-04 01:42:33 - Client 69 Exit
2024-10-04 01:42:34 - New Client number 70 from ('127.0.0.1', 56761)
2024-10-04 01:43:10 - Client 70 Exit
2024-10-04 01:43:10 - New Client number 71 from ('127.0.0.1', 56773)
2024-10-04 01:43:25 - Client 71 Exit
2024-10-04 01:43:26 - New Client number 72 from ('127.0.0.1', 56782)
2024-10-04 01:51:20 - Server listening on ('0.0.0.0', 31026)
2024-10-04 01:51:20 - Main thread: before accepting ...
2024-10-04 01:51:23 - New Client number 1 from ('127.0.0.1', 49878)
2024-10-04 01:54:21 - New Client number 2 from ('127.0.0.1', 49974)
2024-10-04 01:54:39 - Client 1 Exit
2024-10-04 01:54:40 - New Client number 3 from ('127.0.0.1', 49984)
2024-10-04 01:54:45 - Client 3 Exit
2024-10-04 01:54:56 - New Client number 4 from ('127.0.0.1', 49998)
2024-10-04 01:55:32 - Client 4 Exit
2024-10-04 01:55:33 - New Client number 5 from ('127.0.0.1', 50072)
2024-10-04 01:55:46 - Client 5 Exit
2024-10-04 01:56:55 - New Client number 6 from ('127.0.0.1', 50103)
2024-10-04 02:00:17 - Client 6 Exit
2024-10-04 02:00:17 - New Client number 7 from ('127.0.0.1', 50144)
2024-10-04 02:02:29 - Client 7 Exit
2024-10-04 02:02:30 - New Client number 8 from ('127.0.0.1', 50176)
2024-10-04 02:03:01 - New Client number 9 from ('127.0.0.1', 50191)
2024-10-04 02:03:15 - Client 9 Exit
2024-10-04 02:03:16 - New Client number 10 from ('127.0.0.1', 50202)
2024-10-04 02:04:14 - Client 10 Exit
2024-10-04 02:04:14 - New Client number 11 from ('127.0.0.1', 50217)
2024-10-04 02:05:25 - Client 11 Exit
2024-10-04 02:05:26 - New Client number 12 from ('127.0.0.1', 50230)
2024-10-04 02:05:58 - Client 12 Exit
2024-10-04 02:05:59 - New Client number 13 from ('127.0.0.1', 50248)
2024-10-04 02:06:39 - Client 13 Exit
2024-10-04 02:06:40 - New Client number 14 from ('127.0.0.1', 50267)
2024-10-04 02:07:02 - Client 14 Exit
2024-10-04 02:07:02 - New Client number 15 from ('127.0.0.1', 50282)
2024-10-04 02:07:33 - Client 15 Exit
2024-10-04 02:07:34 - New Client number 16 from ('127.0.0.1', 50294)
2024-10-04 02:07:46 - Client 16 Exit
2024-10-04 02:07:47 - New Client number 17 from ('127.0.0.1', 50307)
2024-10-04 02:09:28 - Client 17 Exit
2024-10-04 02:09:28 - New Client number 18 from ('127.0.0.1', 50319)
2024-10-04 02:09:58 - Client 18 Exit
2024-10-04 02:09:59 - New Client number 19 from ('127.0.0.1', 50334)
2024-10-04 02:10:24 - Client 19 Exit
2024-10-04 02:10:25 - New Client number 20 from ('127.0.0.1', 50346)
2024-10-04 02:10:52 - Client 20 Exit
2024-10-04 02:10:52 - New Client number 21 from ('127.0.0.1', 50359)
2024-10-04 02:11:11 - Client 21 Exit
2024-10-04 02:11:11 - New Client number 22 from ('127.0.0.1', 50374)
2024-10-04 02:11:36 - Client 22 Exit
2024-10-04 02:11:36 - New Client number 23 from ('127.0.0.1', 50387)
2024-10-04 02:13:07 - Client 23 Exit
2024-10-04 02:13:07 - New Client number 24 from ('127.0.0.1', 50403)
2024-10-04 02:14:11 - Client 24 Exit
2024-10-04 02:14:12 - New Client number 25 from ('127.0.0.1', 50418)
2024-10-04 02:14:28 - Client 25 Exit
2024-10-04 02:14:28 - New Client number 26 from ('127.0.0.1', 50430)
2024-10-04 02:15:24 - Client 26 Exit
2024-10-04 02:15:25 - New Client number 27 from ('127.0.0.1', 50442)
2024-10-04 02:16:08 - Client 27 Exit
2024-10-04 02:16:09 - New Client number 28 from ('127.0.0.1', 50458)
2024-10-04 02:16:37 - Client 28 Exit
2024-10-04 02:16:37 - New Client number 29 from ('127.0.0.1', 50469)
2024-10-04 02:17:08 - Client 29 Exit
2024-10-04 02:17:08 - New Client number 30 from ('127.0.0.1', 50488)
2024-10-04 02:17:30 - Client 30 Exit
2024-10-04 02:17:30 - New Client number 31 from ('127.0.0.1', 50500)
2024-10-04 02:17:40 - Client 31 Exit
2024-10-04 02:17:40 - New Client number 32 from ('127.0.0.1', 50511)
2024-10-04 02:19:18 - Client 32 Exit
2024-10-04 11:10:11 - Server listening on ('0.0.0.0', 31026)
2024-10-04 11:10:11 - Main thread: before accepting ...
2024-10-04 11:10:12 - New Client number 1 from ('127.0.0.1', 55322)
2024-10-04 11:10:46 - Client 1 Exit
2024-10-04 11:10:47 - New Client number 2 from ('127.0.0.1', 55336)
2024-10-04 11:12:15 - Client 2 Exit
2024-10-04 11:12:16 - New Client number 3 from ('127.0.0.1', 55361)
2024-10-04 11:12:34 - Client 3 Exit
2024-10-04 11:12:35 - New Client number 4 from ('127.0.0.1', 55387)
2024-10-04 11:13:02 - Client 4 Exit
2024-10-04 11:13:02 - New Client number 5 from ('127.0.0.1', 55471)
2024-10-04 11:14:38 - Client 5 Exit
2024-10-04 11:14:48 - New Client number 6 from ('127.0.0.1', 55507)
2024-10-04 11:15:20 - Client 6 Exit
2024-10-04 11:15:20 - New Client number 7 from ('127.0.0.1', 55539)
2024-10-04 11:15:58 - Client 7 Exit
2024-10-04 11:15:59 - New Client number 8 from ('127.0.0.1', 55584)
2024-10-04 11:16:24 - Client 8 Exit
2024-10-04 11:16:24 - New Client number 9 from ('127.0.0.1', 55599)
2024-10-04 11:16:29 - Client 9 Exit
2024-10-04 11:16:30 - New Client number 10 from ('127.0.0.1', 55610)
2024-10-04 11:17:22 - Client 10 Exit
2024-10-04 11:17:23 - New Client number 11 from ('127.0.0.1', 55624)
2024-10-04 11:18:13 - Client 11 Exit
2024-10-04 11:18:14 - New Client number 12 from ('127.0.0.1', 55637)
2024-10-04 11:18:41 - Client 12 Exit
2024-10-04 11:18:41 - New Client number 13 from ('127.0.0.1', 55648)
2024-10-04 11:19:53 - Client 13 Exit
2024-10-04 11:19:54 - New Client number 14 from ('127.0.0.1', 55689)
2024-10-04 11:20:08 - Client 14 Exit
2024-10-04 11:20:09 - New Client number 15 from ('127.0.0.1', 55702)
2024-10-04 11:20:16 - Client 15 Exit
2024-10-04 11:20:16 - New Client number 16 from ('127.0.0.1', 55715)
2024-10-04 11:21:13 - Client 16 Exit
2024-10-04 11:21:14 - New Client number 17 from ('127.0.0.1', 55727)
2024-10-04 11:21:18 - Client 17 Exit
2024-10-04 11:21:46 - New Client number 18 from ('127.0.0.1', 55743)
2024-10-04 11:22:48 - Client 18 Exit
2024-10-04 11:22:49 - New Client number 19 from ('127.0.0.1', 55764)
2024-10-04 11:23:15 - Client 19 Exit
2024-10-04 11:23:16 - New Client number 20 from ('127.0.0.1', 55780)
2024-10-04 11:23:50 - Client 20 Exit
2024-10-04 11:23:51 - New Client number 21 from ('127.0.0.1', 55792)
2024-10-04 11:24:23 - Client 21 Exit
2024-10-04 11:24:23 - New Client number 22 from ('127.0.0.1', 55805)
2024-10-04 11:24:27 - Client 22 Exit
2024-10-04 11:24:47 - New Client number 23 from ('127.0.0.1', 55833)
2024-10-04 11:26:44 - Client 23 Exit
2024-10-04 11:26:44 - New Client number 24 from ('127.0.0.1', 55853)
2024-10-04 11:27:10 - Client 24 Exit
2024-10-04 11:27:11 - New Client number 25 from ('127.0.0.1', 55870)
2024-10-04 11:27:33 - Client 25 Exit
2024-10-04 11:27:34 - New Client number 26 from ('127.0.0.1', 55882)
2024-10-04 11:28:06 - Client 26 Exit
2024-10-04 11:28:06 - New Client number 27 from ('127.0.0.1', 55897)
2024-10-04 11:28:22 - Client 27 Exit
2024-10-04 11:28:23 - New Client number 28 from ('127.0.0.1', 55909)
2024-10-04 11:29:14 - Client 28 Exit
2024-10-04 11:29:15 - New Client number 29 from ('127.0.0.1', 55924)
2024-10-04 11:30:54 - Client 29 Exit
2024-10-04 11:30:54 - New Client number 30 from ('127.0.0.1', 55951)
2024-10-04 11:32:09 - Client 30 Exit
2024-10-04 11:32:09 - New Client number 31 from ('127.0.0.1', 55968)
2024-10-04 11:32:24 - Client 31 Exit
2024-10-04 11:32:25 - New Client number 32 from ('127.0.0.1', 55979)
2024-10-04 11:33:38 - Client 32 Exit
2024-10-04 11:33:39 - New Client number 33 from ('127.0.0.1', 55994)
2024-10-04 11:34:36 - Client 33 Exit
2024-10-04 11:34:37 - New Client number 34 from ('127.0.0.1', 56012)
2024-10-04 11:37:46 - Server listening on ('0.0.0.0', 31026)
2024-10-04 11:37:46 - Main thread: before accepting ...
2024-10-04 11:37:49 - New Client number 1 from ('127.0.0.1', 58661)
2024-10-04 11:38:50 - Client 1 Exit
2024-10-04 11:38:51 - New Client number 2 from ('127.0.0.1', 58704)
2024-10-04 11:38:55 - Client 2 Exit
2024-10-04 11:53:12 - Server listening on ('0.0.0.0', 31026)
2024-10-04 11:53:13 - Main thread: before accepting ...
2024-10-04 11:53:18 - New Client number 1 from ('127.0.0.1', 64979)
2024-10-04 11:56:03 - Client 1 Exit
2024-10-04 11:56:03 - New Client number 2 from ('127.0.0.1', 65041)
2024-10-04 11:59:23 - Client 2 Exit
2024-10-04 11:59:23 - New Client number 3 from ('127.0.0.1', 65073)
2024-10-04 12:01:28 - Client 3 Exit
2024-10-04 12:01:29 - New Client number 4 from ('127.0.0.1', 65098)
2024-10-04 12:01:51 - Traceback (most recent call last):
  File "c:\Users\idanh\desktop\Cyber\My Projects\Final Project\Main\server\server.py", line 465, in protocol_build_reply
    save_file(cloud_path + "\\" + name, sock, tid)
  File "c:\Users\idanh\desktop\Cyber\My Projects\Final Project\Main\server\server.py", line 63, in save_file
    raise Exception
Exception
2024-10-04 12:01:51 - Traceback (most recent call last):
  File "c:\Users\idanh\desktop\Cyber\My Projects\Final Project\Main\server\server.py", line 465, in protocol_build_reply
    save_file(cloud_path + "\\" + name, sock, tid)
  File "c:\Users\idanh\desktop\Cyber\My Projects\Final Project\Main\server\server.py", line 63, in save_file
    raise Exception
Exception

During handling of the above exception, another exception occurred:

Traceback (most recent call last):
  File "c:\Users\idanh\desktop\Cyber\My Projects\Final Project\Main\server\server.py", line 756, in handle_request
    to_send = protocol_build_reply(request, tid, sock)
              ^^^^^^^^^^^^^^^^^^^^^^^^^^^^^^^^^^^^^^^^
  File "c:\Users\idanh\desktop\Cyber\My Projects\Final Project\Main\server\server.py", line 474, in protocol_build_reply
    throw_file(sock, tid)
  File "c:\Users\idanh\desktop\Cyber\My Projects\Final Project\Main\server\server.py", line 112, in throw_file
    raise Exception
Exception
2024-10-04 12:01:52 - Client 4 Exit
2024-10-04 12:01:53 - New Client number 5 from ('127.0.0.1', 65112)
2024-10-04 12:02:11 - Traceback (most recent call last):
  File "c:\Users\idanh\desktop\Cyber\My Projects\Final Project\Main\server\server.py", line 465, in protocol_build_reply
    save_file(cloud_path + "\\" + name, sock, tid)
  File "c:\Users\idanh\desktop\Cyber\My Projects\Final Project\Main\server\server.py", line 63, in save_file
    raise Exception
Exception
2024-10-04 12:02:11 - Traceback (most recent call last):
  File "c:\Users\idanh\desktop\Cyber\My Projects\Final Project\Main\server\server.py", line 465, in protocol_build_reply
    save_file(cloud_path + "\\" + name, sock, tid)
  File "c:\Users\idanh\desktop\Cyber\My Projects\Final Project\Main\server\server.py", line 63, in save_file
    raise Exception
Exception

During handling of the above exception, another exception occurred:

Traceback (most recent call last):
  File "c:\Users\idanh\desktop\Cyber\My Projects\Final Project\Main\server\server.py", line 756, in handle_request
    to_send = protocol_build_reply(request, tid, sock)
              ^^^^^^^^^^^^^^^^^^^^^^^^^^^^^^^^^^^^^^^^
  File "c:\Users\idanh\desktop\Cyber\My Projects\Final Project\Main\server\server.py", line 474, in protocol_build_reply
    throw_file(sock, tid)
  File "c:\Users\idanh\desktop\Cyber\My Projects\Final Project\Main\server\server.py", line 112, in throw_file
    raise Exception
Exception
2024-10-04 12:02:12 - Client 5 Exit
2024-10-04 12:02:12 - New Client number 6 from ('127.0.0.1', 65127)
2024-10-04 12:03:04 - Traceback (most recent call last):
  File "c:\Users\idanh\desktop\Cyber\My Projects\Final Project\Main\server\server.py", line 465, in protocol_build_reply
    save_file(cloud_path + "\\" + name, sock, tid)
  File "c:\Users\idanh\desktop\Cyber\My Projects\Final Project\Main\server\server.py", line 63, in save_file
    raise Exception
Exception
2024-10-04 12:03:04 - Traceback (most recent call last):
  File "c:\Users\idanh\desktop\Cyber\My Projects\Final Project\Main\server\server.py", line 465, in protocol_build_reply
    save_file(cloud_path + "\\" + name, sock, tid)
  File "c:\Users\idanh\desktop\Cyber\My Projects\Final Project\Main\server\server.py", line 63, in save_file
    raise Exception
Exception

During handling of the above exception, another exception occurred:

Traceback (most recent call last):
  File "c:\Users\idanh\desktop\Cyber\My Projects\Final Project\Main\server\server.py", line 756, in handle_request
    to_send = protocol_build_reply(request, tid, sock)
              ^^^^^^^^^^^^^^^^^^^^^^^^^^^^^^^^^^^^^^^^
  File "c:\Users\idanh\desktop\Cyber\My Projects\Final Project\Main\server\server.py", line 474, in protocol_build_reply
    throw_file(sock, tid)
  File "c:\Users\idanh\desktop\Cyber\My Projects\Final Project\Main\server\server.py", line 112, in throw_file
    raise Exception
Exception
2024-10-04 12:03:05 - Client 6 Exit
2024-10-04 12:03:05 - New Client number 7 from ('127.0.0.1', 65141)
2024-10-04 12:03:11 - Traceback (most recent call last):
  File "c:\Users\idanh\desktop\Cyber\My Projects\Final Project\Main\server\server.py", line 465, in protocol_build_reply
    save_file(cloud_path + "\\" + name, sock, tid)
  File "c:\Users\idanh\desktop\Cyber\My Projects\Final Project\Main\server\server.py", line 63, in save_file
    raise Exception
Exception
2024-10-04 12:03:11 - Traceback (most recent call last):
  File "c:\Users\idanh\desktop\Cyber\My Projects\Final Project\Main\server\server.py", line 465, in protocol_build_reply
    save_file(cloud_path + "\\" + name, sock, tid)
  File "c:\Users\idanh\desktop\Cyber\My Projects\Final Project\Main\server\server.py", line 63, in save_file
    raise Exception
Exception

During handling of the above exception, another exception occurred:

Traceback (most recent call last):
  File "c:\Users\idanh\desktop\Cyber\My Projects\Final Project\Main\server\server.py", line 756, in handle_request
    to_send = protocol_build_reply(request, tid, sock)
              ^^^^^^^^^^^^^^^^^^^^^^^^^^^^^^^^^^^^^^^^
  File "c:\Users\idanh\desktop\Cyber\My Projects\Final Project\Main\server\server.py", line 474, in protocol_build_reply
    throw_file(sock, tid)
  File "c:\Users\idanh\desktop\Cyber\My Projects\Final Project\Main\server\server.py", line 112, in throw_file
    raise Exception
Exception
2024-10-04 12:03:12 - Client 7 Exit
2024-10-04 12:04:21 - New Client number 8 from ('127.0.0.1', 65158)
2024-10-04 12:05:40 - Server listening on ('0.0.0.0', 31026)
2024-10-04 12:05:40 - Main thread: before accepting ...
2024-10-04 12:05:40 - New Client number 1 from ('127.0.0.1', 65190)
2024-10-04 12:20:17 - Client 1 Exit
2024-10-04 12:20:18 - New Client number 2 from ('127.0.0.1', 65298)
2024-10-04 12:21:02 - Client 2 Exit
2024-10-04 12:21:03 - New Client number 3 from ('127.0.0.1', 65312)
2024-10-04 12:24:12 - Client 3 Exit
2024-10-04 12:24:12 - New Client number 4 from ('127.0.0.1', 65336)
2024-10-04 12:25:45 - Traceback (most recent call last):
  File "c:\Users\idanh\desktop\Cyber\My Projects\Final Project\Main\server\server.py", line 465, in protocol_build_reply
    save_file(cloud_path + "\\" + name, sock, tid)
  File "c:\Users\idanh\desktop\Cyber\My Projects\Final Project\Main\server\server.py", line 63, in save_file
    raise Exception
Exception
2024-10-04 12:25:45 - Traceback (most recent call last):
  File "c:\Users\idanh\desktop\Cyber\My Projects\Final Project\Main\server\server.py", line 465, in protocol_build_reply
    save_file(cloud_path + "\\" + name, sock, tid)
  File "c:\Users\idanh\desktop\Cyber\My Projects\Final Project\Main\server\server.py", line 63, in save_file
    raise Exception
Exception

During handling of the above exception, another exception occurred:

Traceback (most recent call last):
  File "c:\Users\idanh\desktop\Cyber\My Projects\Final Project\Main\server\server.py", line 756, in handle_request
    to_send = protocol_build_reply(request, tid, sock)
              ^^^^^^^^^^^^^^^^^^^^^^^^^^^^^^^^^^^^^^^^
  File "c:\Users\idanh\desktop\Cyber\My Projects\Final Project\Main\server\server.py", line 474, in protocol_build_reply
    throw_file(sock, tid)
  File "c:\Users\idanh\desktop\Cyber\My Projects\Final Project\Main\server\server.py", line 112, in throw_file
    raise Exception
Exception
2024-10-04 12:25:46 - Client 4 Exit
2024-10-04 12:25:47 - New Client number 5 from ('127.0.0.1', 65359)
2024-10-04 12:26:34 - Traceback (most recent call last):
  File "c:\Users\idanh\desktop\Cyber\My Projects\Final Project\Main\server\server.py", line 465, in protocol_build_reply
    save_file(cloud_path + "\\" + name, sock, tid)
  File "c:\Users\idanh\desktop\Cyber\My Projects\Final Project\Main\server\server.py", line 63, in save_file
    raise Exception
Exception
2024-10-04 12:26:34 - Traceback (most recent call last):
  File "c:\Users\idanh\desktop\Cyber\My Projects\Final Project\Main\server\server.py", line 465, in protocol_build_reply
    save_file(cloud_path + "\\" + name, sock, tid)
  File "c:\Users\idanh\desktop\Cyber\My Projects\Final Project\Main\server\server.py", line 63, in save_file
    raise Exception
Exception

During handling of the above exception, another exception occurred:

Traceback (most recent call last):
  File "c:\Users\idanh\desktop\Cyber\My Projects\Final Project\Main\server\server.py", line 756, in handle_request
    to_send = protocol_build_reply(request, tid, sock)
              ^^^^^^^^^^^^^^^^^^^^^^^^^^^^^^^^^^^^^^^^
  File "c:\Users\idanh\desktop\Cyber\My Projects\Final Project\Main\server\server.py", line 474, in protocol_build_reply
    throw_file(sock, tid)
  File "c:\Users\idanh\desktop\Cyber\My Projects\Final Project\Main\server\server.py", line 112, in throw_file
    raise Exception
Exception
2024-10-04 12:26:35 - Client 5 Exit
2024-10-04 12:26:36 - New Client number 6 from ('127.0.0.1', 65383)
2024-10-04 12:28:17 - Client 6 Exit
2024-10-04 12:28:17 - New Client number 7 from ('127.0.0.1', 65401)
2024-10-04 12:28:25 - Traceback (most recent call last):
  File "c:\Users\idanh\desktop\Cyber\My Projects\Final Project\Main\server\server.py", line 465, in protocol_build_reply
    save_file(cloud_path + "\\" + name, sock, tid)
  File "c:\Users\idanh\desktop\Cyber\My Projects\Final Project\Main\server\server.py", line 63, in save_file
    raise Exception
Exception
2024-10-04 12:28:25 - Traceback (most recent call last):
  File "c:\Users\idanh\desktop\Cyber\My Projects\Final Project\Main\server\server.py", line 465, in protocol_build_reply
    save_file(cloud_path + "\\" + name, sock, tid)
  File "c:\Users\idanh\desktop\Cyber\My Projects\Final Project\Main\server\server.py", line 63, in save_file
    raise Exception
Exception

During handling of the above exception, another exception occurred:

Traceback (most recent call last):
  File "c:\Users\idanh\desktop\Cyber\My Projects\Final Project\Main\server\server.py", line 756, in handle_request
    to_send = protocol_build_reply(request, tid, sock)
              ^^^^^^^^^^^^^^^^^^^^^^^^^^^^^^^^^^^^^^^^
  File "c:\Users\idanh\desktop\Cyber\My Projects\Final Project\Main\server\server.py", line 474, in protocol_build_reply
    throw_file(sock, tid)
  File "c:\Users\idanh\desktop\Cyber\My Projects\Final Project\Main\server\server.py", line 112, in throw_file
    raise Exception
Exception
2024-10-04 12:28:26 - Client 7 Exit
2024-10-04 12:28:47 - New Client number 8 from ('127.0.0.1', 65419)
2024-10-04 12:28:55 - Traceback (most recent call last):
  File "c:\Users\idanh\desktop\Cyber\My Projects\Final Project\Main\server\server.py", line 465, in protocol_build_reply
    save_file(cloud_path + "\\" + name, sock, tid)
  File "c:\Users\idanh\desktop\Cyber\My Projects\Final Project\Main\server\server.py", line 63, in save_file
    raise Exception
Exception
2024-10-04 12:28:55 - Traceback (most recent call last):
  File "c:\Users\idanh\desktop\Cyber\My Projects\Final Project\Main\server\server.py", line 465, in protocol_build_reply
    save_file(cloud_path + "\\" + name, sock, tid)
  File "c:\Users\idanh\desktop\Cyber\My Projects\Final Project\Main\server\server.py", line 63, in save_file
    raise Exception
Exception

During handling of the above exception, another exception occurred:

Traceback (most recent call last):
  File "c:\Users\idanh\desktop\Cyber\My Projects\Final Project\Main\server\server.py", line 756, in handle_request
    to_send = protocol_build_reply(request, tid, sock)
              ^^^^^^^^^^^^^^^^^^^^^^^^^^^^^^^^^^^^^^^^
  File "c:\Users\idanh\desktop\Cyber\My Projects\Final Project\Main\server\server.py", line 474, in protocol_build_reply
    throw_file(sock, tid)
  File "c:\Users\idanh\desktop\Cyber\My Projects\Final Project\Main\server\server.py", line 112, in throw_file
    raise Exception
Exception
2024-10-04 12:28:56 - Client 8 Exit
2024-10-04 12:29:10 - New Client number 9 from ('127.0.0.1', 65435)
2024-10-04 12:29:27 - Client 9 Exit
2024-10-04 12:29:27 - New Client number 10 from ('127.0.0.1', 65448)
2024-10-04 12:29:35 - Traceback (most recent call last):
  File "c:\Users\idanh\desktop\Cyber\My Projects\Final Project\Main\server\server.py", line 465, in protocol_build_reply
    save_file(cloud_path + "\\" + name, sock, tid)
  File "c:\Users\idanh\desktop\Cyber\My Projects\Final Project\Main\server\server.py", line 63, in save_file
    raise Exception
Exception
2024-10-04 12:29:35 - Traceback (most recent call last):
  File "c:\Users\idanh\desktop\Cyber\My Projects\Final Project\Main\server\server.py", line 465, in protocol_build_reply
    save_file(cloud_path + "\\" + name, sock, tid)
  File "c:\Users\idanh\desktop\Cyber\My Projects\Final Project\Main\server\server.py", line 63, in save_file
    raise Exception
Exception

During handling of the above exception, another exception occurred:

Traceback (most recent call last):
  File "c:\Users\idanh\desktop\Cyber\My Projects\Final Project\Main\server\server.py", line 756, in handle_request
    to_send = protocol_build_reply(request, tid, sock)
              ^^^^^^^^^^^^^^^^^^^^^^^^^^^^^^^^^^^^^^^^
  File "c:\Users\idanh\desktop\Cyber\My Projects\Final Project\Main\server\server.py", line 474, in protocol_build_reply
    throw_file(sock, tid)
  File "c:\Users\idanh\desktop\Cyber\My Projects\Final Project\Main\server\server.py", line 112, in throw_file
    raise Exception
Exception
2024-10-04 12:29:36 - Client 10 Exit
2024-10-04 12:29:39 - New Client number 11 from ('127.0.0.1', 65463)
2024-10-04 12:31:05 - Client 11 Exit
2024-10-04 12:31:05 - New Client number 12 from ('127.0.0.1', 65489)
2024-10-04 12:31:44 - Client 12 Exit
2024-10-04 12:31:44 - New Client number 13 from ('127.0.0.1', 65501)
2024-10-04 12:33:26 - Traceback (most recent call last):
  File "c:\Users\idanh\desktop\Cyber\My Projects\Final Project\Main\server\server.py", line 465, in protocol_build_reply
    save_file(cloud_path + "\\" + name, sock, tid)
  File "c:\Users\idanh\desktop\Cyber\My Projects\Final Project\Main\server\server.py", line 66, in save_file
    raise LimitExceeded("File exceeded size limit")
modules.limits.LimitExceeded: File exceeded size limit

During handling of the above exception, another exception occurred:

Traceback (most recent call last):
  File "c:\Users\idanh\desktop\Cyber\My Projects\Final Project\Main\server\server.py", line 470, in protocol_build_reply
    throw_file(sock, tid)
  File "c:\Users\idanh\desktop\Cyber\My Projects\Final Project\Main\server\server.py", line 118, in throw_file
    raise Exception
Exception
2024-10-04 12:33:38 - Client 13 Exit
2024-10-04 12:33:38 - New Client number 14 from ('127.0.0.1', 65515)
2024-10-04 12:33:53 - Client 14 Exit
2024-10-04 12:33:53 - New Client number 15 from ('127.0.0.1', 65531)
2024-10-04 12:35:28 - Client 15 Exit
2024-10-04 12:35:28 - New Client number 16 from ('127.0.0.1', 49174)
2024-10-04 12:40:29 - Client 16 Exit
2024-10-04 12:40:29 - New Client number 17 from ('127.0.0.1', 49218)
2024-10-04 12:40:58 - Client 17 Exit
2024-10-04 12:40:58 - New Client number 18 from ('127.0.0.1', 49235)
2024-10-04 12:41:45 - Client 18 Exit
2024-10-04 12:41:45 - New Client number 19 from ('127.0.0.1', 49253)
2024-10-04 12:42:23 - Client 19 Exit
2024-10-04 12:42:23 - New Client number 20 from ('127.0.0.1', 49265)
2024-10-04 12:44:56 - Traceback (most recent call last):
  File "c:\Users\idanh\desktop\Cyber\My Projects\Final Project\Main\server\server.py", line 595, in protocol_build_reply
    save_file(save_path, sock, tid)
  File "c:\Users\idanh\desktop\Cyber\My Projects\Final Project\Main\server\server.py", line 63, in save_file
    raise Exception
Exception
2024-10-04 12:44:56 - Traceback (most recent call last):
  File "c:\Users\idanh\desktop\Cyber\My Projects\Final Project\Main\server\server.py", line 595, in protocol_build_reply
    save_file(save_path, sock, tid)
  File "c:\Users\idanh\desktop\Cyber\My Projects\Final Project\Main\server\server.py", line 63, in save_file
    raise Exception
Exception

During handling of the above exception, another exception occurred:

Traceback (most recent call last):
  File "c:\Users\idanh\desktop\Cyber\My Projects\Final Project\Main\server\server.py", line 756, in handle_request
    to_send = protocol_build_reply(request, tid, sock)
              ^^^^^^^^^^^^^^^^^^^^^^^^^^^^^^^^^^^^^^^^
  File "c:\Users\idanh\desktop\Cyber\My Projects\Final Project\Main\server\server.py", line 603, in protocol_build_reply
    throw_file(sock, tid)
  File "c:\Users\idanh\desktop\Cyber\My Projects\Final Project\Main\server\server.py", line 112, in throw_file
    raise Exception
Exception
2024-10-04 12:44:57 - Client 20 Exit
2024-10-04 12:44:58 - New Client number 21 from ('127.0.0.1', 49293)
2024-10-04 12:45:07 - Client 21 Exit
2024-10-04 12:45:07 - New Client number 22 from ('127.0.0.1', 49312)
2024-10-04 12:45:20 - Client 22 Exit
2024-10-04 12:45:20 - New Client number 23 from ('127.0.0.1', 49323)
2024-10-04 12:45:29 - Client 23 Exit
2024-10-04 12:45:30 - New Client number 24 from ('127.0.0.1', 49335)
2024-10-04 12:46:02 - Server listening on ('0.0.0.0', 31026)
2024-10-04 12:46:02 - Main thread: before accepting ...
2024-10-04 12:46:02 - New Client number 1 from ('127.0.0.1', 49352)
2024-10-04 12:46:33 - Client 1 Exit
2024-10-04 12:46:34 - New Client number 2 from ('127.0.0.1', 49369)
2024-10-04 12:47:54 - Client 2 Exit
2024-10-04 12:47:55 - New Client number 3 from ('127.0.0.1', 49395)
2024-10-04 12:48:11 - Traceback (most recent call last):
  File "c:\Users\idanh\desktop\Cyber\My Projects\Final Project\Main\server\server.py", line 595, in protocol_build_reply
    save_file(save_path, sock, tid)
  File "c:\Users\idanh\desktop\Cyber\My Projects\Final Project\Main\server\server.py", line 63, in save_file
    raise Exception
Exception
2024-10-04 12:48:11 - Traceback (most recent call last):
  File "c:\Users\idanh\desktop\Cyber\My Projects\Final Project\Main\server\server.py", line 595, in protocol_build_reply
    save_file(save_path, sock, tid)
  File "c:\Users\idanh\desktop\Cyber\My Projects\Final Project\Main\server\server.py", line 63, in save_file
    raise Exception
Exception

During handling of the above exception, another exception occurred:

Traceback (most recent call last):
  File "c:\Users\idanh\desktop\Cyber\My Projects\Final Project\Main\server\server.py", line 756, in handle_request
    to_send = protocol_build_reply(request, tid, sock)
              ^^^^^^^^^^^^^^^^^^^^^^^^^^^^^^^^^^^^^^^^
  File "c:\Users\idanh\desktop\Cyber\My Projects\Final Project\Main\server\server.py", line 603, in protocol_build_reply
    throw_file(sock, tid)
  File "c:\Users\idanh\desktop\Cyber\My Projects\Final Project\Main\server\server.py", line 112, in throw_file
    raise Exception
Exception
2024-10-04 12:48:12 - Client 3 Exit
2024-10-04 12:48:52 - New Client number 4 from ('127.0.0.1', 49412)
2024-10-04 12:50:13 - Client 4 Exit
2024-10-04 12:50:14 - New Client number 5 from ('127.0.0.1', 49429)
2024-10-04 12:51:15 - Client 5 Exit
2024-10-04 12:51:15 - New Client number 6 from ('127.0.0.1', 49452)
2024-10-04 12:52:41 - Server listening on ('0.0.0.0', 31026)
2024-10-04 12:52:42 - Main thread: before accepting ...
2024-10-04 12:52:44 - New Client number 1 from ('127.0.0.1', 49501)
2024-10-04 12:53:12 - Server listening on ('0.0.0.0', 31026)
2024-10-04 12:53:12 - Main thread: before accepting ...
2024-10-04 12:53:12 - New Client number 1 from ('127.0.0.1', 49521)
2024-10-04 12:53:41 - Client 1 Exit
2024-10-04 12:53:42 - New Client number 2 from ('127.0.0.1', 49537)
2024-10-04 12:53:47 - Client 2 Exit
2024-10-04 12:53:47 - New Client number 3 from ('127.0.0.1', 49548)
2024-10-04 12:55:10 - Client 3 Exit
2024-10-04 12:55:11 - New Client number 4 from ('127.0.0.1', 49596)
2024-10-04 14:22:12 - Server listening on ('0.0.0.0', 31026)
2024-10-04 14:22:13 - Main thread: before accepting ...
2024-10-04 14:22:16 - New Client number 1 from ('127.0.0.1', 53881)
2024-10-04 14:24:43 - Client 1 Exit
2024-10-04 14:24:44 - New Client number 2 from ('127.0.0.1', 53904)
2024-10-04 14:25:08 - Traceback (most recent call last):
  File "c:\Users\idanh\Desktop\Cyber\My Projects\Final Project\Main\server\server.py", line 837, in recv_data
    msg = encrypting.decrypt(msg, clients[tid].shared_secret)
          ^^^^^^^^^^^^^^^^^^^^^^^^^^^^^^^^^^^^^^^^^^^^^^^^^^^
  File "c:\Users\idanh\Desktop\Cyber\My Projects\Final Project\Main\server\modules\encrypting.py", line 35, in decrypt
    plain_text = cipher.decrypt(encrypted_text[block_size:])
                 ^^^^^^^^^^^^^^^^^^^^^^^^^^^^^^^^^^^^^^^^^^^
  File "c:\Users\idanh\AppData\Local\Programs\Python\Python312\Lib\site-packages\Crypto\Cipher\_mode_cbc.py", line 246, in decrypt
    raise ValueError("Data must be padded to %d byte boundary in CBC mode" % self.block_size)
ValueError: Data must be padded to 16 byte boundary in CBC mode
2024-10-04 14:25:08 - Traceback (most recent call last):
  File "c:\Users\idanh\Desktop\Cyber\My Projects\Final Project\Main\server\server.py", line 465, in protocol_build_reply
    save_file(cloud_path + "\\" + name, sock, tid)
  File "c:\Users\idanh\Desktop\Cyber\My Projects\Final Project\Main\server\server.py", line 63, in save_file
    raise Exception
Exception
2024-10-04 14:25:16 - Traceback (most recent call last):
  File "c:\Users\idanh\Desktop\Cyber\My Projects\Final Project\Main\server\server.py", line 465, in protocol_build_reply
    save_file(cloud_path + "\\" + name, sock, tid)
  File "c:\Users\idanh\Desktop\Cyber\My Projects\Final Project\Main\server\server.py", line 63, in save_file
    raise Exception
Exception
2024-10-04 14:25:16 - Traceback (most recent call last):
  File "c:\Users\idanh\Desktop\Cyber\My Projects\Final Project\Main\server\server.py", line 465, in protocol_build_reply
    save_file(cloud_path + "\\" + name, sock, tid)
  File "c:\Users\idanh\Desktop\Cyber\My Projects\Final Project\Main\server\server.py", line 63, in save_file
    raise Exception
Exception
2024-10-04 14:25:16 - Traceback (most recent call last):
  File "c:\Users\idanh\Desktop\Cyber\My Projects\Final Project\Main\server\server.py", line 465, in protocol_build_reply
    save_file(cloud_path + "\\" + name, sock, tid)
  File "c:\Users\idanh\Desktop\Cyber\My Projects\Final Project\Main\server\server.py", line 63, in save_file
    raise Exception
Exception
2024-10-04 14:25:16 - Traceback (most recent call last):
  File "c:\Users\idanh\Desktop\Cyber\My Projects\Final Project\Main\server\server.py", line 465, in protocol_build_reply
    save_file(cloud_path + "\\" + name, sock, tid)
  File "c:\Users\idanh\Desktop\Cyber\My Projects\Final Project\Main\server\server.py", line 63, in save_file
    raise Exception
Exception

During handling of the above exception, another exception occurred:

Traceback (most recent call last):
  File "c:\Users\idanh\Desktop\Cyber\My Projects\Final Project\Main\server\server.py", line 756, in handle_request
    to_send = protocol_build_reply(request, tid, sock)
              ^^^^^^^^^^^^^^^^^^^^^^^^^^^^^^^^^^^^^^^^
  File "c:\Users\idanh\Desktop\Cyber\My Projects\Final Project\Main\server\server.py", line 474, in protocol_build_reply
    throw_file(sock, tid)
  File "c:\Users\idanh\Desktop\Cyber\My Projects\Final Project\Main\server\server.py", line 112, in throw_file
    raise Exception
Exception
2024-10-04 14:25:16 - Traceback (most recent call last):
  File "c:\Users\idanh\Desktop\Cyber\My Projects\Final Project\Main\server\server.py", line 465, in protocol_build_reply
    save_file(cloud_path + "\\" + name, sock, tid)
  File "c:\Users\idanh\Desktop\Cyber\My Projects\Final Project\Main\server\server.py", line 63, in save_file
    raise Exception
Exception
2024-10-04 14:25:16 - Traceback (most recent call last):
  File "c:\Users\idanh\Desktop\Cyber\My Projects\Final Project\Main\server\server.py", line 465, in protocol_build_reply
    save_file(cloud_path + "\\" + name, sock, tid)
  File "c:\Users\idanh\Desktop\Cyber\My Projects\Final Project\Main\server\server.py", line 63, in save_file
    raise Exception
Exception
2024-10-04 14:25:16 - Traceback (most recent call last):
  File "c:\Users\idanh\Desktop\Cyber\My Projects\Final Project\Main\server\server.py", line 465, in protocol_build_reply
    save_file(cloud_path + "\\" + name, sock, tid)
  File "c:\Users\idanh\Desktop\Cyber\My Projects\Final Project\Main\server\server.py", line 63, in save_file
    raise Exception
Exception

During handling of the above exception, another exception occurred:

Traceback (most recent call last):
  File "c:\Users\idanh\Desktop\Cyber\My Projects\Final Project\Main\server\server.py", line 756, in handle_request
    to_send = protocol_build_reply(request, tid, sock)
              ^^^^^^^^^^^^^^^^^^^^^^^^^^^^^^^^^^^^^^^^
  File "c:\Users\idanh\Desktop\Cyber\My Projects\Final Project\Main\server\server.py", line 474, in protocol_build_reply
    throw_file(sock, tid)
  File "c:\Users\idanh\Desktop\Cyber\My Projects\Final Project\Main\server\server.py", line 112, in throw_file
    raise Exception
Exception
2024-10-04 14:25:16 - Traceback (most recent call last):
  File "c:\Users\idanh\Desktop\Cyber\My Projects\Final Project\Main\server\server.py", line 465, in protocol_build_reply
    save_file(cloud_path + "\\" + name, sock, tid)
  File "c:\Users\idanh\Desktop\Cyber\My Projects\Final Project\Main\server\server.py", line 63, in save_file
    raise Exception
Exception

During handling of the above exception, another exception occurred:

Traceback (most recent call last):
  File "c:\Users\idanh\Desktop\Cyber\My Projects\Final Project\Main\server\server.py", line 756, in handle_request
    to_send = protocol_build_reply(request, tid, sock)
              ^^^^^^^^^^^^^^^^^^^^^^^^^^^^^^^^^^^^^^^^
  File "c:\Users\idanh\Desktop\Cyber\My Projects\Final Project\Main\server\server.py", line 474, in protocol_build_reply
    throw_file(sock, tid)
  File "c:\Users\idanh\Desktop\Cyber\My Projects\Final Project\Main\server\server.py", line 112, in throw_file
    raise Exception
Exception
2024-10-04 14:25:16 - Traceback (most recent call last):
  File "c:\Users\idanh\Desktop\Cyber\My Projects\Final Project\Main\server\server.py", line 465, in protocol_build_reply
    save_file(cloud_path + "\\" + name, sock, tid)
  File "c:\Users\idanh\Desktop\Cyber\My Projects\Final Project\Main\server\server.py", line 63, in save_file
    raise Exception
Exception

During handling of the above exception, another exception occurred:

Traceback (most recent call last):
  File "c:\Users\idanh\Desktop\Cyber\My Projects\Final Project\Main\server\server.py", line 756, in handle_request
    to_send = protocol_build_reply(request, tid, sock)
              ^^^^^^^^^^^^^^^^^^^^^^^^^^^^^^^^^^^^^^^^
  File "c:\Users\idanh\Desktop\Cyber\My Projects\Final Project\Main\server\server.py", line 474, in protocol_build_reply
    throw_file(sock, tid)
  File "c:\Users\idanh\Desktop\Cyber\My Projects\Final Project\Main\server\server.py", line 112, in throw_file
    raise Exception
Exception
2024-10-04 14:25:16 - Traceback (most recent call last):
  File "c:\Users\idanh\Desktop\Cyber\My Projects\Final Project\Main\server\server.py", line 465, in protocol_build_reply
    save_file(cloud_path + "\\" + name, sock, tid)
  File "c:\Users\idanh\Desktop\Cyber\My Projects\Final Project\Main\server\server.py", line 63, in save_file
    raise Exception
Exception

During handling of the above exception, another exception occurred:

Traceback (most recent call last):
  File "c:\Users\idanh\Desktop\Cyber\My Projects\Final Project\Main\server\server.py", line 756, in handle_request
    to_send = protocol_build_reply(request, tid, sock)
              ^^^^^^^^^^^^^^^^^^^^^^^^^^^^^^^^^^^^^^^^
  File "c:\Users\idanh\Desktop\Cyber\My Projects\Final Project\Main\server\server.py", line 474, in protocol_build_reply
    throw_file(sock, tid)
  File "c:\Users\idanh\Desktop\Cyber\My Projects\Final Project\Main\server\server.py", line 112, in throw_file
    raise Exception
Exception
2024-10-04 14:25:16 - Traceback (most recent call last):
  File "c:\Users\idanh\Desktop\Cyber\My Projects\Final Project\Main\server\server.py", line 465, in protocol_build_reply
    save_file(cloud_path + "\\" + name, sock, tid)
  File "c:\Users\idanh\Desktop\Cyber\My Projects\Final Project\Main\server\server.py", line 63, in save_file
    raise Exception
Exception

During handling of the above exception, another exception occurred:

Traceback (most recent call last):
  File "c:\Users\idanh\Desktop\Cyber\My Projects\Final Project\Main\server\server.py", line 756, in handle_request
    to_send = protocol_build_reply(request, tid, sock)
              ^^^^^^^^^^^^^^^^^^^^^^^^^^^^^^^^^^^^^^^^
  File "c:\Users\idanh\Desktop\Cyber\My Projects\Final Project\Main\server\server.py", line 474, in protocol_build_reply
    throw_file(sock, tid)
  File "c:\Users\idanh\Desktop\Cyber\My Projects\Final Project\Main\server\server.py", line 112, in throw_file
    raise Exception
Exception
2024-10-04 14:25:17 - Client 2 Exit
2024-10-04 14:25:17 - New Client number 3 from ('127.0.0.1', 53921)
2024-10-04 14:27:31 - Client 3 Exit
2024-10-04 14:27:32 - New Client number 4 from ('127.0.0.1', 53990)
2024-10-04 14:33:45 - Client 4 Exit
2024-10-04 14:33:45 - New Client number 5 from ('127.0.0.1', 54076)
2024-10-04 14:34:38 - Client 5 Exit
2024-10-04 14:34:38 - New Client number 6 from ('127.0.0.1', 54088)
2024-10-04 14:36:00 - Client 6 Exit
2024-10-04 14:36:01 - New Client number 7 from ('127.0.0.1', 54115)
2024-10-04 14:36:41 - Client 7 Exit
2024-10-04 14:36:42 - New Client number 8 from ('127.0.0.1', 54129)
2024-10-04 14:36:53 - Client 8 Exit
2024-10-04 14:36:54 - New Client number 9 from ('127.0.0.1', 54142)
2024-10-04 14:37:25 - Client 9 Exit
2024-10-04 14:37:25 - New Client number 10 from ('127.0.0.1', 54156)
2024-10-04 14:38:31 - Client 10 Exit
2024-10-04 14:38:31 - New Client number 11 from ('127.0.0.1', 54181)
2024-10-04 14:39:45 - Client 11 Exit
2024-10-04 14:39:46 - New Client number 12 from ('127.0.0.1', 54202)
2024-10-04 14:43:14 - Client 12 Exit
2024-10-04 14:48:40 - Server listening on ('0.0.0.0', 31026)
2024-10-04 14:48:40 - Main thread: before accepting ...
2024-10-04 14:48:42 - New Client number 1 from ('127.0.0.1', 54276)
2024-10-04 14:49:15 - Client 1 Exit
2024-10-04 14:49:15 - New Client number 2 from ('127.0.0.1', 54295)
2024-10-04 14:49:29 - Client 2 Exit
2024-10-04 14:49:30 - New Client number 3 from ('127.0.0.1', 54308)
2024-10-04 14:49:54 - Client 3 Exit
2024-10-04 14:49:55 - New Client number 4 from ('127.0.0.1', 54321)
2024-10-04 14:50:15 - Client 4 Exit
2024-10-04 14:51:03 - New Client number 5 from ('127.0.0.1', 54346)
2024-10-04 14:51:12 - Client 5 Exit
2024-10-04 14:51:42 - New Client number 6 from ('127.0.0.1', 54367)
2024-10-04 14:51:51 - Client 6 Exit
2024-10-04 14:53:28 - New Client number 7 from ('127.0.0.1', 54394)
2024-10-04 14:53:50 - Traceback (most recent call last):
  File "c:\Users\idanh\Desktop\Cyber\My Projects\Final Project\Main\server\server.py", line 465, in protocol_build_reply
    save_file(cloud_path + "\\" + name, sock, tid)
  File "c:\Users\idanh\Desktop\Cyber\My Projects\Final Project\Main\server\server.py", line 63, in save_file
    raise Exception
Exception
2024-10-04 14:53:50 - Traceback (most recent call last):
  File "c:\Users\idanh\Desktop\Cyber\My Projects\Final Project\Main\server\server.py", line 465, in protocol_build_reply
    save_file(cloud_path + "\\" + name, sock, tid)
  File "c:\Users\idanh\Desktop\Cyber\My Projects\Final Project\Main\server\server.py", line 63, in save_file
    raise Exception
Exception

During handling of the above exception, another exception occurred:

Traceback (most recent call last):
  File "c:\Users\idanh\Desktop\Cyber\My Projects\Final Project\Main\server\server.py", line 756, in handle_request
    to_send = protocol_build_reply(request, tid, sock)
              ^^^^^^^^^^^^^^^^^^^^^^^^^^^^^^^^^^^^^^^^
  File "c:\Users\idanh\Desktop\Cyber\My Projects\Final Project\Main\server\server.py", line 474, in protocol_build_reply
    throw_file(sock, tid)
  File "c:\Users\idanh\Desktop\Cyber\My Projects\Final Project\Main\server\server.py", line 112, in throw_file
    raise Exception
Exception
2024-10-04 14:53:52 - Client 7 Exit
2024-10-04 14:53:52 - New Client number 8 from ('127.0.0.1', 54406)
2024-10-04 14:54:22 - Client 8 Exit
2024-10-04 14:54:32 - New Client number 9 from ('127.0.0.1', 54422)
2024-10-04 14:55:04 - Client 9 Exit
2024-10-04 14:55:04 - New Client number 10 from ('127.0.0.1', 54438)
2024-10-04 14:55:26 - Client 10 Exit
2024-10-04 14:55:27 - New Client number 11 from ('127.0.0.1', 54451)
2024-10-04 14:55:53 - Client 11 Exit
2024-10-04 14:55:53 - New Client number 12 from ('127.0.0.1', 54463)
2024-10-04 14:56:27 - Client 12 Exit
2024-10-04 14:56:28 - New Client number 13 from ('127.0.0.1', 54476)
2024-10-04 14:57:29 - Client 13 Exit
2024-10-04 14:57:29 - New Client number 14 from ('127.0.0.1', 54492)
2024-10-04 14:58:24 - Traceback (most recent call last):
  File "c:\Users\idanh\Desktop\Cyber\My Projects\Final Project\Main\server\server.py", line 465, in protocol_build_reply
    save_file(cloud_path + "\\" + name, sock, tid)
  File "c:\Users\idanh\Desktop\Cyber\My Projects\Final Project\Main\server\server.py", line 63, in save_file
    raise Exception
Exception
2024-10-04 14:58:24 - Traceback (most recent call last):
  File "c:\Users\idanh\Desktop\Cyber\My Projects\Final Project\Main\server\server.py", line 465, in protocol_build_reply
    save_file(cloud_path + "\\" + name, sock, tid)
  File "c:\Users\idanh\Desktop\Cyber\My Projects\Final Project\Main\server\server.py", line 63, in save_file
    raise Exception
Exception

During handling of the above exception, another exception occurred:

Traceback (most recent call last):
  File "c:\Users\idanh\Desktop\Cyber\My Projects\Final Project\Main\server\server.py", line 756, in handle_request
    to_send = protocol_build_reply(request, tid, sock)
              ^^^^^^^^^^^^^^^^^^^^^^^^^^^^^^^^^^^^^^^^
  File "c:\Users\idanh\Desktop\Cyber\My Projects\Final Project\Main\server\server.py", line 474, in protocol_build_reply
    throw_file(sock, tid)
  File "c:\Users\idanh\Desktop\Cyber\My Projects\Final Project\Main\server\server.py", line 112, in throw_file
    raise Exception
Exception
2024-10-04 14:58:25 - Client 14 Exit
2024-10-04 14:58:32 - New Client number 15 from ('127.0.0.1', 54512)
2024-10-04 14:59:08 - Traceback (most recent call last):
  File "c:\Users\idanh\Desktop\Cyber\My Projects\Final Project\Main\server\server.py", line 465, in protocol_build_reply
    save_file(cloud_path + "\\" + name, sock, tid)
  File "c:\Users\idanh\Desktop\Cyber\My Projects\Final Project\Main\server\server.py", line 63, in save_file
    raise Exception
Exception
2024-10-04 14:59:08 - Traceback (most recent call last):
  File "c:\Users\idanh\Desktop\Cyber\My Projects\Final Project\Main\server\server.py", line 465, in protocol_build_reply
    save_file(cloud_path + "\\" + name, sock, tid)
  File "c:\Users\idanh\Desktop\Cyber\My Projects\Final Project\Main\server\server.py", line 63, in save_file
    raise Exception
Exception

During handling of the above exception, another exception occurred:

Traceback (most recent call last):
  File "c:\Users\idanh\Desktop\Cyber\My Projects\Final Project\Main\server\server.py", line 756, in handle_request
    to_send = protocol_build_reply(request, tid, sock)
              ^^^^^^^^^^^^^^^^^^^^^^^^^^^^^^^^^^^^^^^^
  File "c:\Users\idanh\Desktop\Cyber\My Projects\Final Project\Main\server\server.py", line 474, in protocol_build_reply
    throw_file(sock, tid)
  File "c:\Users\idanh\Desktop\Cyber\My Projects\Final Project\Main\server\server.py", line 112, in throw_file
    raise Exception
Exception
2024-10-04 14:59:09 - Client 15 Exit
2024-10-04 14:59:16 - New Client number 16 from ('127.0.0.1', 54526)
2024-10-04 14:59:31 - Traceback (most recent call last):
  File "c:\Users\idanh\Desktop\Cyber\My Projects\Final Project\Main\server\server.py", line 465, in protocol_build_reply
    save_file(cloud_path + "\\" + name, sock, tid)
  File "c:\Users\idanh\Desktop\Cyber\My Projects\Final Project\Main\server\server.py", line 63, in save_file
    raise Exception
Exception
2024-10-04 14:59:31 - Traceback (most recent call last):
  File "c:\Users\idanh\Desktop\Cyber\My Projects\Final Project\Main\server\server.py", line 465, in protocol_build_reply
    save_file(cloud_path + "\\" + name, sock, tid)
  File "c:\Users\idanh\Desktop\Cyber\My Projects\Final Project\Main\server\server.py", line 63, in save_file
    raise Exception
Exception

During handling of the above exception, another exception occurred:

Traceback (most recent call last):
  File "c:\Users\idanh\Desktop\Cyber\My Projects\Final Project\Main\server\server.py", line 756, in handle_request
    to_send = protocol_build_reply(request, tid, sock)
              ^^^^^^^^^^^^^^^^^^^^^^^^^^^^^^^^^^^^^^^^
  File "c:\Users\idanh\Desktop\Cyber\My Projects\Final Project\Main\server\server.py", line 474, in protocol_build_reply
    throw_file(sock, tid)
  File "c:\Users\idanh\Desktop\Cyber\My Projects\Final Project\Main\server\server.py", line 112, in throw_file
    raise Exception
Exception
2024-10-04 14:59:32 - Client 16 Exit
2024-10-04 15:00:03 - New Client number 17 from ('127.0.0.1', 54541)
2024-10-04 15:01:00 - Client 17 Exit
2024-10-04 15:01:46 - New Client number 18 from ('127.0.0.1', 54571)
2024-10-04 15:02:45 - Client 18 Exit
2024-10-04 15:02:46 - New Client number 19 from ('127.0.0.1', 54587)
2024-10-04 15:02:54 - Client 19 Exit
2024-10-04 15:02:54 - New Client number 20 from ('127.0.0.1', 54600)
2024-10-04 15:03:08 - Traceback (most recent call last):
  File "c:\Users\idanh\Desktop\Cyber\My Projects\Final Project\Main\server\server.py", line 837, in recv_data
    msg = encrypting.decrypt(msg, clients[tid].shared_secret)
          ^^^^^^^^^^^^^^^^^^^^^^^^^^^^^^^^^^^^^^^^^^^^^^^^^^^
  File "c:\Users\idanh\Desktop\Cyber\My Projects\Final Project\Main\server\modules\encrypting.py", line 32, in decrypt
    encrypted_text = b64decode(encrypted_text)
                     ^^^^^^^^^^^^^^^^^^^^^^^^^
  File "c:\Users\idanh\AppData\Local\Programs\Python\Python312\Lib\base64.py", line 88, in b64decode
    return binascii.a2b_base64(s, strict_mode=validate)
           ^^^^^^^^^^^^^^^^^^^^^^^^^^^^^^^^^^^^^^^^^^^^
binascii.Error: Invalid base64-encoded string: number of data characters (87421) cannot be 1 more than a multiple of 4
2024-10-04 15:03:08 - Traceback (most recent call last):
  File "c:\Users\idanh\Desktop\Cyber\My Projects\Final Project\Main\server\server.py", line 465, in protocol_build_reply
    save_file(cloud_path + "\\" + name, sock, tid)
  File "c:\Users\idanh\Desktop\Cyber\My Projects\Final Project\Main\server\server.py", line 63, in save_file
    raise Exception
Exception
2024-10-04 15:04:36 - Traceback (most recent call last):
  File "c:\Users\idanh\Desktop\Cyber\My Projects\Final Project\Main\server\server.py", line 465, in protocol_build_reply
    save_file(cloud_path + "\\" + name, sock, tid)
  File "c:\Users\idanh\Desktop\Cyber\My Projects\Final Project\Main\server\server.py", line 63, in save_file
    raise Exception
Exception

During handling of the above exception, another exception occurred:

Traceback (most recent call last):
  File "c:\Users\idanh\Desktop\Cyber\My Projects\Final Project\Main\server\server.py", line 756, in handle_request
    to_send = protocol_build_reply(request, tid, sock)
              ^^^^^^^^^^^^^^^^^^^^^^^^^^^^^^^^^^^^^^^^
  File "c:\Users\idanh\Desktop\Cyber\My Projects\Final Project\Main\server\server.py", line 474, in protocol_build_reply
    throw_file(sock, tid)
  File "c:\Users\idanh\Desktop\Cyber\My Projects\Final Project\Main\server\server.py", line 112, in throw_file
    raise Exception
Exception
2024-10-04 15:04:37 - Client 20 Exit
2024-10-04 15:04:38 - New Client number 21 from ('127.0.0.1', 54625)
2024-10-04 15:05:33 - Traceback (most recent call last):
  File "c:\Users\idanh\Desktop\Cyber\My Projects\Final Project\Main\server\server.py", line 465, in protocol_build_reply
    save_file(cloud_path + "\\" + name, sock, tid)
  File "c:\Users\idanh\Desktop\Cyber\My Projects\Final Project\Main\server\server.py", line 63, in save_file
    raise Exception
Exception
2024-10-04 15:05:33 - Traceback (most recent call last):
  File "c:\Users\idanh\Desktop\Cyber\My Projects\Final Project\Main\server\server.py", line 465, in protocol_build_reply
    save_file(cloud_path + "\\" + name, sock, tid)
  File "c:\Users\idanh\Desktop\Cyber\My Projects\Final Project\Main\server\server.py", line 63, in save_file
    raise Exception
Exception

During handling of the above exception, another exception occurred:

Traceback (most recent call last):
  File "c:\Users\idanh\Desktop\Cyber\My Projects\Final Project\Main\server\server.py", line 756, in handle_request
    to_send = protocol_build_reply(request, tid, sock)
              ^^^^^^^^^^^^^^^^^^^^^^^^^^^^^^^^^^^^^^^^
  File "c:\Users\idanh\Desktop\Cyber\My Projects\Final Project\Main\server\server.py", line 474, in protocol_build_reply
    throw_file(sock, tid)
  File "c:\Users\idanh\Desktop\Cyber\My Projects\Final Project\Main\server\server.py", line 112, in throw_file
    raise Exception
Exception
2024-10-04 15:05:34 - Client 21 Exit
2024-10-04 15:06:39 - New Client number 22 from ('127.0.0.1', 54654)
2024-10-04 15:06:45 - Traceback (most recent call last):
  File "c:\Users\idanh\Desktop\Cyber\My Projects\Final Project\Main\server\server.py", line 465, in protocol_build_reply
    save_file(cloud_path + "\\" + name, sock, tid)
  File "c:\Users\idanh\Desktop\Cyber\My Projects\Final Project\Main\server\server.py", line 63, in save_file
    raise Exception
Exception
2024-10-04 15:06:45 - Traceback (most recent call last):
  File "c:\Users\idanh\Desktop\Cyber\My Projects\Final Project\Main\server\server.py", line 465, in protocol_build_reply
    save_file(cloud_path + "\\" + name, sock, tid)
  File "c:\Users\idanh\Desktop\Cyber\My Projects\Final Project\Main\server\server.py", line 63, in save_file
    raise Exception
Exception

During handling of the above exception, another exception occurred:

Traceback (most recent call last):
  File "c:\Users\idanh\Desktop\Cyber\My Projects\Final Project\Main\server\server.py", line 756, in handle_request
    to_send = protocol_build_reply(request, tid, sock)
              ^^^^^^^^^^^^^^^^^^^^^^^^^^^^^^^^^^^^^^^^
  File "c:\Users\idanh\Desktop\Cyber\My Projects\Final Project\Main\server\server.py", line 474, in protocol_build_reply
    throw_file(sock, tid)
  File "c:\Users\idanh\Desktop\Cyber\My Projects\Final Project\Main\server\server.py", line 112, in throw_file
    raise Exception
Exception
2024-10-04 15:06:46 - Client 22 Exit
2024-10-04 15:06:58 - New Client number 23 from ('127.0.0.1', 54668)
2024-10-04 15:07:14 - Traceback (most recent call last):
  File "c:\Users\idanh\Desktop\Cyber\My Projects\Final Project\Main\server\server.py", line 465, in protocol_build_reply
    save_file(cloud_path + "\\" + name, sock, tid)
  File "c:\Users\idanh\Desktop\Cyber\My Projects\Final Project\Main\server\server.py", line 63, in save_file
    raise Exception
Exception
2024-10-04 15:07:14 - Traceback (most recent call last):
  File "c:\Users\idanh\Desktop\Cyber\My Projects\Final Project\Main\server\server.py", line 465, in protocol_build_reply
    save_file(cloud_path + "\\" + name, sock, tid)
  File "c:\Users\idanh\Desktop\Cyber\My Projects\Final Project\Main\server\server.py", line 63, in save_file
    raise Exception
Exception

During handling of the above exception, another exception occurred:

Traceback (most recent call last):
  File "c:\Users\idanh\Desktop\Cyber\My Projects\Final Project\Main\server\server.py", line 756, in handle_request
    to_send = protocol_build_reply(request, tid, sock)
              ^^^^^^^^^^^^^^^^^^^^^^^^^^^^^^^^^^^^^^^^
  File "c:\Users\idanh\Desktop\Cyber\My Projects\Final Project\Main\server\server.py", line 474, in protocol_build_reply
    throw_file(sock, tid)
  File "c:\Users\idanh\Desktop\Cyber\My Projects\Final Project\Main\server\server.py", line 112, in throw_file
    raise Exception
Exception
2024-10-04 15:07:15 - Client 23 Exit
2024-10-04 15:08:55 - New Client number 24 from ('127.0.0.1', 54700)
2024-10-04 15:09:07 - Traceback (most recent call last):
  File "c:\Users\idanh\Desktop\Cyber\My Projects\Final Project\Main\server\server.py", line 465, in protocol_build_reply
    save_file(cloud_path + "\\" + name, sock, tid)
  File "c:\Users\idanh\Desktop\Cyber\My Projects\Final Project\Main\server\server.py", line 63, in save_file
    raise Exception
Exception
2024-10-04 15:09:07 - Traceback (most recent call last):
  File "c:\Users\idanh\Desktop\Cyber\My Projects\Final Project\Main\server\server.py", line 465, in protocol_build_reply
    save_file(cloud_path + "\\" + name, sock, tid)
  File "c:\Users\idanh\Desktop\Cyber\My Projects\Final Project\Main\server\server.py", line 63, in save_file
    raise Exception
Exception

During handling of the above exception, another exception occurred:

Traceback (most recent call last):
  File "c:\Users\idanh\Desktop\Cyber\My Projects\Final Project\Main\server\server.py", line 756, in handle_request
    to_send = protocol_build_reply(request, tid, sock)
              ^^^^^^^^^^^^^^^^^^^^^^^^^^^^^^^^^^^^^^^^
  File "c:\Users\idanh\Desktop\Cyber\My Projects\Final Project\Main\server\server.py", line 474, in protocol_build_reply
    throw_file(sock, tid)
  File "c:\Users\idanh\Desktop\Cyber\My Projects\Final Project\Main\server\server.py", line 112, in throw_file
    raise Exception
Exception
2024-10-04 15:09:08 - Client 24 Exit
2024-10-04 15:10:02 - New Client number 25 from ('127.0.0.1', 54730)
2024-10-04 15:10:13 - Traceback (most recent call last):
  File "c:\Users\idanh\Desktop\Cyber\My Projects\Final Project\Main\server\server.py", line 465, in protocol_build_reply
    save_file(cloud_path + "\\" + name, sock, tid)
  File "c:\Users\idanh\Desktop\Cyber\My Projects\Final Project\Main\server\server.py", line 63, in save_file
    raise Exception
Exception
2024-10-04 15:10:13 - Traceback (most recent call last):
  File "c:\Users\idanh\Desktop\Cyber\My Projects\Final Project\Main\server\server.py", line 465, in protocol_build_reply
    save_file(cloud_path + "\\" + name, sock, tid)
  File "c:\Users\idanh\Desktop\Cyber\My Projects\Final Project\Main\server\server.py", line 63, in save_file
    raise Exception
Exception

During handling of the above exception, another exception occurred:

Traceback (most recent call last):
  File "c:\Users\idanh\Desktop\Cyber\My Projects\Final Project\Main\server\server.py", line 756, in handle_request
    to_send = protocol_build_reply(request, tid, sock)
              ^^^^^^^^^^^^^^^^^^^^^^^^^^^^^^^^^^^^^^^^
  File "c:\Users\idanh\Desktop\Cyber\My Projects\Final Project\Main\server\server.py", line 474, in protocol_build_reply
    throw_file(sock, tid)
  File "c:\Users\idanh\Desktop\Cyber\My Projects\Final Project\Main\server\server.py", line 112, in throw_file
    raise Exception
Exception
2024-10-04 15:10:14 - Client 25 Exit
2024-10-04 15:11:06 - New Client number 26 from ('127.0.0.1', 54749)
2024-10-04 15:11:14 - Client 26 Exit
2024-10-04 15:11:50 - New Client number 27 from ('127.0.0.1', 54767)
2024-10-04 15:12:18 - Traceback (most recent call last):
  File "c:\Users\idanh\Desktop\Cyber\My Projects\Final Project\Main\server\server.py", line 465, in protocol_build_reply
    save_file(cloud_path + "\\" + name, sock, tid)
  File "c:\Users\idanh\Desktop\Cyber\My Projects\Final Project\Main\server\server.py", line 63, in save_file
    raise Exception
Exception
2024-10-04 15:12:18 - Traceback (most recent call last):
  File "c:\Users\idanh\Desktop\Cyber\My Projects\Final Project\Main\server\server.py", line 465, in protocol_build_reply
    save_file(cloud_path + "\\" + name, sock, tid)
  File "c:\Users\idanh\Desktop\Cyber\My Projects\Final Project\Main\server\server.py", line 63, in save_file
    raise Exception
Exception

During handling of the above exception, another exception occurred:

Traceback (most recent call last):
  File "c:\Users\idanh\Desktop\Cyber\My Projects\Final Project\Main\server\server.py", line 756, in handle_request
    to_send = protocol_build_reply(request, tid, sock)
              ^^^^^^^^^^^^^^^^^^^^^^^^^^^^^^^^^^^^^^^^
  File "c:\Users\idanh\Desktop\Cyber\My Projects\Final Project\Main\server\server.py", line 474, in protocol_build_reply
    throw_file(sock, tid)
  File "c:\Users\idanh\Desktop\Cyber\My Projects\Final Project\Main\server\server.py", line 112, in throw_file
    raise Exception
Exception
2024-10-04 15:12:19 - Client 27 Exit
2024-10-04 15:15:55 - New Client number 28 from ('127.0.0.1', 54807)
2024-10-04 15:16:10 - Client 28 Exit
2024-10-04 15:16:10 - New Client number 29 from ('127.0.0.1', 54821)
2024-10-04 15:16:26 - Client 29 Exit
2024-10-04 15:16:26 - New Client number 30 from ('127.0.0.1', 54834)
2024-10-04 15:17:08 - Traceback (most recent call last):
  File "c:\Users\idanh\Desktop\Cyber\My Projects\Final Project\Main\server\server.py", line 465, in protocol_build_reply
    save_file(cloud_path + "\\" + name, sock, tid)
  File "c:\Users\idanh\Desktop\Cyber\My Projects\Final Project\Main\server\server.py", line 63, in save_file
    raise Exception
Exception
2024-10-04 15:17:08 - Traceback (most recent call last):
  File "c:\Users\idanh\Desktop\Cyber\My Projects\Final Project\Main\server\server.py", line 465, in protocol_build_reply
    save_file(cloud_path + "\\" + name, sock, tid)
  File "c:\Users\idanh\Desktop\Cyber\My Projects\Final Project\Main\server\server.py", line 63, in save_file
    raise Exception
Exception

During handling of the above exception, another exception occurred:

Traceback (most recent call last):
  File "c:\Users\idanh\Desktop\Cyber\My Projects\Final Project\Main\server\server.py", line 756, in handle_request
    to_send = protocol_build_reply(request, tid, sock)
              ^^^^^^^^^^^^^^^^^^^^^^^^^^^^^^^^^^^^^^^^
  File "c:\Users\idanh\Desktop\Cyber\My Projects\Final Project\Main\server\server.py", line 474, in protocol_build_reply
    throw_file(sock, tid)
  File "c:\Users\idanh\Desktop\Cyber\My Projects\Final Project\Main\server\server.py", line 112, in throw_file
    raise Exception
Exception
2024-10-04 15:17:09 - Client 30 Exit
2024-10-04 15:17:09 - New Client number 31 from ('127.0.0.1', 54851)
2024-10-04 15:17:36 - Client 31 Exit
2024-10-04 15:17:36 - New Client number 32 from ('127.0.0.1', 54863)
2024-10-04 15:19:10 - Client 32 Exit
2024-10-04 15:19:10 - New Client number 33 from ('127.0.0.1', 54882)
2024-10-04 15:19:47 - Client 33 Exit
2024-10-04 15:19:48 - New Client number 34 from ('127.0.0.1', 54895)
2024-10-04 15:20:17 - Client 34 Exit
2024-10-04 15:20:18 - New Client number 35 from ('127.0.0.1', 54908)
2024-10-04 15:20:42 - Client 35 Exit
2024-10-04 15:20:43 - New Client number 36 from ('127.0.0.1', 54923)
2024-10-04 15:22:30 - Client 36 Exit
2024-10-04 15:22:31 - New Client number 37 from ('127.0.0.1', 54947)
2024-10-04 15:23:21 - Client 37 Exit
2024-10-04 15:23:22 - New Client number 38 from ('127.0.0.1', 54965)
2024-10-04 15:24:11 - Client 38 Exit
2024-10-04 15:24:12 - New Client number 39 from ('127.0.0.1', 54983)
2024-10-04 15:24:28 - Client 39 Exit
2024-10-04 15:24:42 - New Client number 40 from ('127.0.0.1', 54999)
2024-10-04 15:25:44 - Client 40 Exit
2024-10-04 15:26:02 - New Client number 41 from ('127.0.0.1', 55020)
2024-10-04 15:26:08 - Client 41 Exit
2024-10-04 15:30:34 - New Client number 42 from ('127.0.0.1', 55073)
2024-10-04 15:31:54 - Client 42 Exit
2024-10-04 15:31:54 - New Client number 43 from ('127.0.0.1', 55094)
2024-10-04 15:33:09 - Client 43 Exit
2024-10-04 15:33:10 - New Client number 44 from ('127.0.0.1', 55115)
2024-10-04 15:33:19 - Client 44 Exit
2024-10-04 15:35:43 - New Client number 45 from ('127.0.0.1', 55148)
2024-10-04 15:37:43 - Client 45 Exit
2024-10-04 15:37:43 - New Client number 46 from ('127.0.0.1', 55164)
2024-10-04 15:44:34 - Client 46 Exit
2024-10-04 15:44:35 - New Client number 47 from ('127.0.0.1', 55215)
2024-10-04 15:45:31 - Traceback (most recent call last):
  File "c:\Users\idanh\Desktop\Cyber\My Projects\Final Project\Main\server\server.py", line 465, in protocol_build_reply
    save_file(cloud_path + "\\" + name, sock, tid)
  File "c:\Users\idanh\Desktop\Cyber\My Projects\Final Project\Main\server\server.py", line 63, in save_file
    raise Exception
Exception
2024-10-04 15:45:31 - Traceback (most recent call last):
  File "c:\Users\idanh\Desktop\Cyber\My Projects\Final Project\Main\server\server.py", line 465, in protocol_build_reply
    save_file(cloud_path + "\\" + name, sock, tid)
  File "c:\Users\idanh\Desktop\Cyber\My Projects\Final Project\Main\server\server.py", line 63, in save_file
    raise Exception
Exception

During handling of the above exception, another exception occurred:

Traceback (most recent call last):
  File "c:\Users\idanh\Desktop\Cyber\My Projects\Final Project\Main\server\server.py", line 756, in handle_request
    to_send = protocol_build_reply(request, tid, sock)
              ^^^^^^^^^^^^^^^^^^^^^^^^^^^^^^^^^^^^^^^^
  File "c:\Users\idanh\Desktop\Cyber\My Projects\Final Project\Main\server\server.py", line 474, in protocol_build_reply
    throw_file(sock, tid)
  File "c:\Users\idanh\Desktop\Cyber\My Projects\Final Project\Main\server\server.py", line 112, in throw_file
    raise Exception
Exception
2024-10-04 15:45:32 - Client 47 Exit
2024-10-04 15:45:33 - New Client number 48 from ('127.0.0.1', 55239)
2024-10-04 15:45:48 - Traceback (most recent call last):
  File "c:\Users\idanh\Desktop\Cyber\My Projects\Final Project\Main\server\server.py", line 465, in protocol_build_reply
    save_file(cloud_path + "\\" + name, sock, tid)
  File "c:\Users\idanh\Desktop\Cyber\My Projects\Final Project\Main\server\server.py", line 63, in save_file
    raise Exception
Exception
2024-10-04 15:45:48 - Traceback (most recent call last):
  File "c:\Users\idanh\Desktop\Cyber\My Projects\Final Project\Main\server\server.py", line 465, in protocol_build_reply
    save_file(cloud_path + "\\" + name, sock, tid)
  File "c:\Users\idanh\Desktop\Cyber\My Projects\Final Project\Main\server\server.py", line 63, in save_file
    raise Exception
Exception

During handling of the above exception, another exception occurred:

Traceback (most recent call last):
  File "c:\Users\idanh\Desktop\Cyber\My Projects\Final Project\Main\server\server.py", line 756, in handle_request
    to_send = protocol_build_reply(request, tid, sock)
              ^^^^^^^^^^^^^^^^^^^^^^^^^^^^^^^^^^^^^^^^
  File "c:\Users\idanh\Desktop\Cyber\My Projects\Final Project\Main\server\server.py", line 474, in protocol_build_reply
    throw_file(sock, tid)
  File "c:\Users\idanh\Desktop\Cyber\My Projects\Final Project\Main\server\server.py", line 112, in throw_file
    raise Exception
Exception
2024-10-04 15:45:49 - Client 48 Exit
2024-10-04 15:45:50 - New Client number 49 from ('127.0.0.1', 55252)
2024-10-04 15:46:19 - Traceback (most recent call last):
  File "c:\Users\idanh\Desktop\Cyber\My Projects\Final Project\Main\server\server.py", line 465, in protocol_build_reply
    save_file(cloud_path + "\\" + name, sock, tid)
  File "c:\Users\idanh\Desktop\Cyber\My Projects\Final Project\Main\server\server.py", line 63, in save_file
    raise Exception
Exception
2024-10-04 15:46:19 - Traceback (most recent call last):
  File "c:\Users\idanh\Desktop\Cyber\My Projects\Final Project\Main\server\server.py", line 465, in protocol_build_reply
    save_file(cloud_path + "\\" + name, sock, tid)
  File "c:\Users\idanh\Desktop\Cyber\My Projects\Final Project\Main\server\server.py", line 63, in save_file
    raise Exception
Exception

During handling of the above exception, another exception occurred:

Traceback (most recent call last):
  File "c:\Users\idanh\Desktop\Cyber\My Projects\Final Project\Main\server\server.py", line 756, in handle_request
    to_send = protocol_build_reply(request, tid, sock)
              ^^^^^^^^^^^^^^^^^^^^^^^^^^^^^^^^^^^^^^^^
  File "c:\Users\idanh\Desktop\Cyber\My Projects\Final Project\Main\server\server.py", line 474, in protocol_build_reply
    throw_file(sock, tid)
  File "c:\Users\idanh\Desktop\Cyber\My Projects\Final Project\Main\server\server.py", line 112, in throw_file
    raise Exception
Exception
2024-10-04 15:46:20 - Client 49 Exit
2024-10-04 15:46:21 - New Client number 50 from ('127.0.0.1', 55265)
2024-10-04 15:46:30 - Traceback (most recent call last):
  File "c:\Users\idanh\Desktop\Cyber\My Projects\Final Project\Main\server\server.py", line 465, in protocol_build_reply
    save_file(cloud_path + "\\" + name, sock, tid)
  File "c:\Users\idanh\Desktop\Cyber\My Projects\Final Project\Main\server\server.py", line 63, in save_file
    raise Exception
Exception
2024-10-04 15:46:30 - Traceback (most recent call last):
  File "c:\Users\idanh\Desktop\Cyber\My Projects\Final Project\Main\server\server.py", line 465, in protocol_build_reply
    save_file(cloud_path + "\\" + name, sock, tid)
  File "c:\Users\idanh\Desktop\Cyber\My Projects\Final Project\Main\server\server.py", line 63, in save_file
    raise Exception
Exception

During handling of the above exception, another exception occurred:

Traceback (most recent call last):
  File "c:\Users\idanh\Desktop\Cyber\My Projects\Final Project\Main\server\server.py", line 756, in handle_request
    to_send = protocol_build_reply(request, tid, sock)
              ^^^^^^^^^^^^^^^^^^^^^^^^^^^^^^^^^^^^^^^^
  File "c:\Users\idanh\Desktop\Cyber\My Projects\Final Project\Main\server\server.py", line 474, in protocol_build_reply
    throw_file(sock, tid)
  File "c:\Users\idanh\Desktop\Cyber\My Projects\Final Project\Main\server\server.py", line 112, in throw_file
    raise Exception
Exception
2024-10-04 15:46:31 - Client 50 Exit
2024-10-04 15:46:31 - New Client number 51 from ('127.0.0.1', 55277)
2024-10-04 15:46:41 - Traceback (most recent call last):
  File "c:\Users\idanh\Desktop\Cyber\My Projects\Final Project\Main\server\server.py", line 465, in protocol_build_reply
    save_file(cloud_path + "\\" + name, sock, tid)
  File "c:\Users\idanh\Desktop\Cyber\My Projects\Final Project\Main\server\server.py", line 63, in save_file
    raise Exception
Exception
2024-10-04 15:46:41 - Traceback (most recent call last):
  File "c:\Users\idanh\Desktop\Cyber\My Projects\Final Project\Main\server\server.py", line 465, in protocol_build_reply
    save_file(cloud_path + "\\" + name, sock, tid)
  File "c:\Users\idanh\Desktop\Cyber\My Projects\Final Project\Main\server\server.py", line 63, in save_file
    raise Exception
Exception

During handling of the above exception, another exception occurred:

Traceback (most recent call last):
  File "c:\Users\idanh\Desktop\Cyber\My Projects\Final Project\Main\server\server.py", line 756, in handle_request
    to_send = protocol_build_reply(request, tid, sock)
              ^^^^^^^^^^^^^^^^^^^^^^^^^^^^^^^^^^^^^^^^
  File "c:\Users\idanh\Desktop\Cyber\My Projects\Final Project\Main\server\server.py", line 474, in protocol_build_reply
    throw_file(sock, tid)
  File "c:\Users\idanh\Desktop\Cyber\My Projects\Final Project\Main\server\server.py", line 112, in throw_file
    raise Exception
Exception
2024-10-04 15:46:42 - Client 51 Exit
2024-10-04 15:46:43 - New Client number 52 from ('127.0.0.1', 55289)
2024-10-04 15:46:55 - Traceback (most recent call last):
  File "c:\Users\idanh\Desktop\Cyber\My Projects\Final Project\Main\server\server.py", line 465, in protocol_build_reply
    save_file(cloud_path + "\\" + name, sock, tid)
  File "c:\Users\idanh\Desktop\Cyber\My Projects\Final Project\Main\server\server.py", line 63, in save_file
    raise Exception
Exception
2024-10-04 15:46:55 - Traceback (most recent call last):
  File "c:\Users\idanh\Desktop\Cyber\My Projects\Final Project\Main\server\server.py", line 465, in protocol_build_reply
    save_file(cloud_path + "\\" + name, sock, tid)
  File "c:\Users\idanh\Desktop\Cyber\My Projects\Final Project\Main\server\server.py", line 63, in save_file
    raise Exception
Exception

During handling of the above exception, another exception occurred:

Traceback (most recent call last):
  File "c:\Users\idanh\Desktop\Cyber\My Projects\Final Project\Main\server\server.py", line 756, in handle_request
    to_send = protocol_build_reply(request, tid, sock)
              ^^^^^^^^^^^^^^^^^^^^^^^^^^^^^^^^^^^^^^^^
  File "c:\Users\idanh\Desktop\Cyber\My Projects\Final Project\Main\server\server.py", line 474, in protocol_build_reply
    throw_file(sock, tid)
  File "c:\Users\idanh\Desktop\Cyber\My Projects\Final Project\Main\server\server.py", line 112, in throw_file
    raise Exception
Exception
2024-10-04 15:46:56 - Client 52 Exit
2024-10-04 15:46:56 - New Client number 53 from ('127.0.0.1', 55301)
2024-10-04 15:47:57 - Traceback (most recent call last):
  File "c:\Users\idanh\Desktop\Cyber\My Projects\Final Project\Main\server\server.py", line 465, in protocol_build_reply
    save_file(cloud_path + "\\" + name, sock, tid)
  File "c:\Users\idanh\Desktop\Cyber\My Projects\Final Project\Main\server\server.py", line 63, in save_file
    raise Exception
Exception
2024-10-04 15:47:57 - Traceback (most recent call last):
  File "c:\Users\idanh\Desktop\Cyber\My Projects\Final Project\Main\server\server.py", line 465, in protocol_build_reply
    save_file(cloud_path + "\\" + name, sock, tid)
  File "c:\Users\idanh\Desktop\Cyber\My Projects\Final Project\Main\server\server.py", line 63, in save_file
    raise Exception
Exception

During handling of the above exception, another exception occurred:

Traceback (most recent call last):
  File "c:\Users\idanh\Desktop\Cyber\My Projects\Final Project\Main\server\server.py", line 756, in handle_request
    to_send = protocol_build_reply(request, tid, sock)
              ^^^^^^^^^^^^^^^^^^^^^^^^^^^^^^^^^^^^^^^^
  File "c:\Users\idanh\Desktop\Cyber\My Projects\Final Project\Main\server\server.py", line 474, in protocol_build_reply
    throw_file(sock, tid)
  File "c:\Users\idanh\Desktop\Cyber\My Projects\Final Project\Main\server\server.py", line 112, in throw_file
    raise Exception
Exception
2024-10-04 15:47:58 - Client 53 Exit
2024-10-04 15:47:58 - New Client number 54 from ('127.0.0.1', 55322)
2024-10-04 15:51:49 - Client 54 Exit
2024-10-04 15:51:50 - New Client number 55 from ('127.0.0.1', 55349)
2024-10-04 15:52:11 - Client 55 Exit
2024-10-04 15:52:51 - New Client number 56 from ('127.0.0.1', 55371)
2024-10-04 15:53:29 - Client 56 Exit
2024-10-04 15:53:30 - New Client number 57 from ('127.0.0.1', 55383)
2024-10-04 15:53:38 - Client 57 Exit
2024-10-04 15:53:50 - New Client number 58 from ('127.0.0.1', 55402)
2024-10-04 15:54:44 - Client 58 Exit
2024-10-04 15:54:44 - New Client number 59 from ('127.0.0.1', 55416)
2024-10-04 15:55:08 - Client 59 Exit
2024-10-05 14:51:59 - Server listening on ('0.0.0.0', 31026)
2024-10-05 14:52:00 - Main thread: before accepting ...
2024-10-05 14:52:04 - New Client number 1 from ('127.0.0.1', 49897)
2024-10-05 14:52:17 - Client 1 Exit
2024-10-05 14:55:04 - New Client number 2 from ('127.0.0.1', 50060)
2024-10-05 14:57:13 - Client 2 Exit
2024-10-05 14:57:13 - New Client number 3 from ('127.0.0.1', 50203)
2024-10-05 14:58:19 - Client 3 Exit
2024-10-05 14:58:19 - New Client number 4 from ('127.0.0.1', 50236)
2024-10-05 14:59:06 - Client 4 Exit
2024-10-05 14:59:06 - New Client number 5 from ('127.0.0.1', 50249)
2024-10-05 15:00:27 - Client 5 Exit
2024-10-05 15:00:27 - New Client number 6 from ('127.0.0.1', 50284)
2024-10-05 15:01:19 - Client 6 Exit
2024-10-05 15:01:20 - New Client number 7 from ('127.0.0.1', 50303)
2024-10-05 15:02:16 - Client 7 Exit
2024-10-05 15:02:17 - New Client number 8 from ('127.0.0.1', 50323)
2024-10-05 15:03:49 - Client 8 Exit
2024-10-05 15:03:50 - New Client number 9 from ('127.0.0.1', 50351)
2024-10-05 15:10:00 - Client 9 Exit
2024-10-05 15:10:00 - New Client number 10 from ('127.0.0.1', 50425)
2024-10-05 15:12:00 - Client 10 Exit
2024-10-05 15:12:01 - New Client number 11 from ('127.0.0.1', 50453)
2024-10-05 15:13:58 - Client 11 Exit
2024-10-05 15:13:59 - New Client number 12 from ('127.0.0.1', 50475)
2024-10-05 15:14:24 - Client 12 Exit
2024-10-05 15:14:25 - New Client number 13 from ('127.0.0.1', 50488)
2024-10-05 15:17:24 - Client 13 Exit
2024-10-05 15:17:25 - New Client number 14 from ('127.0.0.1', 50536)
2024-10-05 15:18:56 - Client 14 Exit
2024-10-05 15:18:56 - New Client number 15 from ('127.0.0.1', 50555)
2024-10-05 15:19:23 - Client 15 Exit
2024-10-05 15:19:24 - New Client number 16 from ('127.0.0.1', 50566)
2024-10-05 15:19:30 - Client 16 Exit
2024-10-05 15:19:30 - New Client number 17 from ('127.0.0.1', 50577)
2024-10-05 15:19:48 - Client 17 Exit
2024-10-05 15:19:49 - New Client number 18 from ('127.0.0.1', 50592)
2024-10-05 15:20:48 - Client 18 Exit
2024-10-05 15:20:49 - New Client number 19 from ('127.0.0.1', 50628)
2024-10-05 15:23:19 - Client 19 Exit
2024-10-05 15:23:19 - New Client number 20 from ('127.0.0.1', 50652)
2024-10-05 15:24:01 - Client 20 Exit
2024-10-05 15:24:03 - Server listening on ('0.0.0.0', 31026)
2024-10-05 15:24:03 - Main thread: before accepting ...
2024-10-05 15:24:03 - New Client number 1 from ('127.0.0.1', 50664)
2024-10-05 15:24:43 - Client 1 Exit
2024-10-05 15:24:43 - New Client number 2 from ('127.0.0.1', 50686)
2024-10-05 15:25:30 - Server listening on ('0.0.0.0', 31026)
2024-10-05 15:25:30 - Main thread: before accepting ...
2024-10-05 15:25:30 - New Client number 1 from ('127.0.0.1', 50717)
2024-10-05 15:26:44 - Client 1 Exit
2024-10-05 15:26:44 - New Client number 2 from ('127.0.0.1', 50738)
2024-10-05 15:28:17 - Client 2 Exit
2024-10-05 15:28:17 - New Client number 3 from ('127.0.0.1', 50756)
2024-10-05 15:40:14 - Client 3 Exit
2024-10-05 15:40:14 - New Client number 4 from ('127.0.0.1', 50814)
2024-10-05 15:40:36 - Client 4 Exit
2024-10-05 15:40:37 - New Client number 5 from ('127.0.0.1', 50826)
2024-10-05 15:40:56 - Client 5 Exit
2024-10-05 15:41:59 - New Client number 6 from ('127.0.0.1', 50843)
2024-10-05 15:42:33 - Client 6 Exit
2024-10-05 15:42:34 - New Client number 7 from ('127.0.0.1', 50854)
2024-10-05 15:43:25 - Client 7 Exit
2024-10-05 15:43:25 - New Client number 8 from ('127.0.0.1', 50872)
2024-10-05 15:44:10 - Client 8 Exit
2024-10-05 15:44:11 - New Client number 9 from ('127.0.0.1', 50890)
2024-10-05 15:44:19 - Client 9 Exit
2024-10-05 15:46:02 - New Client number 10 from ('127.0.0.1', 50919)
2024-10-05 15:46:31 - Client 10 Exit
2024-10-05 15:46:32 - New Client number 11 from ('127.0.0.1', 50933)
2024-10-05 15:48:34 - Client 11 Exit
2024-10-05 15:48:34 - New Client number 12 from ('127.0.0.1', 50945)
2024-10-05 15:49:46 - Client 12 Exit
2024-10-05 15:49:47 - New Client number 13 from ('127.0.0.1', 50961)
2024-10-05 15:50:31 - Client 13 Exit
2024-10-05 15:50:31 - New Client number 14 from ('127.0.0.1', 50987)
2024-10-05 15:50:55 - Client 14 Exit
2024-10-05 15:50:55 - New Client number 15 from ('127.0.0.1', 51001)
2024-10-05 15:55:56 - Client 15 Exit
2024-10-05 15:55:57 - New Client number 16 from ('127.0.0.1', 51057)
2024-10-05 15:56:06 - Client 16 Exit
2024-10-05 15:57:03 - New Client number 17 from ('127.0.0.1', 51079)
2024-10-05 15:58:53 - Client 17 Exit
2024-10-05 15:58:54 - New Client number 18 from ('127.0.0.1', 51106)
2024-10-05 15:59:23 - Client 18 Exit
2024-10-05 15:59:24 - New Client number 19 from ('127.0.0.1', 51122)
2024-10-05 15:59:47 - Client 19 Exit
2024-10-05 15:59:47 - New Client number 20 from ('127.0.0.1', 51134)
2024-10-05 16:00:25 - Client 20 Exit
2024-10-05 16:00:26 - New Client number 21 from ('127.0.0.1', 51156)
2024-10-05 16:00:47 - Client 21 Exit
2024-10-05 16:00:47 - New Client number 22 from ('127.0.0.1', 51169)
2024-10-05 16:00:55 - Client 22 Exit
2024-10-05 16:01:15 - New Client number 23 from ('127.0.0.1', 51197)
2024-10-05 16:05:16 - Client 23 Exit
2024-10-05 16:05:16 - New Client number 24 from ('127.0.0.1', 51280)
2024-10-05 16:06:04 - Client 24 Exit
2024-10-05 16:06:04 - New Client number 25 from ('127.0.0.1', 51295)
2024-10-05 16:06:14 - Client 25 Exit
2024-10-05 16:06:43 - New Client number 26 from ('127.0.0.1', 51314)
2024-10-05 16:07:07 - Client 26 Exit
2024-10-05 16:07:10 - Server listening on ('0.0.0.0', 31026)
2024-10-05 16:07:11 - Main thread: before accepting ...
2024-10-05 16:07:14 - New Client number 1 from ('127.0.0.1', 51339)
2024-10-05 16:07:23 - Traceback (most recent call last):
  File "c:\Users\idanh\Desktop\Cyber\My Projects\Final Project\Main\server\server.py", line 757, in handle_request
    to_send = protocol_build_reply(request, tid, sock)
              ^^^^^^^^^^^^^^^^^^^^^^^^^^^^^^^^^^^^^^^^
  File "c:\Users\idanh\Desktop\Cyber\My Projects\Final Project\Main\server\server.py", line 541, in protocol_build_reply
    send_data(sock, tid, len(zip_buffer.getbuffer()).encode())
                         ^^^^^^^^^^^^^^^^^^^^^^^^^^^^^^^^^^
AttributeError: 'int' object has no attribute 'encode'
2024-10-05 16:07:27 - Client 1 Exit
