2025-01-15 11:20:40 - recieved ip and port from server: ('172.16.20.119', '3102')
2025-01-15 11:20:41 - Login was succesfull for user: a
2025-01-15 11:20:41 - File data recieved 0
2025-01-15 11:20:41 - Profile picture was recieved
2025-01-15 11:20:41 - Got files
2025-01-15 11:20:41 - Current used storage is 74.808
2025-01-15 11:20:41 - Got directories
2025-01-15 11:22:28 - recieved ip and port from server: ('172.16.20.119', '3102')
2025-01-15 11:22:28 - Login was succesfull for user: a
2025-01-15 11:22:29 - File data recieved 0
2025-01-15 11:22:29 - Profile picture was recieved
2025-01-15 11:22:29 - Got files
2025-01-15 11:22:29 - Current used storage is 74.808
2025-01-15 11:22:29 - Got directories
2025-01-15 11:24:51 - recieved ip and port from server: ('172.16.20.119', '3102')
2025-01-15 11:24:52 - Login was succesfull for user: a
2025-01-15 11:24:52 - File data recieved 0
2025-01-15 11:24:52 - Profile picture was recieved
2025-01-15 11:24:52 - Got files
2025-01-15 11:24:52 - Current used storage is 74.808
2025-01-15 11:24:52 - Got directories
2025-01-15 12:22:24 - recieved ip and port from server: ('192.168.56.1', '3102')
2025-01-15 12:22:26 - recieved ip and port from server: ('192.168.56.1', '3102')
2025-01-15 12:22:48 - recieved ip and port from server: ('192.168.56.1', '3102')
2025-01-15 12:22:50 - recieved ip and port from server: ('192.168.56.1', '3102')
2025-01-15 12:28:16 - recieved ip and port from server: ('172.16.20.119', '3102')
2025-01-15 12:28:16 - Login was succesfull for user: a
2025-01-15 12:28:16 - File data recieved 0
2025-01-15 12:28:16 - Profile picture was recieved
2025-01-15 12:28:16 - Current used storage is 74.808
2025-01-15 12:28:16 - Got files
2025-01-15 12:28:16 - Got directories
2025-01-15 12:28:29 - No server found
2025-01-15 12:28:34 - No server found
2025-01-15 12:29:14 - No server found
2025-01-15 12:29:19 - No server found
2025-01-15 12:30:02 - No server found
2025-01-15 12:30:08 - No server found
2025-01-15 12:34:01 - No server found
2025-01-15 12:34:06 - No server found
2025-01-15 12:35:07 - No server found
2025-01-15 12:35:12 - No server found
2025-01-15 12:36:44 - No server found
2025-01-15 12:36:49 - No server found
2025-01-15 12:38:55 - No server found
2025-01-15 12:39:00 - No server found
2025-01-15 12:39:37 - No server found
2025-01-15 12:39:42 - No server found
2025-01-15 12:52:44 - No server found
2025-01-15 12:52:49 - No server found
2025-01-15 12:57:37 - recieved ip and port from server: ('172.16.20.119', '3102')
2025-01-15 12:57:37 - Login was succesfull for user: a
2025-01-15 12:57:38 - File data recieved 0
2025-01-15 12:57:38 - Profile picture was recieved
2025-01-15 12:57:38 - Current used storage is 74.808
2025-01-15 12:57:38 - Got files
2025-01-15 12:57:38 - Got directories
2025-01-15 13:10:50 - recieved ip and port from server: ('172.16.20.119', '3102')
2025-01-15 13:10:50 - Login was succesfull for user: a
2025-01-15 13:10:50 - File data recieved 0
2025-01-15 13:10:50 - Profile picture was recieved
2025-01-15 13:10:50 - Current used storage is 74.808
2025-01-15 13:10:50 - Got files
2025-01-15 13:10:50 - Got directories
2025-01-15 13:10:52 - Logout succesfull
2025-01-15 13:12:04 - recieved ip and port from server: ('172.16.20.119', '3102')
2025-01-15 13:12:05 - Login was succesfull for user: a
2025-01-15 13:12:05 - File data recieved 0
2025-01-15 13:12:05 - Profile picture was recieved
2025-01-15 13:12:05 - Got files
2025-01-15 13:12:05 - Current used storage is 74.808
2025-01-15 13:12:05 - Got directories
2025-01-15 13:15:06 - recieved ip and port from server: ('172.16.20.119', '3102')
2025-01-15 13:15:06 - Login was succesfull for user: a
2025-01-15 13:15:06 - File data recieved 0
2025-01-15 13:15:06 - Profile picture was recieved
2025-01-15 13:15:06 - Got files
2025-01-15 13:15:06 - Current used storage is 74.808
2025-01-15 13:15:06 - Got directories
2025-01-15 13:20:24 - Traceback (most recent call last):
  File "C:\Users\idanh\Desktop\Cyber\My Projects\Final-Project\Main\client\client.pyw", line 1962, in search_server
    netmask = get_subnet_mask()  # Adjust based on your network configuration
              ^^^^^^^^^^^^^^^^^
  File "C:\Users\idanh\Desktop\Cyber\My Projects\Final-Project\Main\client\client.pyw", line 1953, in get_subnet_mask
    if addr.family == psutil.AF_INET and addr.address != '127.0.0.1':  # Ignore localhost
                      ^^^^^^^^^^^^^^
AttributeError: module 'psutil' has no attribute 'AF_INET'
2025-01-15 13:20:26 - Traceback (most recent call last):
  File "C:\Users\idanh\Desktop\Cyber\My Projects\Final-Project\Main\client\client.pyw", line 1915, in connect_server
    sock.connect((ip, int(port)))
ConnectionRefusedError: [WinError 10061] No connection could be made because the target machine actively refused it

During handling of the above exception, another exception occurred:

Traceback (most recent call last):
  File "C:\Users\idanh\Desktop\Cyber\My Projects\Final-Project\Main\client\client.pyw", line 1962, in search_server
    netmask = get_subnet_mask()  # Adjust based on your network configuration
              ^^^^^^^^^^^^^^^^^
  File "C:\Users\idanh\Desktop\Cyber\My Projects\Final-Project\Main\client\client.pyw", line 1953, in get_subnet_mask
    if addr.family == psutil.AF_INET and addr.address != '127.0.0.1':  # Ignore localhost
                      ^^^^^^^^^^^^^^
AttributeError: module 'psutil' has no attribute 'AF_INET'
2025-01-15 13:20:39 - Traceback (most recent call last):
  File "c:\Users\idanh\Desktop\Cyber\My Projects\Final-Project\Main\client\client.pyw", line 1962, in search_server
    netmask = get_subnet_mask()  # Adjust based on your network configuration
              ^^^^^^^^^^^^^^^^^
  File "c:\Users\idanh\Desktop\Cyber\My Projects\Final-Project\Main\client\client.pyw", line 1953, in get_subnet_mask
    if addr.family == psutil.AF_INET and addr.address != '127.0.0.1':  # Ignore localhost
                      ^^^^^^^^^^^^^^
AttributeError: module 'psutil' has no attribute 'AF_INET'
2025-01-15 13:20:41 - Traceback (most recent call last):
  File "c:\Users\idanh\Desktop\Cyber\My Projects\Final-Project\Main\client\client.pyw", line 1915, in connect_server
    sock.connect((ip, int(port)))
ConnectionRefusedError: [WinError 10061] No connection could be made because the target machine actively refused it

During handling of the above exception, another exception occurred:

Traceback (most recent call last):
  File "c:\Users\idanh\Desktop\Cyber\My Projects\Final-Project\Main\client\client.pyw", line 1962, in search_server
    netmask = get_subnet_mask()  # Adjust based on your network configuration
              ^^^^^^^^^^^^^^^^^
  File "c:\Users\idanh\Desktop\Cyber\My Projects\Final-Project\Main\client\client.pyw", line 1953, in get_subnet_mask
    if addr.family == psutil.AF_INET and addr.address != '127.0.0.1':  # Ignore localhost
                      ^^^^^^^^^^^^^^
AttributeError: module 'psutil' has no attribute 'AF_INET'
2025-01-15 13:24:34 - recieved ip and port from server: ('172.16.20.119', '3102')
2025-01-15 13:24:34 - Login was succesfull for user: a
2025-01-15 13:24:34 - File data recieved 0
2025-01-15 13:24:34 - Profile picture was recieved
2025-01-15 13:24:34 - Got files
2025-01-15 13:24:34 - Current used storage is 74.808
2025-01-15 13:24:35 - Got directories
2025-01-15 13:27:52 - recieved ip and port from server: ('172.16.20.119', '3102')
2025-01-15 13:27:52 - Login was succesfull for user: a
2025-01-15 13:27:52 - File data recieved 0
2025-01-15 13:27:52 - Profile picture was recieved
2025-01-15 13:27:52 - Current used storage is 74.808
2025-01-15 13:27:52 - Got files
2025-01-15 13:27:52 - Got directories
2025-01-21 20:49:49 - Netmask: 255.255.255.0
2025-01-21 20:49:49 - IP: 192.168.56.1
2025-01-21 20:49:49 - recieved ip and port from server: ('192.168.56.1', '3102')
2025-01-21 20:49:49 - Login was succesfull for user: a
2025-01-21 20:49:49 - File data recieved 0
2025-01-21 20:49:49 - Profile picture was recieved
2025-01-21 20:49:49 - Got files
2025-01-21 20:49:49 - Current used storage is 74.808
2025-01-21 20:49:50 - Got directories
2025-01-21 20:57:13 - Netmask: {'interface': 'Ethernet', 'ip_address': '192.168.1.122', 'subnet_mask': '255.255.255.0'}
2025-01-21 20:57:13 - IP: 192.168.56.1
2025-01-21 20:57:13 - Traceback (most recent call last):
  File "c:\Users\idanh\Desktop\Cyber\My Projects\Final Project\Main\client\client.pyw", line 2006, in search_server
    broadcast_address = get_broadcast_address(socket.gethostbyname(socket.gethostname()), netmask)
                        ^^^^^^^^^^^^^^^^^^^^^^^^^^^^^^^^^^^^^^^^^^^^^^^^^^^^^^^^^^^^^^^^^^^^^^^^^^
  File "c:\Users\idanh\Desktop\Cyber\My Projects\Final Project\Main\client\client.pyw", line 1944, in get_broadcast_address
    netmask_binary = struct.unpack('>I', socket.inet_aton(netmask))[0]
                                         ^^^^^^^^^^^^^^^^^^^^^^^^^
TypeError: inet_aton() argument 1 must be str, not dict
2025-01-21 20:57:15 - Netmask: {'interface': 'Ethernet', 'ip_address': '192.168.1.122', 'subnet_mask': '255.255.255.0'}
2025-01-21 20:57:15 - IP: 192.168.56.1
2025-01-21 20:57:15 - Traceback (most recent call last):
  File "c:\Users\idanh\Desktop\Cyber\My Projects\Final Project\Main\client\client.pyw", line 1915, in connect_server
    sock.connect((ip, int(port)))
ConnectionRefusedError: [WinError 10061] No connection could be made because the target machine actively refused it

During handling of the above exception, another exception occurred:

Traceback (most recent call last):
  File "c:\Users\idanh\Desktop\Cyber\My Projects\Final Project\Main\client\client.pyw", line 2006, in search_server
    broadcast_address = get_broadcast_address(socket.gethostbyname(socket.gethostname()), netmask)
                        ^^^^^^^^^^^^^^^^^^^^^^^^^^^^^^^^^^^^^^^^^^^^^^^^^^^^^^^^^^^^^^^^^^^^^^^^^^
  File "c:\Users\idanh\Desktop\Cyber\My Projects\Final Project\Main\client\client.pyw", line 1944, in get_broadcast_address
    netmask_binary = struct.unpack('>I', socket.inet_aton(netmask))[0]
                                         ^^^^^^^^^^^^^^^^^^^^^^^^^
TypeError: inet_aton() argument 1 must be str, not dict
2025-01-21 20:57:50 - Netmask: 255.255.255.0
2025-01-21 20:57:50 - IP: 192.168.56.1
2025-01-21 20:57:50 - recieved ip and port from server: ('192.168.56.1', '3102')
2025-01-21 20:57:50 - Login was succesfull for user: a
2025-01-21 20:57:50 - File data recieved 0
2025-01-21 20:57:50 - Profile picture was recieved
2025-01-21 20:57:50 - Current used storage is 74.808
2025-01-21 20:57:50 - Got files
2025-01-21 20:57:50 - Got directories
2025-01-21 20:58:21 - Netmask: 255.255.255.0
2025-01-21 20:58:21 - IP: 192.168.56.1
2025-01-21 20:58:21 - recieved ip and port from server: ('192.168.56.1', '3102')
2025-01-21 20:58:21 - Login was succesfull for user: a
2025-01-21 20:58:21 - File data recieved 0
2025-01-21 20:58:21 - Profile picture was recieved
2025-01-21 20:58:21 - Current used storage is 74.808
2025-01-21 20:58:21 - Got directories
2025-01-21 20:58:21 - Got files
2025-01-21 20:58:31 - Netmask: 255.255.255.0
2025-01-21 20:58:31 - IP: 192.168.56.1
2025-01-21 20:58:34 - No server found
2025-01-21 20:58:36 - Netmask: 255.255.255.0
2025-01-21 20:58:36 - IP: 192.168.56.1
2025-01-21 20:58:39 - No server found
2025-01-21 21:00:06 - Netmask: 255.255.255.0
2025-01-21 21:00:06 - IP: 192.168.1.122
2025-01-21 21:00:06 - recieved ip and port from server: ('192.168.1.247', '3102')
2025-01-21 21:00:07 - Login was succesfull for user: a
2025-01-21 21:00:07 - File data recieved 0
2025-01-21 21:00:07 - Profile picture was recieved
2025-01-21 21:00:07 - Current used storage is 74.808
2025-01-21 21:00:07 - Got directories
2025-01-21 21:00:07 - Got files
2025-01-21 21:00:55 - Netmask: 255.255.255.0
2025-01-21 21:00:55 - IP: 192.168.1.122
2025-01-21 21:00:55 - recieved ip and port from server: ('192.168.56.1', '3102')
2025-01-21 21:00:55 - Login was succesfull for user: a
2025-01-21 21:00:55 - File data recieved 0
2025-01-21 21:00:55 - Profile picture was recieved
2025-01-21 21:00:55 - Current used storage is 74.808
2025-01-21 21:00:55 - Got files
2025-01-21 21:00:55 - Got directories
2025-01-21 21:01:10 - Netmask: 255.255.255.0
2025-01-21 21:01:10 - IP: 192.168.1.122
2025-01-21 21:01:10 - recieved ip and port from server: ('192.168.56.1', '3102')
2025-01-21 21:01:10 - Login was succesfull for user: a
2025-01-21 21:01:10 - File data recieved 0
2025-01-21 21:01:10 - Profile picture was recieved
2025-01-21 21:01:10 - Current used storage is 74.808
2025-01-21 21:01:10 - Got files
2025-01-21 21:01:10 - Got directories
2025-01-21 21:02:32 - Netmask: 255.255.255.0
2025-01-21 21:02:32 - IP: 192.168.1.122
2025-01-21 21:02:32 - recieved ip and port from server: ('192.168.56.1', '3102')
2025-01-21 21:02:32 - Login was succesfull for user: a
2025-01-21 21:02:32 - File data recieved 0
2025-01-21 21:02:32 - Profile picture was recieved
2025-01-21 21:02:32 - Got files
2025-01-21 21:02:32 - Current used storage is 74.808
2025-01-21 21:02:32 - Got directories
2025-01-21 21:03:14 - Netmask: 255.255.255.0
2025-01-21 21:03:14 - IP: 192.168.1.122
2025-01-21 21:03:14 - recieved ip and port from server: ('192.168.1.122', '3102')
2025-01-21 21:03:14 - Login was succesfull for user: a
2025-01-21 21:03:14 - File data recieved 0
2025-01-21 21:03:15 - Profile picture was recieved
2025-01-21 21:03:15 - Current used storage is 74.808
2025-01-21 21:03:15 - Got files
2025-01-21 21:03:15 - Got directories
2025-01-21 21:04:53 - Netmask: 255.255.255.0
2025-01-21 21:04:53 - IP: 192.168.1.122
2025-01-21 21:04:53 - recieved ip and port from server: ('192.168.1.247', '3102')
2025-01-21 21:04:53 - Login was succesfull for user: a
2025-01-21 21:04:53 - File data recieved 0
2025-01-21 21:04:53 - Profile picture was recieved
2025-01-21 21:04:53 - Got files
2025-01-21 21:04:53 - Current used storage is 74.808
2025-01-21 21:04:53 - Got directories
2025-01-21 21:05:26 - Netmask: 255.255.255.0
2025-01-21 21:05:26 - IP: 192.168.1.122
2025-01-21 21:05:27 - recieved ip and port from server: ('192.168.1.122', '3102')
2025-01-21 21:05:27 - Login was succesfull for user: a
2025-01-21 21:05:27 - File data recieved 0
2025-01-21 21:05:27 - Profile picture was recieved
2025-01-21 21:05:27 - Got files
2025-01-21 21:05:27 - Current used storage is 74.808
2025-01-21 21:05:27 - Got directories
2025-01-21 21:13:40 - Traceback (most recent call last):
  File "c:\Users\idanh\Desktop\Cyber\My Projects\Final Project\Main\client\client.pyw", line 1964, in main
    network = networking.Networking()
              ^^^^^^^^^^^^^^^^^^^^^^^
TypeError: Networking.__init__() missing 1 required positional argument: 'log'
2025-01-21 21:13:52 - Netmask: 255.255.255.0
2025-01-21 21:13:52 - IP: 192.168.1.122
2025-01-21 21:13:53 - Traceback (most recent call last):
  File "c:\Users\idanh\Desktop\Cyber\My Projects\Final Project\Main\client\modules\key_exchange.py", line 10, in rsa_exchange
    send_data_wrap(b"RSAR", False)
    ^^^^^^^^^^^^^^
NameError: name 'send_data_wrap' is not defined
2025-01-21 21:21:05 - Netmask: 255.255.255.0
2025-01-21 21:21:05 - IP: 192.168.1.122
2025-01-21 21:21:05 - Netmask: 255.255.255.0
2025-01-21 21:21:05 - IP: 192.168.1.122
2025-01-21 21:21:38 - Netmask: 255.255.255.0
2025-01-21 21:21:38 - IP: 192.168.1.122
2025-01-21 21:22:15 - Netmask: 255.255.255.0
2025-01-21 21:22:15 - IP: 192.168.1.122
2025-01-21 21:23:00 - Traceback (most recent call last):
  File "c:\Users\idanh\Desktop\Cyber\My Projects\Final Project\Main\client\client.pyw", line 1918, in connect_server
    shared_secret = exchange.rsa_exchange(sock)
                   ^^^^^^^^^^^^^^^^^^^^^^^^^^^
TypeError: Key_Exchange.rsa_exchange() takes 1 positional argument but 2 were given
2025-01-21 21:23:00 - Traceback (most recent call last):
  File "c:\Users\idanh\Desktop\Cyber\My Projects\Final Project\Main\client\client.pyw", line 1918, in connect_server
    shared_secret = exchange.rsa_exchange(sock)
                   ^^^^^^^^^^^^^^^^^^^^^^^^^^^
TypeError: Key_Exchange.rsa_exchange() takes 1 positional argument but 2 were given

During handling of the above exception, another exception occurred:

Traceback (most recent call last):
  File "c:\Users\idanh\Desktop\Cyber\My Projects\Final Project\Main\client\client.pyw", line 1918, in connect_server
    shared_secret = exchange.rsa_exchange(sock)
                   ^^^^^^^^^^^^^^^^^^^^^^^^^^^
TypeError: Key_Exchange.rsa_exchange() takes 1 positional argument but 2 were given
2025-01-21 21:23:33 - Traceback (most recent call last):
  File "c:\Users\idanh\Desktop\Cyber\My Projects\Final Project\Main\client\modules\key_exchange.py", line 14, in rsa_exchange
    s_public_key = self.recv_rsa_key(self.network.sock)
                   ^^^^^^^^^^^^^^^^^^^^^^^^^^^^^^^^^^^^
TypeError: Key_Exchange.recv_rsa_key() takes 1 positional argument but 2 were given
2025-01-21 21:23:52 - Traceback (most recent call last):
  File "c:\Users\idanh\Desktop\Cyber\My Projects\Final Project\Main\client\modules\key_exchange.py", line 14, in rsa_exchange
    s_public_key = self.recv_rsa_key(self.network.sock)
                   ^^^^^^^^^^^^^^^^^^^^^^^^^^^^^^^^^^^^
TypeError: Key_Exchange.recv_rsa_key() takes 1 positional argument but 2 were given
2025-01-21 21:24:03 - Login was succesfull for user: a
2025-01-21 21:24:03 - File data recieved 0
2025-01-21 21:24:03 - Profile picture was recieved
2025-01-21 21:24:03 - Current used storage is 74.808
2025-01-21 21:24:03 - Got files
2025-01-21 21:24:03 - Got directories
2025-01-21 21:24:15 - Succesfully moved to
2025-01-21 21:24:15 - Got files
2025-01-21 21:24:15 - Got directories
2025-01-21 21:24:15 - Current used storage is 74.808
2025-01-21 21:24:16 - Succesfully moved to
2025-01-21 21:24:16 - Current used storage is 74.808
2025-01-21 21:24:16 - Got files
2025-01-21 21:24:16 - Got directories
2025-01-21 21:24:17 - Current used storage is 74.808
2025-01-21 21:24:17 - Got files
2025-01-21 21:24:17 - Got directories
2025-01-21 21:24:18 - Current used storage is 74.808
2025-01-21 21:24:18 - Got files
2025-01-21 21:24:18 - Got directories
2025-01-21 21:24:21 - Current used storage is 74.808
2025-01-21 21:24:21 - Got files
2025-01-21 21:24:21 - Got directories
2025-01-21 21:24:25 - Succesfully moved to
2025-01-21 21:24:25 - Got files
2025-01-21 21:24:25 - Got directories
2025-01-21 21:24:25 - Current used storage is 74.808
2025-01-21 21:24:28 - File CactiMaster.rar was deleted!
2025-01-21 21:24:28 - Succesfully deleted 1 files
2025-01-21 21:24:28 - Got directories
2025-01-21 21:24:28 - Got files
2025-01-21 21:24:28 - Current used storage is 22.031
2025-01-21 21:24:30 - Succesfully moved to
2025-01-21 21:24:30 - Current used storage is 22.031
2025-01-21 21:24:30 - Got files
2025-01-21 21:24:30 - Got directories
2025-01-21 21:24:32 - Current used storage is 22.031
2025-01-21 21:24:32 - Got files
2025-01-21 21:24:32 - Got directories
2025-01-21 21:24:33 - Current used storage is 22.031
2025-01-21 21:24:33 - Got files
2025-01-21 21:24:33 - Got directories
2025-01-21 21:24:38 - Current used storage is 22.031
2025-01-21 21:24:38 - Got files
2025-01-21 21:24:38 - Got directories
2025-01-21 21:24:38 - Current used storage is 22.031
2025-01-21 21:24:38 - Got files
2025-01-21 21:24:38 - Got directories
2025-01-21 21:24:38 - Current used storage is 22.031
2025-01-21 21:24:38 - Got files
2025-01-21 21:24:38 - Got directories
2025-01-21 21:24:39 - Current used storage is 22.031
2025-01-21 21:24:39 - Got files
2025-01-21 21:24:39 - Got directories
2025-01-21 21:24:39 - Current used storage is 22.031
2025-01-21 21:24:39 - Got files
2025-01-21 21:24:40 - Got directories
2025-01-21 21:24:40 - Current used storage is 22.031
2025-01-21 21:24:40 - Got files
2025-01-21 21:24:40 - Got directories
2025-01-21 21:24:40 - Current used storage is 22.031
2025-01-21 21:24:40 - Got files
2025-01-21 21:24:40 - Got directories
2025-01-21 21:24:40 - Current used storage is 22.031
2025-01-21 21:24:40 - Got files
2025-01-21 21:24:41 - Got directories
2025-01-21 21:24:41 - Current used storage is 22.031
2025-01-21 21:24:41 - Got files
2025-01-21 21:24:41 - Got directories
2025-01-21 23:41:55 - Traceback (most recent call last):
  File "c:\Users\idanh\Desktop\Cyber\My Projects\Final Project\Main\client\modules\protocol.py", line 602, in connect_server
    sock.connect((ip, port))
                  ^^
NameError: name 'ip' is not defined. Did you mean: 'self.ip'?
2025-01-21 23:42:27 - Traceback (most recent call last):
  File "c:\Users\idanh\Desktop\Cyber\My Projects\Final Project\Main\client\modules\protocol.py", line 602, in connect_server
    sock.connect((ip, port))
                  ^^
NameError: name 'ip' is not defined. Did you mean: 'self.ip'?
2025-01-21 23:43:04 - Traceback (most recent call last):
  File "c:\Users\idanh\Desktop\Cyber\My Projects\Final Project\Main\client\modules\protocol.py", line 602, in connect_server
    sock.connect((ip, port))
                  ^^
NameError: name 'ip' is not defined. Did you mean: 'self.ip'?
2025-01-21 23:43:04 - Traceback (most recent call last):
  File "c:\Users\idanh\Desktop\Cyber\My Projects\Final Project\Main\client\modules\protocol.py", line 602, in connect_server
    sock.connect((ip, port))
                  ^^
NameError: name 'ip' is not defined. Did you mean: 'self.ip'?

During handling of the above exception, another exception occurred:

Traceback (most recent call last):
  File "c:\Users\idanh\Desktop\Cyber\My Projects\Final Project\Main\client\modules\protocol.py", line 602, in connect_server
    sock.connect((ip, port))
                  ^^
NameError: name 'ip' is not defined. Did you mean: 'self.ip'?
2025-01-21 23:43:04 - Traceback (most recent call last):
  File "c:\Users\idanh\Desktop\Cyber\My Projects\Final Project\Main\client\modules\protocol.py", line 602, in connect_server
    sock.connect((ip, port))
                  ^^
NameError: name 'ip' is not defined. Did you mean: 'self.ip'?

During handling of the above exception, another exception occurred:

Traceback (most recent call last):
  File "c:\Users\idanh\Desktop\Cyber\My Projects\Final Project\Main\client\modules\protocol.py", line 602, in connect_server
    sock.connect((ip, port))
                  ^^
NameError: name 'ip' is not defined. Did you mean: 'self.ip'?

During handling of the above exception, another exception occurred:

Traceback (most recent call last):
  File "c:\Users\idanh\Desktop\Cyber\My Projects\Final Project\Main\client\modules\gui.py", line 614, in not_connected_page
    if connect: self.protocol.connect_server(self.protocol.ip, self.protocol.port, True)
                ^^^^^^^^^^^^^^^^^^^^^^^^^^^^^^^^^^^^^^^^^^^^^^^^^^^^^^^^^^^^^^^^^^^^^^^^
  File "c:\Users\idanh\Desktop\Cyber\My Projects\Final Project\Main\client\modules\protocol.py", line 624, in connect_server
    self.window.set_error_message(f'Server was not found {ip} {port}')
                                                          ^^
NameError: name 'ip' is not defined. Did you mean: 'self.ip'?
2025-01-21 23:43:27 - Traceback (most recent call last):
  File "c:\Users\idanh\Desktop\Cyber\My Projects\Final Project\Main\client\modules\protocol.py", line 602, in connect_server
    sock.connect((ip, port))
                  ^^
NameError: name 'ip' is not defined. Did you mean: 'self.ip'?
2025-01-21 23:43:27 - Traceback (most recent call last):
  File "c:\Users\idanh\Desktop\Cyber\My Projects\Final Project\Main\client\modules\protocol.py", line 602, in connect_server
    sock.connect((ip, port))
                  ^^
NameError: name 'ip' is not defined. Did you mean: 'self.ip'?

During handling of the above exception, another exception occurred:

Traceback (most recent call last):
  File "c:\Users\idanh\Desktop\Cyber\My Projects\Final Project\Main\client\modules\protocol.py", line 602, in connect_server
    sock.connect((ip, port))
                  ^^
NameError: name 'ip' is not defined. Did you mean: 'self.ip'?
2025-01-21 23:43:47 - Traceback (most recent call last):
  File "c:\Users\idanh\Desktop\Cyber\My Projects\Final Project\Main\client\modules\protocol.py", line 611, in connect_server
    receive_thread.start()
    ^^^^^^^^^^^^^^
NameError: name 'receive_thread' is not defined
2025-01-21 23:43:48 - Traceback (most recent call last):
  File "c:\Users\idanh\Desktop\Cyber\My Projects\Final Project\Main\client\modules\protocol.py", line 611, in connect_server
    receive_thread.start()
    ^^^^^^^^^^^^^^
NameError: name 'receive_thread' is not defined

During handling of the above exception, another exception occurred:

Traceback (most recent call last):
  File "c:\Users\idanh\Desktop\Cyber\My Projects\Final Project\Main\client\modules\protocol.py", line 611, in connect_server
    receive_thread.start()
    ^^^^^^^^^^^^^^
NameError: name 'receive_thread' is not defined
2025-01-21 23:45:01 - Traceback (most recent call last):
  File "c:\Users\idanh\Desktop\Cyber\My Projects\Final Project\Main\client\client.pyw", line 61, in handle_reply
    app.network.logtcp('recv', reply)
    ^^^
NameError: name 'app' is not defined
2025-01-21 23:45:40 - Traceback (most recent call last):
  File "c:\Users\idanh\Desktop\Cyber\My Projects\Final Project\Main\client\modules\protocol.py", line 339, in protocol_parse_reply
    self.get_user_icon()
  File "c:\Users\idanh\Desktop\Cyber\My Projects\Final Project\Main\client\modules\protocol.py", line 104, in get_user_icon
    self.window.files_downloading["user"] = self.window.file_sending.File(self.window, user_icon, "user", 0, file_name="User Icon")
                                            ^^^^^^^^^^^^^^^^^^^^^^^^^^^^^
AttributeError: 'FileSending' object has no attribute 'File'
2025-01-21 23:45:40 - Login was succesfull for user: a
2025-01-21 23:45:40 - File data recieved 0
2025-01-21 23:45:40 - Traceback (most recent call last):
  File "c:\Users\idanh\Desktop\Cyber\My Projects\Final Project\Main\client\modules\protocol.py", line 585, in protocol_parse_reply
    if code != "RILD" and code != "RILE": self.window.force_update_self.window()
                                          ^^^^^^^^^^^^^^^^^^^^^^^^^^^^^
AttributeError: 'MainWindow' object has no attribute 'force_update_self'. Did you mean: 'force_update_window'?
2025-01-21 23:45:40 - Profile picture was recieved
2025-01-21 23:46:31 - Traceback (most recent call last):
  File "c:\Users\idanh\Desktop\Cyber\My Projects\Final Project\Main\client\modules\protocol.py", line 339, in protocol_parse_reply
    self.get_user_icon()
  File "c:\Users\idanh\Desktop\Cyber\My Projects\Final Project\Main\client\modules\protocol.py", line 104, in get_user_icon
    self.window.files_downloading["user"] = self.window.file_sending.File(self.window, user_icon, "user", 0, file_name="User Icon")
                                            ^^^^^^^^^^^^^^^^^^^^^^^^^^^^^
AttributeError: 'FileSending' object has no attribute 'File'
2025-01-21 23:46:31 - Login was succesfull for user: a
2025-01-21 23:46:31 - File data recieved 0
2025-01-21 23:46:31 - Profile picture was recieved
2025-01-21 23:48:07 - Traceback (most recent call last):
  File "c:\Users\idanh\Desktop\Cyber\My Projects\Final Project\Main\client\modules\protocol.py", line 343, in protocol_parse_reply
    self.window.user_page()
  File "c:\Users\idanh\Desktop\Cyber\My Projects\Final Project\Main\client\modules\gui.py", line 308, in user_page
    self.update_user_page()
  File "c:\Users\idanh\Desktop\Cyber\My Projects\Final Project\Main\client\modules\gui.py", line 323, in update_user_page
    self.protocol.get_cwd_files(self.search_filter)
  File "c:\Users\idanh\Desktop\Cyber\My Projects\Final Project\Main\client\modules\protocol.py", line 59, in get_cwd_files
    self.protocol.get_files(1, filter)
    ^^^^^^^^^^^^^
AttributeError: 'Protocol' object has no attribute 'protocol'
2025-01-21 23:48:07 - Login was succesfull for user: a
2025-01-21 23:48:07 - File data recieved 0
2025-01-21 23:48:07 - Profile picture was recieved
2025-01-21 23:48:07 - Traceback (most recent call last):
  File "c:\Users\idanh\Desktop\Cyber\My Projects\Final Project\Main\client\modules\protocol.py", line 505, in protocol_parse_reply
    self.window.set_used_storage()
  File "c:\Users\idanh\Desktop\Cyber\My Projects\Final Project\Main\client\modules\gui.py", line 771, in set_used_storage
    self.storage_remaining.setValue(int(self.used_storage))
    ^^^^^^^^^^^^^^^^^^^^^^
AttributeError: 'MainWindow' object has no attribute 'storage_remaining'
2025-01-21 23:48:07 - Invalid reply from server
2025-01-21 23:48:07 - b'GEUR|74808221'
2025-01-21 23:49:00 - Traceback (most recent call last):
  File "c:\Users\idanh\Desktop\Cyber\My Projects\Final Project\Main\client\modules\gui.py", line 356, in run_user_page
    self.search.clicked.connect(self.search)
TypeError: argument 1 has unexpected type 'QPushButton'
2025-01-21 23:49:00 - Traceback (most recent call last):
  File "c:\Users\idanh\Desktop\Cyber\My Projects\Final Project\Main\client\modules\protocol.py", line 345, in protocol_parse_reply
    if remember:
       ^^^^^^^^
NameError: name 'remember' is not defined
2025-01-21 23:49:00 - Login was succesfull for user: a
2025-01-21 23:49:00 - File data recieved 0
2025-01-21 23:49:00 - Profile picture was recieved
2025-01-21 23:49:00 - Traceback (most recent call last):
  File "c:\Users\idanh\Desktop\Cyber\My Projects\Final Project\Main\client\modules\protocol.py", line 558, in protocol_parse_reply
    if files != None and directories != None:
                         ^^^^^^^^^^^
NameError: name 'directories' is not defined
2025-01-21 23:49:00 - Invalid reply from server
2025-01-21 23:49:00 - b'PATH|55|\xd7\xa9\xd7\x90\xd7\x9c\xd7\x95\xd7\x9f \xd7\xa2\xd7\x99\xd7\x93\xd7\x9f \xd7\x97\xd7\x96\xd7\x90\xd7\x99 330905159.docx~2025-01-05 23:00:33.327545~81756~9b9b918dce3840f6a6f78a588ddd4d0c|\xd7\x9e\xd7\x99\xd7\x95\xd7\x9f \xd7\x90\xd7\x99\xd7\xa9\xd7\x99\xd7\x95\xd7\xaa.txt~2025-01-05 21:37:34.227244~12215~a4813d15a35d49fb9c24035f20208b80|\xd7\x9e\xd7\x99\xd7\x95\xd7\x9f \xd7\x90\xd7\x99\xd7\xa9\xd7\x99\xd7\x95\xd7\xaa.txt~2025-01-05 23:00:34.481928~12215~3b7c56f4f8e445d8bbcd1342cde035ba|Zoom_aMx6bGM4b7.png~2025-01-05 23:00:45.560242~354146~3056bcfbdf294d9aafd58f8b6ddec99f|Zoom_aM0cBMMuYW.png~2025-01-05 23:00:45.687764~482436~ddfd77c0232b4a07b26c2fcff4ede7a2|VSCode.css~2025-01-05 21:37:34.352710~4424~6efb108d14554e4a8fc4e4b72c8826da|VSCode.css~2025-01-05 23:00:34.536958~4424~be2457bd003a4c39a48e53a42b5a5378|vencord-settings-backup.json~2025-01-05 21:37:34.273657~23664~84d56a58ffaa44929211e98a0aef1f04|vencord-settings-backup.json~2025-01-05 23:00:34.529958~23664~54aa23c8f45c48c7892ccaadb35122fa|ThemeTool.exe~2025-01-05 21:37:34.021652~221696~6ecfa86717a74e0c84514e8263a21650|ThemeTool.exe~2025-01-05 23:00:34.285359~221696~4f043aa5301745849d15ba63399f3d18|Teams_JHQYh64EmD.png~2025-01-05 23:00:45.197499~54123~b6d9250f51b24201b0601af81797c908|Teams_BkqJFDNiGE.png~2025-01-05 23:00:44.851344~58876~8bb50e179f164a0a9d8ac2e6fac976f4|RocketLeague_nvmo0joaYd.jpg~2025-01-05 23:00:45.447727~417754~d4c14103cf0b4a81915794d327208c4d|RocketLeague_npe4XSGKVK.png~2025-01-05 23:00:45.341549~229358~e0f1ee76b16043ee8c79698ae9811135|RocketLeague_EteTcy8mkT.jpg~2025-01-05 23:00:44.783834~319798~45f76e75f2c5475d9fb70e93248e1c3b|RocketLeague_b33BhjulkZ.png~2025-01-05 23:00:45.197499~319727~fec1697be03d4edc8e5b80c26c854e08|macchiato.qbtheme~2025-01-05 23:00:34.595969~5498~b94df2de9e8740699539e04892058906|kVaJtxZ5CF.png~2025-01-05 23:00:44.779834~21612~f11d7c5c493849b9bfb5f452ffb7fcd2|Infinity5.ahk~2025-01-05 21:37:34.576751~514~c2a4df7bdcb84e3597805f035d04e01a'
2025-01-21 23:49:00 - Current used storage is 74.808
2025-01-21 23:49:00 - Traceback (most recent call last):
  File "c:\Users\idanh\Desktop\Cyber\My Projects\Final Project\Main\client\modules\gui.py", line 429, in draw_cwd
    for file in files:
                ^^^^^
TypeError: 'NoneType' object is not iterable
2025-01-21 23:49:00 - Got directories
2025-01-21 23:51:11 - Traceback (most recent call last):
  File "c:\Users\idanh\Desktop\Cyber\My Projects\Final Project\Main\client\modules\protocol.py", line 345, in protocol_parse_reply
    if remember:
       ^^^^^^^^
NameError: name 'remember' is not defined
2025-01-21 23:51:11 - Login was succesfull for user: a
2025-01-21 23:51:11 - File data recieved 0
2025-01-21 23:51:11 - Profile picture was recieved
2025-01-21 23:51:11 - Current used storage is 74.808
2025-01-21 23:51:11 - Traceback (most recent call last):
  File "c:\Users\idanh\Desktop\Cyber\My Projects\Final Project\Main\client\modules\protocol.py", line 558, in protocol_parse_reply
    if files != None and directories != None:
                         ^^^^^^^^^^^
NameError: name 'directories' is not defined
2025-01-21 23:51:11 - Invalid reply from server
2025-01-21 23:51:11 - b'PATH|55|\xd7\xa9\xd7\x90\xd7\x9c\xd7\x95\xd7\x9f \xd7\xa2\xd7\x99\xd7\x93\xd7\x9f \xd7\x97\xd7\x96\xd7\x90\xd7\x99 330905159.docx~2025-01-05 23:00:33.327545~81756~9b9b918dce3840f6a6f78a588ddd4d0c|\xd7\x9e\xd7\x99\xd7\x95\xd7\x9f \xd7\x90\xd7\x99\xd7\xa9\xd7\x99\xd7\x95\xd7\xaa.txt~2025-01-05 21:37:34.227244~12215~a4813d15a35d49fb9c24035f20208b80|\xd7\x9e\xd7\x99\xd7\x95\xd7\x9f \xd7\x90\xd7\x99\xd7\xa9\xd7\x99\xd7\x95\xd7\xaa.txt~2025-01-05 23:00:34.481928~12215~3b7c56f4f8e445d8bbcd1342cde035ba|Zoom_aMx6bGM4b7.png~2025-01-05 23:00:45.560242~354146~3056bcfbdf294d9aafd58f8b6ddec99f|Zoom_aM0cBMMuYW.png~2025-01-05 23:00:45.687764~482436~ddfd77c0232b4a07b26c2fcff4ede7a2|VSCode.css~2025-01-05 21:37:34.352710~4424~6efb108d14554e4a8fc4e4b72c8826da|VSCode.css~2025-01-05 23:00:34.536958~4424~be2457bd003a4c39a48e53a42b5a5378|vencord-settings-backup.json~2025-01-05 21:37:34.273657~23664~84d56a58ffaa44929211e98a0aef1f04|vencord-settings-backup.json~2025-01-05 23:00:34.529958~23664~54aa23c8f45c48c7892ccaadb35122fa|ThemeTool.exe~2025-01-05 21:37:34.021652~221696~6ecfa86717a74e0c84514e8263a21650|ThemeTool.exe~2025-01-05 23:00:34.285359~221696~4f043aa5301745849d15ba63399f3d18|Teams_JHQYh64EmD.png~2025-01-05 23:00:45.197499~54123~b6d9250f51b24201b0601af81797c908|Teams_BkqJFDNiGE.png~2025-01-05 23:00:44.851344~58876~8bb50e179f164a0a9d8ac2e6fac976f4|RocketLeague_nvmo0joaYd.jpg~2025-01-05 23:00:45.447727~417754~d4c14103cf0b4a81915794d327208c4d|RocketLeague_npe4XSGKVK.png~2025-01-05 23:00:45.341549~229358~e0f1ee76b16043ee8c79698ae9811135|RocketLeague_EteTcy8mkT.jpg~2025-01-05 23:00:44.783834~319798~45f76e75f2c5475d9fb70e93248e1c3b|RocketLeague_b33BhjulkZ.png~2025-01-05 23:00:45.197499~319727~fec1697be03d4edc8e5b80c26c854e08|macchiato.qbtheme~2025-01-05 23:00:34.595969~5498~b94df2de9e8740699539e04892058906|kVaJtxZ5CF.png~2025-01-05 23:00:44.779834~21612~f11d7c5c493849b9bfb5f452ffb7fcd2|Infinity5.ahk~2025-01-05 21:37:34.576751~514~c2a4df7bdcb84e3597805f035d04e01a'
2025-01-21 23:51:11 - Traceback (most recent call last):
  File "c:\Users\idanh\Desktop\Cyber\My Projects\Final Project\Main\client\modules\gui.py", line 429, in draw_cwd
    for file in files:
                ^^^^^
TypeError: 'NoneType' object is not iterable
2025-01-21 23:51:11 - Got directories
2025-01-21 23:51:50 - Login was succesfull for user: a
2025-01-21 23:51:50 - File data recieved 0
2025-01-21 23:51:50 - Profile picture was recieved
2025-01-21 23:51:50 - Traceback (most recent call last):
  File "c:\Users\idanh\Desktop\Cyber\My Projects\Final Project\Main\client\modules\protocol.py", line 557, in protocol_parse_reply
    if files != None and directories != None:
                         ^^^^^^^^^^^
NameError: name 'directories' is not defined
2025-01-21 23:51:50 - Invalid reply from server
2025-01-21 23:51:50 - b'PATH|55|\xd7\xa9\xd7\x90\xd7\x9c\xd7\x95\xd7\x9f \xd7\xa2\xd7\x99\xd7\x93\xd7\x9f \xd7\x97\xd7\x96\xd7\x90\xd7\x99 330905159.docx~2025-01-05 23:00:33.327545~81756~9b9b918dce3840f6a6f78a588ddd4d0c|\xd7\x9e\xd7\x99\xd7\x95\xd7\x9f \xd7\x90\xd7\x99\xd7\xa9\xd7\x99\xd7\x95\xd7\xaa.txt~2025-01-05 21:37:34.227244~12215~a4813d15a35d49fb9c24035f20208b80|\xd7\x9e\xd7\x99\xd7\x95\xd7\x9f \xd7\x90\xd7\x99\xd7\xa9\xd7\x99\xd7\x95\xd7\xaa.txt~2025-01-05 23:00:34.481928~12215~3b7c56f4f8e445d8bbcd1342cde035ba|Zoom_aMx6bGM4b7.png~2025-01-05 23:00:45.560242~354146~3056bcfbdf294d9aafd58f8b6ddec99f|Zoom_aM0cBMMuYW.png~2025-01-05 23:00:45.687764~482436~ddfd77c0232b4a07b26c2fcff4ede7a2|VSCode.css~2025-01-05 21:37:34.352710~4424~6efb108d14554e4a8fc4e4b72c8826da|VSCode.css~2025-01-05 23:00:34.536958~4424~be2457bd003a4c39a48e53a42b5a5378|vencord-settings-backup.json~2025-01-05 21:37:34.273657~23664~84d56a58ffaa44929211e98a0aef1f04|vencord-settings-backup.json~2025-01-05 23:00:34.529958~23664~54aa23c8f45c48c7892ccaadb35122fa|ThemeTool.exe~2025-01-05 21:37:34.021652~221696~6ecfa86717a74e0c84514e8263a21650|ThemeTool.exe~2025-01-05 23:00:34.285359~221696~4f043aa5301745849d15ba63399f3d18|Teams_JHQYh64EmD.png~2025-01-05 23:00:45.197499~54123~b6d9250f51b24201b0601af81797c908|Teams_BkqJFDNiGE.png~2025-01-05 23:00:44.851344~58876~8bb50e179f164a0a9d8ac2e6fac976f4|RocketLeague_nvmo0joaYd.jpg~2025-01-05 23:00:45.447727~417754~d4c14103cf0b4a81915794d327208c4d|RocketLeague_npe4XSGKVK.png~2025-01-05 23:00:45.341549~229358~e0f1ee76b16043ee8c79698ae9811135|RocketLeague_EteTcy8mkT.jpg~2025-01-05 23:00:44.783834~319798~45f76e75f2c5475d9fb70e93248e1c3b|RocketLeague_b33BhjulkZ.png~2025-01-05 23:00:45.197499~319727~fec1697be03d4edc8e5b80c26c854e08|macchiato.qbtheme~2025-01-05 23:00:34.595969~5498~b94df2de9e8740699539e04892058906|kVaJtxZ5CF.png~2025-01-05 23:00:44.779834~21612~f11d7c5c493849b9bfb5f452ffb7fcd2|Infinity5.ahk~2025-01-05 21:37:34.576751~514~c2a4df7bdcb84e3597805f035d04e01a'
2025-01-21 23:51:50 - Traceback (most recent call last):
  File "c:\Users\idanh\Desktop\Cyber\My Projects\Final Project\Main\client\modules\gui.py", line 429, in draw_cwd
    for file in files:
                ^^^^^
TypeError: 'NoneType' object is not iterable
2025-01-21 23:51:50 - Got directories
2025-01-21 23:51:50 - Current used storage is 74.808
2025-01-21 23:52:50 - Login was succesfull for user: a
2025-01-21 23:52:50 - File data recieved 0
2025-01-21 23:52:50 - Profile picture was recieved
2025-01-21 23:52:50 - Traceback (most recent call last):
  File "c:\Users\idanh\Desktop\Cyber\My Projects\Final Project\Main\client\modules\gui.py", line 429, in draw_cwd
    for file in files:
                ^^^^^
TypeError: 'NoneType' object is not iterable
2025-01-21 23:52:50 - Got files
2025-01-21 23:52:50 - Current used storage is 74.808
2025-01-21 23:52:50 - Traceback (most recent call last):
  File "c:\Users\idanh\Desktop\Cyber\My Projects\Final Project\Main\client\modules\protocol.py", line 564, in protocol_parse_reply
    if files != None and self.window.directories != None:
       ^^^^^
NameError: name 'files' is not defined. Did you mean: 'File'?
2025-01-21 23:52:50 - Invalid reply from server
2025-01-21 23:52:50 - b'PATD|60'
2025-01-21 23:53:50 - Login was succesfull for user: a
2025-01-21 23:53:50 - File data recieved 0
2025-01-21 23:53:50 - Profile picture was recieved
2025-01-21 23:53:50 - Current used storage is 74.808
2025-01-21 23:53:50 - Traceback (most recent call last):
  File "c:\Users\idanh\Desktop\Cyber\My Projects\Final Project\Main\client\modules\protocol.py", line 558, in protocol_parse_reply
    self.window.update_current_files()
  File "c:\Users\idanh\Desktop\Cyber\My Projects\Final Project\Main\client\modules\gui.py", line 801, in update_current_files
    scroll.verticalScrollBar().setMaximum(self.scroll_progress)
    ^^^^^^
NameError: name 'scroll' is not defined. Did you mean: 'self.scroll'?
2025-01-21 23:53:50 - Invalid reply from server
2025-01-21 23:53:50 - b'PATH|55|\xd7\xa9\xd7\x90\xd7\x9c\xd7\x95\xd7\x9f \xd7\xa2\xd7\x99\xd7\x93\xd7\x9f \xd7\x97\xd7\x96\xd7\x90\xd7\x99 330905159.docx~2025-01-05 23:00:33.327545~81756~9b9b918dce3840f6a6f78a588ddd4d0c|\xd7\x9e\xd7\x99\xd7\x95\xd7\x9f \xd7\x90\xd7\x99\xd7\xa9\xd7\x99\xd7\x95\xd7\xaa.txt~2025-01-05 21:37:34.227244~12215~a4813d15a35d49fb9c24035f20208b80|\xd7\x9e\xd7\x99\xd7\x95\xd7\x9f \xd7\x90\xd7\x99\xd7\xa9\xd7\x99\xd7\x95\xd7\xaa.txt~2025-01-05 23:00:34.481928~12215~3b7c56f4f8e445d8bbcd1342cde035ba|Zoom_aMx6bGM4b7.png~2025-01-05 23:00:45.560242~354146~3056bcfbdf294d9aafd58f8b6ddec99f|Zoom_aM0cBMMuYW.png~2025-01-05 23:00:45.687764~482436~ddfd77c0232b4a07b26c2fcff4ede7a2|VSCode.css~2025-01-05 21:37:34.352710~4424~6efb108d14554e4a8fc4e4b72c8826da|VSCode.css~2025-01-05 23:00:34.536958~4424~be2457bd003a4c39a48e53a42b5a5378|vencord-settings-backup.json~2025-01-05 21:37:34.273657~23664~84d56a58ffaa44929211e98a0aef1f04|vencord-settings-backup.json~2025-01-05 23:00:34.529958~23664~54aa23c8f45c48c7892ccaadb35122fa|ThemeTool.exe~2025-01-05 21:37:34.021652~221696~6ecfa86717a74e0c84514e8263a21650|ThemeTool.exe~2025-01-05 23:00:34.285359~221696~4f043aa5301745849d15ba63399f3d18|Teams_JHQYh64EmD.png~2025-01-05 23:00:45.197499~54123~b6d9250f51b24201b0601af81797c908|Teams_BkqJFDNiGE.png~2025-01-05 23:00:44.851344~58876~8bb50e179f164a0a9d8ac2e6fac976f4|RocketLeague_nvmo0joaYd.jpg~2025-01-05 23:00:45.447727~417754~d4c14103cf0b4a81915794d327208c4d|RocketLeague_npe4XSGKVK.png~2025-01-05 23:00:45.341549~229358~e0f1ee76b16043ee8c79698ae9811135|RocketLeague_EteTcy8mkT.jpg~2025-01-05 23:00:44.783834~319798~45f76e75f2c5475d9fb70e93248e1c3b|RocketLeague_b33BhjulkZ.png~2025-01-05 23:00:45.197499~319727~fec1697be03d4edc8e5b80c26c854e08|macchiato.qbtheme~2025-01-05 23:00:34.595969~5498~b94df2de9e8740699539e04892058906|kVaJtxZ5CF.png~2025-01-05 23:00:44.779834~21612~f11d7c5c493849b9bfb5f452ffb7fcd2|Infinity5.ahk~2025-01-05 21:37:34.576751~514~c2a4df7bdcb84e3597805f035d04e01a'
2025-01-21 23:53:50 - Traceback (most recent call last):
  File "c:\Users\idanh\Desktop\Cyber\My Projects\Final Project\Main\client\modules\protocol.py", line 565, in protocol_parse_reply
    self.window.update_current_files()
  File "c:\Users\idanh\Desktop\Cyber\My Projects\Final Project\Main\client\modules\gui.py", line 801, in update_current_files
    scroll.verticalScrollBar().setMaximum(self.scroll_progress)
    ^^^^^^
NameError: name 'scroll' is not defined. Did you mean: 'self.scroll'?
2025-01-21 23:53:50 - Invalid reply from server
2025-01-21 23:53:50 - b'PATD|60'
2025-01-21 23:54:55 - Login was succesfull for user: a
2025-01-21 23:54:55 - File data recieved 0
2025-01-21 23:54:55 - Profile picture was recieved
2025-01-21 23:54:55 - Current used storage is 74.808
2025-01-21 23:54:55 - Got files
2025-01-21 23:54:55 - Got directories
2025-01-21 23:58:42 - Login was succesfull for user: a
2025-01-21 23:58:42 - File data recieved 0
2025-01-21 23:58:42 - Profile picture was recieved
2025-01-21 23:58:42 - Current used storage is 74.808
2025-01-21 23:58:42 - Got files
2025-01-21 23:58:42 - Got directories
2025-01-21 23:59:17 - Current used storage is 74.808
2025-01-21 23:59:23 - Got files
2025-01-21 23:59:23 - Current used storage is 74.808
2025-01-21 23:59:23 - Got directories
2025-01-21 23:59:29 - Traceback (most recent call last):
  File "c:\Users\idanh\Desktop\Cyber\My Projects\Final Project\Main\client\modules\gui.py", line 715, in file_dialog
    self.file_sending.send_files()
  File "c:\Users\idanh\Desktop\Cyber\My Projects\Final Project\Main\client\modules\file_sending.py", line 27, in send_files
    thread.finished.connect(self.finish_sending)
                            ^^^^^^^^^^^^^^^^^^^
AttributeError: 'FileSending' object has no attribute 'finish_sending'
2025-01-22 00:00:04 - Login was succesfull for user: a
2025-01-22 00:00:04 - File data recieved 0
2025-01-22 00:00:04 - Profile picture was recieved
2025-01-22 00:00:04 - Current used storage is 74.808
2025-01-22 00:00:04 - Got files
2025-01-22 00:00:04 - Got directories
2025-01-22 00:01:08 - Login was succesfull for user: a
2025-01-22 00:01:08 - File data recieved 0
2025-01-22 00:01:08 - Profile picture was recieved
2025-01-22 00:01:08 - Current used storage is 74.808
2025-01-22 00:01:08 - Got directories
2025-01-22 00:01:08 - Got files
2025-01-22 00:01:40 - Login was succesfull for user: a
2025-01-22 00:01:40 - File data recieved 0
2025-01-22 00:01:40 - Profile picture was recieved
2025-01-22 00:01:40 - Current used storage is 74.808
2025-01-22 00:01:40 - Got files
2025-01-22 00:01:40 - Got directories
2025-01-22 00:01:46 - Login was succesfull for user: a
2025-01-22 00:01:46 - File data recieved 0
2025-01-22 00:01:46 - Profile picture was recieved
2025-01-22 00:01:46 - Current used storage is 74.808
2025-01-22 00:01:46 - Got files
2025-01-22 00:01:46 - Got directories
2025-01-22 00:01:47 - Got files
2025-01-22 00:01:47 - Got directories
2025-01-22 00:01:47 - Current used storage is 74.808
2025-01-22 00:01:48 - Got files
2025-01-22 00:01:48 - Current used storage is 74.808
2025-01-22 00:01:48 - Got directories
2025-01-22 00:01:50 - Current used storage is 74.808
2025-01-22 00:01:50 - Got files
2025-01-22 00:01:50 - Got directories
2025-01-22 00:01:50 - Got directories
2025-01-22 00:01:50 - Current used storage is 74.808
2025-01-22 00:01:50 - Got files
2025-01-22 00:01:51 - Got directories
2025-01-22 00:01:51 - Got files
2025-01-22 00:01:51 - Current used storage is 74.808
2025-01-22 00:01:51 - Got files
2025-01-22 00:01:51 - Current used storage is 74.808
2025-01-22 00:01:51 - Got directories
2025-01-22 00:01:51 - Current used storage is 74.808
2025-01-22 00:01:51 - Got files
2025-01-22 00:01:51 - Got directories
2025-01-22 00:01:51 - Got files
2025-01-22 00:01:51 - Current used storage is 74.808
2025-01-22 00:01:51 - Got directories
2025-01-22 00:01:51 - Got files
2025-01-22 00:01:51 - Current used storage is 74.808
2025-01-22 00:01:51 - Got directories
2025-01-22 00:01:58 - Got files
2025-01-22 00:01:58 - Current used storage is 74.808
2025-01-22 00:01:58 - Got directories
2025-01-22 00:02:05 - Got files
2025-01-22 00:02:05 - Current used storage is 74.808
2025-01-22 00:02:05 - Got directories
2025-01-22 00:02:07 - Current used storage is 74.808
2025-01-22 00:02:07 - Got files
2025-01-22 00:02:07 - Got directories
2025-01-22 10:25:57 - Login was succesfull for user: a
2025-01-22 10:25:57 - File data recieved 0
2025-01-22 10:25:57 - Profile picture was recieved
2025-01-22 10:25:57 - Current used storage is 74.808
2025-01-22 10:25:57 - Got files
2025-01-22 10:25:57 - Got directories
2025-01-22 10:27:15 - Login was succesfull for user: a
2025-01-22 10:27:15 - File data recieved 0
2025-01-22 10:27:15 - Profile picture was recieved
2025-01-22 10:27:15 - Got files
2025-01-22 10:27:15 - Current used storage is 74.808
2025-01-22 10:27:15 - Got directories
2025-01-22 10:28:33 - Login was succesfull for user: a
2025-01-22 10:28:33 - File data recieved 0
2025-01-22 10:28:33 - Profile picture was recieved
2025-01-22 10:28:33 - Got files
2025-01-22 10:28:33 - Current used storage is 74.808
2025-01-22 10:28:33 - Got directories
2025-01-22 10:28:35 - Succesfully moved to
2025-01-22 10:28:35 - Current used storage is 74.808
2025-01-22 10:28:35 - Got files
2025-01-22 10:28:35 - Got directories
2025-01-22 10:31:18 - Login was succesfull for user: a
2025-01-22 10:31:18 - File data recieved 0
2025-01-22 10:31:18 - Profile picture was recieved
2025-01-22 10:31:18 - Got files
2025-01-22 10:31:18 - Current used storage is 74.808
2025-01-22 10:31:19 - Got directories
2025-01-22 10:31:27 - File Zoom_aM0cBMMuYW.png was viewed
2025-01-22 10:31:27 - File viewing released
2025-01-22 10:31:30 - File data recieved 0
2025-01-22 10:32:06 - Login was succesfull for user: a
2025-01-22 10:32:06 - File data recieved 0
2025-01-22 10:32:06 - Profile picture was recieved
2025-01-22 10:32:06 - Got files
2025-01-22 10:32:06 - Current used storage is 74.808
2025-01-22 10:32:06 - Got directories
2025-01-22 10:32:16 - File data recieved 0
2025-01-22 10:32:16 - File \u05de\u05d9\u05d5\u05df \u05d0\u05d9\u05e9\u05d9\u05d5\u05ea.txt was downloaded
2025-01-22 10:34:09 - Login was succesfull for user: a
2025-01-22 10:34:09 - File data recieved 0
2025-01-22 10:34:09 - Profile picture was recieved
2025-01-22 10:34:09 - Got files
2025-01-22 10:34:09 - Current used storage is 74.808
2025-01-22 10:34:09 - Got directories
2025-01-22 10:34:52 - Login was succesfull for user: a
2025-01-22 10:34:52 - File data recieved 0
2025-01-22 10:34:52 - Profile picture was recieved
2025-01-22 10:34:52 - Got files
2025-01-22 10:34:52 - Current used storage is 74.808
2025-01-22 10:34:52 - Got directories
2025-01-22 10:34:58 - Current used storage is 74.808
2025-01-22 10:35:00 - Subscription level updated to basic
2025-01-22 10:35:00 - Current used storage is 74.808
2025-01-22 10:35:01 - Subscription level updated to free
2025-01-22 10:35:01 - Current used storage is 74.808
2025-01-22 10:36:26 - Login was succesfull for user: a
2025-01-22 10:36:26 - File data recieved 0
2025-01-22 10:36:26 - Profile picture was recieved
2025-01-22 10:36:26 - Got files
2025-01-22 10:36:26 - Current used storage is 74.808
2025-01-22 10:36:26 - Got directories
2025-01-22 10:38:58 - Login was succesfull for user: a
2025-01-22 10:38:58 - File data recieved 0
2025-01-22 10:38:58 - Profile picture was recieved
2025-01-22 10:38:59 - Current used storage is 74.808
2025-01-22 10:38:59 - Got files
2025-01-22 10:38:59 - Got directories
2025-01-22 10:39:21 - Login was succesfull for user: a
2025-01-22 10:39:21 - File data recieved 0
2025-01-22 10:39:21 - Profile picture was recieved
2025-01-22 10:39:21 - Got files
2025-01-22 10:39:21 - Current used storage is 74.808
2025-01-22 10:39:22 - Got directories
2025-01-22 10:39:29 - Succesfully moved to
2025-01-22 10:39:29 - Got files
2025-01-22 10:39:29 - Got directories
2025-01-22 10:39:29 - Current used storage is 74.808
2025-01-22 10:39:31 - Got files
2025-01-22 10:39:31 - Got directories
2025-01-22 10:39:31 - Current used storage is 74.808
2025-01-22 10:39:32 - Got files
2025-01-22 10:39:32 - Got directories
2025-01-22 10:39:32 - Current used storage is 74.808
2025-01-22 10:39:32 - Got files
2025-01-22 10:39:32 - Got directories
2025-01-22 10:39:32 - Current used storage is 74.808
2025-01-22 10:39:36 - Got files
2025-01-22 10:39:36 - Got directories
2025-01-22 10:39:36 - Current used storage is 74.808
2025-01-22 10:45:00 - Got files
2025-01-22 10:45:00 - Got directories
2025-01-22 10:45:00 - Current used storage is 74.808
2025-01-22 10:45:00 - Got files
2025-01-22 10:45:00 - Got directories
2025-01-22 10:45:00 - Current used storage is 74.808
2025-01-22 10:45:02 - Succesfully moved to
2025-01-22 10:45:02 - Got files
2025-01-22 10:45:02 - Current used storage is 74.808
2025-01-22 10:45:03 - Got directories
2025-01-22 10:45:06 - Traceback (most recent call last):
  File "c:\Users\idanh\Desktop\Cyber\My Projects\Final-Project\Main\client\modules\file_sending.py", line 70, in run
    for file_path in self.file_queue:
                     ^^^^^^^^^^^^^^^
AttributeError: 'FileSenderThread' object has no attribute 'file_queue'
2025-01-22 10:45:34 - Login was succesfull for user: a
2025-01-22 10:45:34 - File data recieved 0
2025-01-22 10:45:34 - Profile picture was recieved
2025-01-22 10:45:34 - Got files
2025-01-22 10:45:34 - Current used storage is 74.808
2025-01-22 10:45:34 - Got directories
2025-01-22 10:45:37 - start upload:
2025-01-22 10:45:37 - c7f546e11c644c8a986bdc6eeff7e1fc
2025-01-22 10:45:37 - File app_log.txt started uploading
2025-01-22 10:45:37 - Got files
2025-01-22 10:45:37 - Current used storage is 74.808
2025-01-22 10:45:37 - Got directories
2025-01-22 10:45:38 - Traceback (most recent call last):
  File "c:\Users\idanh\Desktop\Cyber\My Projects\Final-Project\Main\client\modules\protocol.py", line 393, in protocol_parse_reply
    if time.time() - last_load > 0.5:
                     ^^^^^^^^^
UnboundLocalError: cannot access local variable 'last_load' where it is not associated with a value
2025-01-22 10:45:38 - File app_log.txt was uploaded
2025-01-22 10:46:43 - Login was succesfull for user: a
2025-01-22 10:46:43 - File data recieved 0
2025-01-22 10:46:43 - Profile picture was recieved
2025-01-22 10:46:43 - Current used storage is 74.86
2025-01-22 10:46:43 - Got files
2025-01-22 10:46:43 - Got directories
2025-01-22 10:47:11 - Login was succesfull for user: a
2025-01-22 10:47:11 - File data recieved 0
2025-01-22 10:47:11 - Profile picture was recieved
2025-01-22 10:47:11 - Current used storage is 74.86
2025-01-22 10:47:11 - Got files
2025-01-22 10:47:11 - Got directories
2025-01-22 10:47:13 - Got files
2025-01-22 10:47:13 - Current used storage is 74.86
2025-01-22 10:47:13 - Got directories
2025-01-22 10:47:15 - Current used storage is 74.86
2025-01-22 10:47:15 - Got files
2025-01-22 10:47:16 - Got directories
2025-01-22 10:47:16 - Got files
2025-01-22 10:47:16 - Current used storage is 74.86
2025-01-22 10:47:16 - Got directories
2025-01-22 10:47:17 - Got files
2025-01-22 10:47:17 - Current used storage is 74.86
2025-01-22 10:47:17 - Got directories
2025-01-22 10:47:18 - Got files
2025-01-22 10:47:18 - Current used storage is 74.86
2025-01-22 10:47:18 - Got directories
2025-01-22 10:47:20 - Current used storage is 74.86
2025-01-22 10:47:20 - Got files
2025-01-22 10:47:20 - Got directories
2025-01-22 10:48:29 - Login was succesfull for user: a
2025-01-22 10:48:29 - File data recieved 0
2025-01-22 10:48:29 - Profile picture was recieved
2025-01-22 10:48:29 - Current used storage is 74.86
2025-01-22 10:48:29 - Got files
2025-01-22 10:48:29 - Got directories
2025-01-22 10:48:55 - Login was succesfull for user: a
2025-01-22 10:48:55 - File data recieved 0
2025-01-22 10:48:55 - Profile picture was recieved
2025-01-22 10:48:55 - Current used storage is 74.86
2025-01-22 10:48:55 - Got files
2025-01-22 10:48:55 - Got directories
2025-01-22 10:48:58 - Got files
2025-01-22 10:48:58 - Got directories
2025-01-22 10:48:58 - Current used storage is 74.86
2025-01-22 10:49:01 - Got files
2025-01-22 10:49:01 - Got directories
2025-01-22 10:49:01 - Current used storage is 74.86
2025-01-22 10:49:08 - File data recieved 0
2025-01-22 10:49:08 - File Zoom_aMx6bGM4b7.png was downloaded
2025-01-22 10:49:39 - Login was succesfull for user: a
2025-01-22 10:49:39 - File data recieved 0
2025-01-22 10:49:39 - Profile picture was recieved
2025-01-22 10:49:39 - Got files
2025-01-22 10:49:39 - Current used storage is 74.86
2025-01-22 10:49:39 - Got directories
2025-01-22 10:49:41 - Current used storage is 74.86
2025-01-22 10:49:41 - Got files
2025-01-22 10:49:41 - Got directories
2025-01-22 10:49:45 - Succesfully deleted 1 files
2025-01-22 10:49:45 - File app_log.txt was deleted!
2025-01-22 10:49:45 - Got files
2025-01-22 10:49:45 - Current used storage is 74.86
2025-01-22 10:49:45 - Got directories
2025-01-22 10:49:48 - Succesfully deleted 2 files
2025-01-22 10:49:48 - File Zoom_aM0cBMMuYW.png was deleted!
2025-01-22 10:49:48 - File app_log.txt was deleted!
2025-01-22 10:49:48 - Current used storage is 74.86
2025-01-22 10:49:48 - Got files
2025-01-22 10:49:48 - Got directories
2025-01-22 10:49:55 - Succesfully shared 3 files
2025-01-22 10:49:55 - Current used storage is 74.86
2025-01-22 10:49:55 - Got files
2025-01-22 10:49:55 - Got directories
2025-01-22 10:49:58 - Sharing options recieved
2025-01-22 10:49:58 - Sharing option with idan have been updated
2025-01-22 10:50:00 - Sharing options recieved
2025-01-22 10:50:00 - Sharing option with idan have been updated
2025-01-22 10:50:01 - Sharing options recieved
2025-01-22 10:50:01 - Sharing option with idan have been updated
2025-01-22 10:50:40 - Login was succesfull for user: a
2025-01-22 10:50:40 - File data recieved 0
2025-01-22 10:50:40 - Profile picture was recieved
2025-01-22 10:50:40 - Got files
2025-01-22 10:50:40 - Current used storage is 74.86
2025-01-22 10:50:40 - Got directories
2025-01-22 10:50:44 - File/Folder \u05de\u05d9\u05d5\u05df \u05d0\u05d9\u05e9\u05d9\u05d5\u05ea.txt was renamed to hello
2025-01-22 10:50:44 - Got files
2025-01-22 10:50:44 - Current used storage is 74.86
2025-01-22 10:50:44 - Got directories
2025-01-22 10:50:47 - Got files
2025-01-22 10:50:47 - Got directories
2025-01-22 10:50:47 - Current used storage is 74.86
2025-01-22 10:50:51 - Got files
2025-01-22 10:50:51 - Current used storage is 74.86
2025-01-22 10:50:51 - Got directories
2025-01-22 10:50:53 - Succesfully moved to
2025-01-22 10:50:53 - Got files
2025-01-22 10:50:53 - Got directories
2025-01-22 10:50:54 - Current used storage is 74.86
2025-01-22 10:54:34 - Login was succesfull for user: a
2025-01-22 10:54:34 - File data recieved 0
2025-01-22 10:54:34 - Profile picture was recieved
2025-01-22 10:54:34 - Current used storage is 74.86
2025-01-22 10:54:34 - Got files
2025-01-22 10:54:34 - Got directories
2025-01-22 10:54:36 - Got files
2025-01-22 10:54:36 - Current used storage is 74.86
2025-01-22 10:54:36 - Got directories
2025-01-22 10:54:37 - Got files
2025-01-22 10:54:37 - Current used storage is 74.86
2025-01-22 10:54:37 - Got directories
2025-01-22 10:56:14 - Login was succesfull for user: a
2025-01-22 10:56:14 - File data recieved 0
2025-01-22 10:56:15 - Profile picture was recieved
2025-01-22 10:56:15 - Got files
2025-01-22 10:56:15 - Current used storage is 74.86
2025-01-22 10:56:15 - Got directories
2025-01-22 10:56:28 - Traceback (most recent call last):
  File "c:\Users\idanh\Desktop\Cyber\My Projects\Final-Project\Main\client\modules\gui.py", line 357, in run_user_page
    self.refresh.setIconSize(QSize(self.user_button.size().width()/2, self.user_button.size().height())/2)
                             ^^^^^^^^^^^^^^^^^^^^^^^^^^^^^^^^^^^^^^^^^^^^^^^^^^^^^^^^^^^^^^^^^^^^^^^^^^
TypeError: arguments did not match any overloaded call:
  QSize(): too many arguments
  QSize(w: int, h: int): argument 1 has unexpected type 'float'
  QSize(a0: QSize): argument 1 has unexpected type 'float'
2025-01-22 10:56:28 - Login was succesfull for user: a
2025-01-22 10:56:28 - File data recieved 0
2025-01-22 10:56:28 - Profile picture was recieved
2025-01-22 10:56:28 - Current used storage is 74.86
2025-01-22 10:56:28 - Got files
2025-01-22 10:56:28 - Got directories
2025-01-22 10:56:47 - Login was succesfull for user: a
2025-01-22 10:56:47 - File data recieved 0
2025-01-22 10:56:47 - Profile picture was recieved
2025-01-22 10:56:47 - Current used storage is 74.86
2025-01-22 10:56:47 - Got files
2025-01-22 10:56:47 - Got directories
2025-01-22 10:57:06 - Got files
2025-01-22 10:57:06 - Current used storage is 74.86
2025-01-22 10:57:06 - Got directories
2025-01-22 10:57:07 - Logout succesfull
2025-01-22 10:57:08 - Server acknowledged the exit message
2025-01-22 10:57:08 - Succefully exit
2025-01-22 10:57:17 - Login was succesfull for user: a
2025-01-22 10:57:17 - File data recieved 0
2025-01-22 10:57:17 - Profile picture was recieved
2025-01-22 10:57:17 - Got files
2025-01-22 10:57:17 - Current used storage is 74.86
2025-01-22 10:57:18 - Got directories
2025-01-22 10:57:37 - Login was succesfull for user: a
2025-01-22 10:57:37 - File data recieved 0
2025-01-22 10:57:37 - Profile picture was recieved
2025-01-22 10:57:37 - Current used storage is 74.86
2025-01-22 10:57:37 - Got files
2025-01-22 10:57:37 - Got directories
2025-01-22 10:58:02 - Succesfully moved to
2025-01-22 10:58:02 - Got files
2025-01-22 10:58:02 - Got directories
2025-01-22 10:58:02 - Current used storage is 74.86
2025-01-22 10:58:05 - Succesfully deleted 1 files
2025-01-22 10:58:05 - File Zoom_aM0cBMMuYW.png was deleted!
2025-01-22 10:58:05 - Got directories
2025-01-22 10:58:05 - Got files
2025-01-22 10:58:05 - Current used storage is 74.378
2025-01-22 10:58:07 - Succesfully recovered 1 files
2025-01-22 10:58:07 - Got files
2025-01-22 10:58:07 - Got directories
2025-01-22 10:58:07 - Succefully recovered macchiato.qbtheme
2025-01-22 10:58:07 - Current used storage is 74.378
2025-01-22 10:58:09 - Succesfully moved to
2025-01-22 10:58:09 - Current used storage is 74.378
2025-01-22 10:58:09 - Got files
2025-01-22 10:58:09 - Got directories
2025-01-22 10:58:10 - Succesfully moved to
2025-01-22 10:58:10 - Got directories
2025-01-22 10:58:10 - Got files
2025-01-22 10:58:10 - Current used storage is 74.378
2025-01-22 10:58:12 - Succesfully moved to
2025-01-22 10:58:12 - Got files
2025-01-22 10:58:12 - Current used storage is 74.378
2025-01-22 10:58:12 - Got directories
2025-01-22 10:58:13 - Succesfully moved to
2025-01-22 10:58:13 - Got files
2025-01-22 10:58:13 - Got directories
2025-01-22 10:58:13 - Current used storage is 74.378
2025-01-22 10:58:17 - File/Folder rename was renamed to jj
2025-01-22 10:58:17 - Got files
2025-01-22 10:58:17 - Got directories
2025-01-22 10:58:17 - Current used storage is 74.378
2025-01-22 10:58:19 - Succesfully removed 1 files from share
2025-01-22 10:58:19 - Succefully remove jj from share
2025-01-22 10:58:19 - Got files
2025-01-22 10:58:19 - Got directories
2025-01-22 10:58:19 - Current used storage is 74.378
2025-01-22 10:58:20 - Succesfully moved to
2025-01-22 10:58:20 - Current used storage is 74.378
2025-01-22 10:58:20 - Got files
2025-01-22 10:58:21 - Got directories
2025-01-22 10:58:21 - Got files
2025-01-22 10:58:21 - Current used storage is 74.378
2025-01-22 10:58:21 - Got directories
2025-01-22 10:58:23 - Server return an error: 103 Invalid email address
2025-01-22 10:58:31 - Traceback (most recent call last):
  File "c:\Users\idanh\Desktop\Cyber\My Projects\Final-Project\Main\client\modules\protocol.py", line 207, in upload_icon
    self.send_files("ICOS")
    ^^^^^^^^^^^^^^^
AttributeError: 'Protocol' object has no attribute 'send_files'. Did you mean: 'get_files'?
2025-01-22 10:59:07 - Login was succesfull for user: a
2025-01-22 10:59:07 - File data recieved 0
2025-01-22 10:59:07 - Profile picture was recieved
2025-01-22 10:59:07 - Got files
2025-01-22 10:59:07 - Current used storage is 74.378
2025-01-22 10:59:07 - Got directories
2025-01-22 10:59:14 - start upload:
2025-01-22 10:59:14 - 8b1ca0cb6dc34b0ca49e03e6b5fe8cf1
2025-01-22 10:59:14 - Profile icon started uploading succefully!
2025-01-22 10:59:14 - Current used storage is 74.378
2025-01-22 10:59:14 - Profile icon uploaded succefully!
2025-01-22 10:59:14 - Got files
2025-01-22 10:59:14 - File data recieved 0
2025-01-22 10:59:14 - Profile picture was recieved
2025-01-22 10:59:14 - Got directories
2025-01-22 10:59:20 - Got files
2025-01-22 10:59:20 - Current used storage is 74.378
2025-01-22 10:59:20 - Got directories
2025-01-22 10:59:20 - Logout succesfull
2025-01-22 10:59:39 - Signup was successful for user: Test, password:Idan1234
2025-01-22 11:00:22 - Verification for user testest@gmail.com was succesfull
2025-01-22 11:00:31 - Traceback (most recent call last):
  File "c:\Users\idanh\Desktop\Cyber\My Projects\Final-Project\Main\client\modules\protocol.py", line 325, in protocol_parse_reply
    self.window.user["email"] = email
    ~~~~~~~~~~~~~~~~^^^^^^^^^
TypeError: 'QLineEdit' object does not support item assignment
2025-01-22 11:00:31 - Login was succesfull for user: Test
2025-01-22 11:02:44 - Login was succesfull for user: a
2025-01-22 11:02:44 - File data recieved 0
2025-01-22 11:02:44 - Profile picture was recieved
2025-01-22 11:02:44 - Got files
2025-01-22 11:02:44 - Current used storage is 74.378
2025-01-22 11:02:44 - Got directories
2025-01-22 11:02:46 - Logout succesfull
2025-01-22 11:02:53 - Login was succesfull for user: Test
2025-01-22 11:02:53 - File data recieved 0
2025-01-22 11:02:53 - Profile picture was recieved
2025-01-22 11:02:53 - Got files
2025-01-22 11:02:53 - Got directories
2025-01-22 11:02:53 - Current used storage is 0.0
2025-01-22 11:02:53 - Cookie recieved
2025-01-22 11:03:00 - Password reset code was sent to testest@gmail.com
2025-01-22 11:03:26 - Password was reset for user: testest@gmail.com, new password: Idan12345
2025-01-22 11:03:26 - Logout succesfull
2025-01-22 11:03:36 - Login was succesfull for user: Test
2025-01-22 11:03:36 - File data recieved 0
2025-01-22 11:03:36 - Profile picture was recieved
2025-01-22 11:03:36 - Got files
2025-01-22 11:03:36 - Got directories
2025-01-22 11:03:36 - Current used storage is 0.0
2025-01-22 11:03:36 - Cookie recieved
2025-01-22 11:03:47 - Login was succesfull for user: Test
2025-01-22 11:03:47 - File data recieved 0
2025-01-22 11:03:47 - Profile picture was recieved
2025-01-22 11:03:47 - Got files
2025-01-22 11:03:47 - Current used storage is 0.0
2025-01-22 11:03:47 - Got directories
2025-01-22 11:03:53 - Username changed to Test1
2025-01-22 11:03:58 - Got files
2025-01-22 11:03:58 - Got directories
2025-01-22 11:03:58 - Current used storage is 0.0
2025-01-22 11:04:25 - User testest@gmail.com was deleted
2025-01-22 11:04:31 - Server return an error: 003 Please check your password and email/username and try again.
2025-01-22 11:15:58 - No server found
2025-01-22 11:15:58 - Traceback (most recent call last):
  File "c:\Users\idanh\Desktop\Cyber\My Projects\Final-Project\Main\client\modules\protocol.py", line 587, in connect_server
    self.ip, self.port = self.network.search_server()
    ^^^^^^^^^^^^^^^^^^
TypeError: cannot unpack non-iterable NoneType object
2025-01-22 11:16:01 - No server found
2025-01-22 11:16:01 - Traceback (most recent call last):
  File "c:\Users\idanh\Desktop\Cyber\My Projects\Final-Project\Main\client\modules\protocol.py", line 587, in connect_server
    self.ip, self.port = self.network.search_server()
    ^^^^^^^^^^^^^^^^^^
TypeError: cannot unpack non-iterable NoneType object

During handling of the above exception, another exception occurred:

Traceback (most recent call last):
  File "c:\Users\idanh\Desktop\Cyber\My Projects\Final-Project\Main\client\modules\protocol.py", line 587, in connect_server
    self.ip, self.port = self.network.search_server()
    ^^^^^^^^^^^^^^^^^^
TypeError: cannot unpack non-iterable NoneType object
2025-01-22 11:16:01 - Traceback (most recent call last):
  File "c:\Users\idanh\Desktop\Cyber\My Projects\Final-Project\Main\client\modules\protocol.py", line 587, in connect_server
    self.ip, self.port = self.network.search_server()
    ^^^^^^^^^^^^^^^^^^
TypeError: cannot unpack non-iterable NoneType object

During handling of the above exception, another exception occurred:

Traceback (most recent call last):
  File "c:\Users\idanh\Desktop\Cyber\My Projects\Final-Project\Main\client\modules\protocol.py", line 587, in connect_server
    self.ip, self.port = self.network.search_server()
    ^^^^^^^^^^^^^^^^^^
TypeError: cannot unpack non-iterable NoneType object

During handling of the above exception, another exception occurred:

Traceback (most recent call last):
  File "c:\Users\idanh\Desktop\Cyber\My Projects\Final-Project\Main\client\modules\gui.py", line 612, in not_connected_page
    if connect: self.protocol.connect_server(self.protocol.ip, self.protocol.port, True)
                ^^^^^^^^^^^^^^^^^^^^^^^^^^^^^^^^^^^^^^^^^^^^^^^^^^^^^^^^^^^^^^^^^^^^^^^^
  File "c:\Users\idanh\Desktop\Cyber\My Projects\Final-Project\Main\client\modules\protocol.py", line 610, in connect_server
    receive_thread.pause()
    ^^^^^^^^^^^^^^^^^^^^
AttributeError: 'bool' object has no attribute 'pause'
2025-01-22 11:17:19 - No server found
2025-01-22 11:17:19 - Traceback (most recent call last):
  File "c:\Users\idanh\Desktop\Cyber\My Projects\Final-Project\Main\client\modules\protocol.py", line 587, in connect_server
    self.ip, self.port = self.network.search_server()
                         ^^^^^^^^^^^^^^^^^^^^^^^^^^^^
  File "c:\Users\idanh\Desktop\Cyber\My Projects\Final-Project\Main\client\modules\networking.py", line 144, in search_server
    return ip, port
               ^^^^
UnboundLocalError: cannot access local variable 'port' where it is not associated with a value
2025-01-22 11:17:22 - No server found
2025-01-22 11:17:22 - Traceback (most recent call last):
  File "c:\Users\idanh\Desktop\Cyber\My Projects\Final-Project\Main\client\modules\protocol.py", line 587, in connect_server
    self.ip, self.port = self.network.search_server()
                         ^^^^^^^^^^^^^^^^^^^^^^^^^^^^
  File "c:\Users\idanh\Desktop\Cyber\My Projects\Final-Project\Main\client\modules\networking.py", line 144, in search_server
    return ip, port
               ^^^^
UnboundLocalError: cannot access local variable 'port' where it is not associated with a value

During handling of the above exception, another exception occurred:

Traceback (most recent call last):
  File "c:\Users\idanh\Desktop\Cyber\My Projects\Final-Project\Main\client\modules\protocol.py", line 587, in connect_server
    self.ip, self.port = self.network.search_server()
                         ^^^^^^^^^^^^^^^^^^^^^^^^^^^^
  File "c:\Users\idanh\Desktop\Cyber\My Projects\Final-Project\Main\client\modules\networking.py", line 144, in search_server
    return ip, port
               ^^^^
UnboundLocalError: cannot access local variable 'port' where it is not associated with a value
2025-01-22 11:17:22 - Traceback (most recent call last):
  File "c:\Users\idanh\Desktop\Cyber\My Projects\Final-Project\Main\client\modules\protocol.py", line 587, in connect_server
    self.ip, self.port = self.network.search_server()
                         ^^^^^^^^^^^^^^^^^^^^^^^^^^^^
  File "c:\Users\idanh\Desktop\Cyber\My Projects\Final-Project\Main\client\modules\networking.py", line 144, in search_server
    return ip, port
               ^^^^
UnboundLocalError: cannot access local variable 'port' where it is not associated with a value

During handling of the above exception, another exception occurred:

Traceback (most recent call last):
  File "c:\Users\idanh\Desktop\Cyber\My Projects\Final-Project\Main\client\modules\protocol.py", line 587, in connect_server
    self.ip, self.port = self.network.search_server()
                         ^^^^^^^^^^^^^^^^^^^^^^^^^^^^
  File "c:\Users\idanh\Desktop\Cyber\My Projects\Final-Project\Main\client\modules\networking.py", line 144, in search_server
    return ip, port
               ^^^^
UnboundLocalError: cannot access local variable 'port' where it is not associated with a value

During handling of the above exception, another exception occurred:

Traceback (most recent call last):
  File "c:\Users\idanh\Desktop\Cyber\My Projects\Final-Project\Main\client\modules\gui.py", line 612, in not_connected_page
    if connect: self.protocol.connect_server(self.protocol.ip, self.protocol.port, True)
                ^^^^^^^^^^^^^^^^^^^^^^^^^^^^^^^^^^^^^^^^^^^^^^^^^^^^^^^^^^^^^^^^^^^^^^^^
  File "c:\Users\idanh\Desktop\Cyber\My Projects\Final-Project\Main\client\modules\protocol.py", line 610, in connect_server
    receive_thread.pause()
    ^^^^^^^^^^^^^^^^^^^^
AttributeError: 'bool' object has no attribute 'pause'
2025-01-22 11:18:01 - No server found
2025-01-22 11:18:03 - Traceback (most recent call last):
  File "c:\Users\idanh\Desktop\Cyber\My Projects\Final-Project\Main\client\modules\protocol.py", line 589, in connect_server
    sock.connect((self.ip, self.port))
ConnectionRefusedError: [WinError 10061] No connection could be made because the target machine actively refused it
2025-01-22 11:18:07 - No server found
2025-01-22 11:18:09 - Traceback (most recent call last):
  File "c:\Users\idanh\Desktop\Cyber\My Projects\Final-Project\Main\client\modules\protocol.py", line 589, in connect_server
    sock.connect((self.ip, self.port))
ConnectionRefusedError: [WinError 10061] No connection could be made because the target machine actively refused it

During handling of the above exception, another exception occurred:

Traceback (most recent call last):
  File "c:\Users\idanh\Desktop\Cyber\My Projects\Final-Project\Main\client\modules\protocol.py", line 589, in connect_server
    sock.connect((self.ip, self.port))
ConnectionRefusedError: [WinError 10061] No connection could be made because the target machine actively refused it
2025-01-22 11:18:09 - Traceback (most recent call last):
  File "c:\Users\idanh\Desktop\Cyber\My Projects\Final-Project\Main\client\modules\protocol.py", line 589, in connect_server
    sock.connect((self.ip, self.port))
ConnectionRefusedError: [WinError 10061] No connection could be made because the target machine actively refused it

During handling of the above exception, another exception occurred:

Traceback (most recent call last):
  File "c:\Users\idanh\Desktop\Cyber\My Projects\Final-Project\Main\client\modules\protocol.py", line 589, in connect_server
    sock.connect((self.ip, self.port))
ConnectionRefusedError: [WinError 10061] No connection could be made because the target machine actively refused it

During handling of the above exception, another exception occurred:

Traceback (most recent call last):
  File "c:\Users\idanh\Desktop\Cyber\My Projects\Final-Project\Main\client\modules\gui.py", line 612, in not_connected_page
    if connect: self.protocol.connect_server(self.protocol.ip, self.protocol.port, True)
                ^^^^^^^^^^^^^^^^^^^^^^^^^^^^^^^^^^^^^^^^^^^^^^^^^^^^^^^^^^^^^^^^^^^^^^^^
  File "c:\Users\idanh\Desktop\Cyber\My Projects\Final-Project\Main\client\modules\protocol.py", line 610, in connect_server
    receive_thread.pause()
    ^^^^^^^^^^^^^^^^^^^^
AttributeError: 'bool' object has no attribute 'pause'
2025-01-22 11:21:24 - No server found
2025-01-22 11:21:27 - Traceback (most recent call last):
  File "c:\Users\idanh\Desktop\Cyber\My Projects\Final-Project\Main\client\modules\protocol.py", line 589, in connect_server
    sock.connect((self.ip, self.port))
ConnectionRefusedError: [WinError 10061] No connection could be made because the target machine actively refused it
2025-01-22 11:21:52 - No server found
2025-01-22 11:21:54 - Traceback (most recent call last):
  File "c:\Users\idanh\Desktop\Cyber\My Projects\Final-Project\Main\client\modules\protocol.py", line 589, in connect_server
    sock.connect((self.ip, self.port))
ConnectionRefusedError: [WinError 10061] No connection could be made because the target machine actively refused it
2025-01-22 11:21:58 - No server found
2025-01-22 11:22:00 - Traceback (most recent call last):
  File "c:\Users\idanh\Desktop\Cyber\My Projects\Final-Project\Main\client\modules\protocol.py", line 589, in connect_server
    sock.connect((self.ip, self.port))
ConnectionRefusedError: [WinError 10061] No connection could be made because the target machine actively refused it

During handling of the above exception, another exception occurred:

Traceback (most recent call last):
  File "c:\Users\idanh\Desktop\Cyber\My Projects\Final-Project\Main\client\modules\protocol.py", line 589, in connect_server
    sock.connect((self.ip, self.port))
ConnectionRefusedError: [WinError 10061] No connection could be made because the target machine actively refused it
2025-01-22 11:22:03 - No server found
2025-01-22 11:22:05 - Traceback (most recent call last):
  File "c:\Users\idanh\Desktop\Cyber\My Projects\Final-Project\Main\client\modules\protocol.py", line 589, in connect_server
    sock.connect((self.ip, self.port))
ConnectionRefusedError: [WinError 10061] No connection could be made because the target machine actively refused it

During handling of the above exception, another exception occurred:

Traceback (most recent call last):
  File "c:\Users\idanh\Desktop\Cyber\My Projects\Final-Project\Main\client\modules\protocol.py", line 589, in connect_server
    sock.connect((self.ip, self.port))
ConnectionRefusedError: [WinError 10061] No connection could be made because the target machine actively refused it

During handling of the above exception, another exception occurred:

Traceback (most recent call last):
  File "c:\Users\idanh\Desktop\Cyber\My Projects\Final-Project\Main\client\modules\protocol.py", line 589, in connect_server
    sock.connect((self.ip, self.port))
ConnectionRefusedError: [WinError 10061] No connection could be made because the target machine actively refused it
2025-01-22 11:22:08 - No server found
2025-01-22 11:22:10 - Traceback (most recent call last):
  File "c:\Users\idanh\Desktop\Cyber\My Projects\Final-Project\Main\client\modules\protocol.py", line 589, in connect_server
    sock.connect((self.ip, self.port))
ConnectionRefusedError: [WinError 10061] No connection could be made because the target machine actively refused it

During handling of the above exception, another exception occurred:

Traceback (most recent call last):
  File "c:\Users\idanh\Desktop\Cyber\My Projects\Final-Project\Main\client\modules\protocol.py", line 589, in connect_server
    sock.connect((self.ip, self.port))
ConnectionRefusedError: [WinError 10061] No connection could be made because the target machine actively refused it

During handling of the above exception, another exception occurred:

Traceback (most recent call last):
  File "c:\Users\idanh\Desktop\Cyber\My Projects\Final-Project\Main\client\modules\protocol.py", line 589, in connect_server
    sock.connect((self.ip, self.port))
ConnectionRefusedError: [WinError 10061] No connection could be made because the target machine actively refused it

During handling of the above exception, another exception occurred:

Traceback (most recent call last):
  File "c:\Users\idanh\Desktop\Cyber\My Projects\Final-Project\Main\client\modules\protocol.py", line 589, in connect_server
    sock.connect((self.ip, self.port))
ConnectionRefusedError: [WinError 10061] No connection could be made because the target machine actively refused it
2025-01-22 11:22:13 - No server found
2025-01-22 11:22:15 - Traceback (most recent call last):
  File "c:\Users\idanh\Desktop\Cyber\My Projects\Final-Project\Main\client\modules\protocol.py", line 589, in connect_server
    sock.connect((self.ip, self.port))
ConnectionRefusedError: [WinError 10061] No connection could be made because the target machine actively refused it

During handling of the above exception, another exception occurred:

Traceback (most recent call last):
  File "c:\Users\idanh\Desktop\Cyber\My Projects\Final-Project\Main\client\modules\protocol.py", line 589, in connect_server
    sock.connect((self.ip, self.port))
ConnectionRefusedError: [WinError 10061] No connection could be made because the target machine actively refused it

During handling of the above exception, another exception occurred:

Traceback (most recent call last):
  File "c:\Users\idanh\Desktop\Cyber\My Projects\Final-Project\Main\client\modules\protocol.py", line 589, in connect_server
    sock.connect((self.ip, self.port))
ConnectionRefusedError: [WinError 10061] No connection could be made because the target machine actively refused it

During handling of the above exception, another exception occurred:

Traceback (most recent call last):
  File "c:\Users\idanh\Desktop\Cyber\My Projects\Final-Project\Main\client\modules\protocol.py", line 589, in connect_server
    sock.connect((self.ip, self.port))
ConnectionRefusedError: [WinError 10061] No connection could be made because the target machine actively refused it

During handling of the above exception, another exception occurred:

Traceback (most recent call last):
  File "c:\Users\idanh\Desktop\Cyber\My Projects\Final-Project\Main\client\modules\protocol.py", line 589, in connect_server
    sock.connect((self.ip, self.port))
ConnectionRefusedError: [WinError 10061] No connection could be made because the target machine actively refused it
2025-01-22 11:22:18 - No server found
2025-01-22 11:22:20 - Traceback (most recent call last):
  File "c:\Users\idanh\Desktop\Cyber\My Projects\Final-Project\Main\client\modules\protocol.py", line 589, in connect_server
    sock.connect((self.ip, self.port))
ConnectionRefusedError: [WinError 10061] No connection could be made because the target machine actively refused it

During handling of the above exception, another exception occurred:

Traceback (most recent call last):
  File "c:\Users\idanh\Desktop\Cyber\My Projects\Final-Project\Main\client\modules\protocol.py", line 589, in connect_server
    sock.connect((self.ip, self.port))
ConnectionRefusedError: [WinError 10061] No connection could be made because the target machine actively refused it

During handling of the above exception, another exception occurred:

Traceback (most recent call last):
  File "c:\Users\idanh\Desktop\Cyber\My Projects\Final-Project\Main\client\modules\protocol.py", line 589, in connect_server
    sock.connect((self.ip, self.port))
ConnectionRefusedError: [WinError 10061] No connection could be made because the target machine actively refused it

During handling of the above exception, another exception occurred:

Traceback (most recent call last):
  File "c:\Users\idanh\Desktop\Cyber\My Projects\Final-Project\Main\client\modules\protocol.py", line 589, in connect_server
    sock.connect((self.ip, self.port))
ConnectionRefusedError: [WinError 10061] No connection could be made because the target machine actively refused it

During handling of the above exception, another exception occurred:

Traceback (most recent call last):
  File "c:\Users\idanh\Desktop\Cyber\My Projects\Final-Project\Main\client\modules\protocol.py", line 589, in connect_server
    sock.connect((self.ip, self.port))
ConnectionRefusedError: [WinError 10061] No connection could be made because the target machine actively refused it

During handling of the above exception, another exception occurred:

Traceback (most recent call last):
  File "c:\Users\idanh\Desktop\Cyber\My Projects\Final-Project\Main\client\modules\protocol.py", line 589, in connect_server
    sock.connect((self.ip, self.port))
ConnectionRefusedError: [WinError 10061] No connection could be made because the target machine actively refused it
2025-01-22 11:22:23 - No server found
2025-01-22 11:22:25 - Traceback (most recent call last):
  File "c:\Users\idanh\Desktop\Cyber\My Projects\Final-Project\Main\client\modules\protocol.py", line 589, in connect_server
    sock.connect((self.ip, self.port))
ConnectionRefusedError: [WinError 10061] No connection could be made because the target machine actively refused it

During handling of the above exception, another exception occurred:

Traceback (most recent call last):
  File "c:\Users\idanh\Desktop\Cyber\My Projects\Final-Project\Main\client\modules\protocol.py", line 589, in connect_server
    sock.connect((self.ip, self.port))
ConnectionRefusedError: [WinError 10061] No connection could be made because the target machine actively refused it

During handling of the above exception, another exception occurred:

Traceback (most recent call last):
  File "c:\Users\idanh\Desktop\Cyber\My Projects\Final-Project\Main\client\modules\protocol.py", line 589, in connect_server
    sock.connect((self.ip, self.port))
ConnectionRefusedError: [WinError 10061] No connection could be made because the target machine actively refused it

During handling of the above exception, another exception occurred:

Traceback (most recent call last):
  File "c:\Users\idanh\Desktop\Cyber\My Projects\Final-Project\Main\client\modules\protocol.py", line 589, in connect_server
    sock.connect((self.ip, self.port))
ConnectionRefusedError: [WinError 10061] No connection could be made because the target machine actively refused it

During handling of the above exception, another exception occurred:

Traceback (most recent call last):
  File "c:\Users\idanh\Desktop\Cyber\My Projects\Final-Project\Main\client\modules\protocol.py", line 589, in connect_server
    sock.connect((self.ip, self.port))
ConnectionRefusedError: [WinError 10061] No connection could be made because the target machine actively refused it

During handling of the above exception, another exception occurred:

Traceback (most recent call last):
  File "c:\Users\idanh\Desktop\Cyber\My Projects\Final-Project\Main\client\modules\protocol.py", line 589, in connect_server
    sock.connect((self.ip, self.port))
ConnectionRefusedError: [WinError 10061] No connection could be made because the target machine actively refused it

During handling of the above exception, another exception occurred:

Traceback (most recent call last):
  File "c:\Users\idanh\Desktop\Cyber\My Projects\Final-Project\Main\client\modules\protocol.py", line 589, in connect_server
    sock.connect((self.ip, self.port))
ConnectionRefusedError: [WinError 10061] No connection could be made because the target machine actively refused it
2025-01-22 11:22:28 - No server found
2025-01-22 11:22:30 - Traceback (most recent call last):
  File "c:\Users\idanh\Desktop\Cyber\My Projects\Final-Project\Main\client\modules\protocol.py", line 589, in connect_server
    sock.connect((self.ip, self.port))
ConnectionRefusedError: [WinError 10061] No connection could be made because the target machine actively refused it

During handling of the above exception, another exception occurred:

Traceback (most recent call last):
  File "c:\Users\idanh\Desktop\Cyber\My Projects\Final-Project\Main\client\modules\protocol.py", line 589, in connect_server
    sock.connect((self.ip, self.port))
ConnectionRefusedError: [WinError 10061] No connection could be made because the target machine actively refused it

During handling of the above exception, another exception occurred:

Traceback (most recent call last):
  File "c:\Users\idanh\Desktop\Cyber\My Projects\Final-Project\Main\client\modules\protocol.py", line 589, in connect_server
    sock.connect((self.ip, self.port))
ConnectionRefusedError: [WinError 10061] No connection could be made because the target machine actively refused it

During handling of the above exception, another exception occurred:

Traceback (most recent call last):
  File "c:\Users\idanh\Desktop\Cyber\My Projects\Final-Project\Main\client\modules\protocol.py", line 589, in connect_server
    sock.connect((self.ip, self.port))
ConnectionRefusedError: [WinError 10061] No connection could be made because the target machine actively refused it

During handling of the above exception, another exception occurred:

Traceback (most recent call last):
  File "c:\Users\idanh\Desktop\Cyber\My Projects\Final-Project\Main\client\modules\protocol.py", line 589, in connect_server
    sock.connect((self.ip, self.port))
ConnectionRefusedError: [WinError 10061] No connection could be made because the target machine actively refused it

During handling of the above exception, another exception occurred:

Traceback (most recent call last):
  File "c:\Users\idanh\Desktop\Cyber\My Projects\Final-Project\Main\client\modules\protocol.py", line 589, in connect_server
    sock.connect((self.ip, self.port))
ConnectionRefusedError: [WinError 10061] No connection could be made because the target machine actively refused it

During handling of the above exception, another exception occurred:

Traceback (most recent call last):
  File "c:\Users\idanh\Desktop\Cyber\My Projects\Final-Project\Main\client\modules\protocol.py", line 589, in connect_server
    sock.connect((self.ip, self.port))
ConnectionRefusedError: [WinError 10061] No connection could be made because the target machine actively refused it

During handling of the above exception, another exception occurred:

Traceback (most recent call last):
  File "c:\Users\idanh\Desktop\Cyber\My Projects\Final-Project\Main\client\modules\protocol.py", line 589, in connect_server
    sock.connect((self.ip, self.port))
ConnectionRefusedError: [WinError 10061] No connection could be made because the target machine actively refused it
2025-01-22 11:22:33 - No server found
2025-01-22 11:22:35 - Traceback (most recent call last):
  File "c:\Users\idanh\Desktop\Cyber\My Projects\Final-Project\Main\client\modules\protocol.py", line 589, in connect_server
    sock.connect((self.ip, self.port))
ConnectionRefusedError: [WinError 10061] No connection could be made because the target machine actively refused it

During handling of the above exception, another exception occurred:

Traceback (most recent call last):
  File "c:\Users\idanh\Desktop\Cyber\My Projects\Final-Project\Main\client\modules\protocol.py", line 589, in connect_server
    sock.connect((self.ip, self.port))
ConnectionRefusedError: [WinError 10061] No connection could be made because the target machine actively refused it

During handling of the above exception, another exception occurred:

Traceback (most recent call last):
  File "c:\Users\idanh\Desktop\Cyber\My Projects\Final-Project\Main\client\modules\protocol.py", line 589, in connect_server
    sock.connect((self.ip, self.port))
ConnectionRefusedError: [WinError 10061] No connection could be made because the target machine actively refused it

During handling of the above exception, another exception occurred:

Traceback (most recent call last):
  File "c:\Users\idanh\Desktop\Cyber\My Projects\Final-Project\Main\client\modules\protocol.py", line 589, in connect_server
    sock.connect((self.ip, self.port))
ConnectionRefusedError: [WinError 10061] No connection could be made because the target machine actively refused it

During handling of the above exception, another exception occurred:

Traceback (most recent call last):
  File "c:\Users\idanh\Desktop\Cyber\My Projects\Final-Project\Main\client\modules\protocol.py", line 589, in connect_server
    sock.connect((self.ip, self.port))
ConnectionRefusedError: [WinError 10061] No connection could be made because the target machine actively refused it

During handling of the above exception, another exception occurred:

Traceback (most recent call last):
  File "c:\Users\idanh\Desktop\Cyber\My Projects\Final-Project\Main\client\modules\protocol.py", line 589, in connect_server
    sock.connect((self.ip, self.port))
ConnectionRefusedError: [WinError 10061] No connection could be made because the target machine actively refused it

During handling of the above exception, another exception occurred:

Traceback (most recent call last):
  File "c:\Users\idanh\Desktop\Cyber\My Projects\Final-Project\Main\client\modules\protocol.py", line 589, in connect_server
    sock.connect((self.ip, self.port))
ConnectionRefusedError: [WinError 10061] No connection could be made because the target machine actively refused it

During handling of the above exception, another exception occurred:

Traceback (most recent call last):
  File "c:\Users\idanh\Desktop\Cyber\My Projects\Final-Project\Main\client\modules\protocol.py", line 589, in connect_server
    sock.connect((self.ip, self.port))
ConnectionRefusedError: [WinError 10061] No connection could be made because the target machine actively refused it

During handling of the above exception, another exception occurred:

Traceback (most recent call last):
  File "c:\Users\idanh\Desktop\Cyber\My Projects\Final-Project\Main\client\modules\protocol.py", line 589, in connect_server
    sock.connect((self.ip, self.port))
ConnectionRefusedError: [WinError 10061] No connection could be made because the target machine actively refused it
2025-01-22 11:22:39 - No server found
2025-01-22 11:22:41 - Traceback (most recent call last):
  File "c:\Users\idanh\Desktop\Cyber\My Projects\Final-Project\Main\client\modules\protocol.py", line 589, in connect_server
    sock.connect((self.ip, self.port))
ConnectionRefusedError: [WinError 10061] No connection could be made because the target machine actively refused it

During handling of the above exception, another exception occurred:

Traceback (most recent call last):
  File "c:\Users\idanh\Desktop\Cyber\My Projects\Final-Project\Main\client\modules\protocol.py", line 589, in connect_server
    sock.connect((self.ip, self.port))
ConnectionRefusedError: [WinError 10061] No connection could be made because the target machine actively refused it

During handling of the above exception, another exception occurred:

Traceback (most recent call last):
  File "c:\Users\idanh\Desktop\Cyber\My Projects\Final-Project\Main\client\modules\protocol.py", line 589, in connect_server
    sock.connect((self.ip, self.port))
ConnectionRefusedError: [WinError 10061] No connection could be made because the target machine actively refused it

During handling of the above exception, another exception occurred:

Traceback (most recent call last):
  File "c:\Users\idanh\Desktop\Cyber\My Projects\Final-Project\Main\client\modules\protocol.py", line 589, in connect_server
    sock.connect((self.ip, self.port))
ConnectionRefusedError: [WinError 10061] No connection could be made because the target machine actively refused it

During handling of the above exception, another exception occurred:

Traceback (most recent call last):
  File "c:\Users\idanh\Desktop\Cyber\My Projects\Final-Project\Main\client\modules\protocol.py", line 589, in connect_server
    sock.connect((self.ip, self.port))
ConnectionRefusedError: [WinError 10061] No connection could be made because the target machine actively refused it

During handling of the above exception, another exception occurred:

Traceback (most recent call last):
  File "c:\Users\idanh\Desktop\Cyber\My Projects\Final-Project\Main\client\modules\protocol.py", line 589, in connect_server
    sock.connect((self.ip, self.port))
ConnectionRefusedError: [WinError 10061] No connection could be made because the target machine actively refused it

During handling of the above exception, another exception occurred:

Traceback (most recent call last):
  File "c:\Users\idanh\Desktop\Cyber\My Projects\Final-Project\Main\client\modules\protocol.py", line 589, in connect_server
    sock.connect((self.ip, self.port))
ConnectionRefusedError: [WinError 10061] No connection could be made because the target machine actively refused it

During handling of the above exception, another exception occurred:

Traceback (most recent call last):
  File "c:\Users\idanh\Desktop\Cyber\My Projects\Final-Project\Main\client\modules\protocol.py", line 589, in connect_server
    sock.connect((self.ip, self.port))
ConnectionRefusedError: [WinError 10061] No connection could be made because the target machine actively refused it

During handling of the above exception, another exception occurred:

Traceback (most recent call last):
  File "c:\Users\idanh\Desktop\Cyber\My Projects\Final-Project\Main\client\modules\protocol.py", line 589, in connect_server
    sock.connect((self.ip, self.port))
ConnectionRefusedError: [WinError 10061] No connection could be made because the target machine actively refused it

During handling of the above exception, another exception occurred:

Traceback (most recent call last):
  File "c:\Users\idanh\Desktop\Cyber\My Projects\Final-Project\Main\client\modules\protocol.py", line 589, in connect_server
    sock.connect((self.ip, self.port))
ConnectionRefusedError: [WinError 10061] No connection could be made because the target machine actively refused it
2025-01-22 11:22:44 - No server found
2025-01-22 11:22:46 - Traceback (most recent call last):
  File "c:\Users\idanh\Desktop\Cyber\My Projects\Final-Project\Main\client\modules\protocol.py", line 589, in connect_server
    sock.connect((self.ip, self.port))
ConnectionRefusedError: [WinError 10061] No connection could be made because the target machine actively refused it

During handling of the above exception, another exception occurred:

Traceback (most recent call last):
  File "c:\Users\idanh\Desktop\Cyber\My Projects\Final-Project\Main\client\modules\protocol.py", line 589, in connect_server
    sock.connect((self.ip, self.port))
ConnectionRefusedError: [WinError 10061] No connection could be made because the target machine actively refused it

During handling of the above exception, another exception occurred:

Traceback (most recent call last):
  File "c:\Users\idanh\Desktop\Cyber\My Projects\Final-Project\Main\client\modules\protocol.py", line 589, in connect_server
    sock.connect((self.ip, self.port))
ConnectionRefusedError: [WinError 10061] No connection could be made because the target machine actively refused it

During handling of the above exception, another exception occurred:

Traceback (most recent call last):
  File "c:\Users\idanh\Desktop\Cyber\My Projects\Final-Project\Main\client\modules\protocol.py", line 589, in connect_server
    sock.connect((self.ip, self.port))
ConnectionRefusedError: [WinError 10061] No connection could be made because the target machine actively refused it

During handling of the above exception, another exception occurred:

Traceback (most recent call last):
  File "c:\Users\idanh\Desktop\Cyber\My Projects\Final-Project\Main\client\modules\protocol.py", line 589, in connect_server
    sock.connect((self.ip, self.port))
ConnectionRefusedError: [WinError 10061] No connection could be made because the target machine actively refused it

During handling of the above exception, another exception occurred:

Traceback (most recent call last):
  File "c:\Users\idanh\Desktop\Cyber\My Projects\Final-Project\Main\client\modules\protocol.py", line 589, in connect_server
    sock.connect((self.ip, self.port))
ConnectionRefusedError: [WinError 10061] No connection could be made because the target machine actively refused it

During handling of the above exception, another exception occurred:

Traceback (most recent call last):
  File "c:\Users\idanh\Desktop\Cyber\My Projects\Final-Project\Main\client\modules\protocol.py", line 589, in connect_server
    sock.connect((self.ip, self.port))
ConnectionRefusedError: [WinError 10061] No connection could be made because the target machine actively refused it

During handling of the above exception, another exception occurred:

Traceback (most recent call last):
  File "c:\Users\idanh\Desktop\Cyber\My Projects\Final-Project\Main\client\modules\protocol.py", line 589, in connect_server
    sock.connect((self.ip, self.port))
ConnectionRefusedError: [WinError 10061] No connection could be made because the target machine actively refused it

During handling of the above exception, another exception occurred:

Traceback (most recent call last):
  File "c:\Users\idanh\Desktop\Cyber\My Projects\Final-Project\Main\client\modules\protocol.py", line 589, in connect_server
    sock.connect((self.ip, self.port))
ConnectionRefusedError: [WinError 10061] No connection could be made because the target machine actively refused it

During handling of the above exception, another exception occurred:

Traceback (most recent call last):
  File "c:\Users\idanh\Desktop\Cyber\My Projects\Final-Project\Main\client\modules\protocol.py", line 589, in connect_server
    sock.connect((self.ip, self.port))
ConnectionRefusedError: [WinError 10061] No connection could be made because the target machine actively refused it

During handling of the above exception, another exception occurred:

Traceback (most recent call last):
  File "c:\Users\idanh\Desktop\Cyber\My Projects\Final-Project\Main\client\modules\protocol.py", line 589, in connect_server
    sock.connect((self.ip, self.port))
ConnectionRefusedError: [WinError 10061] No connection could be made because the target machine actively refused it
2025-01-22 11:22:49 - No server found
2025-01-22 11:22:51 - Traceback (most recent call last):
  File "c:\Users\idanh\Desktop\Cyber\My Projects\Final-Project\Main\client\modules\protocol.py", line 589, in connect_server
    sock.connect((self.ip, self.port))
ConnectionRefusedError: [WinError 10061] No connection could be made because the target machine actively refused it

During handling of the above exception, another exception occurred:

Traceback (most recent call last):
  File "c:\Users\idanh\Desktop\Cyber\My Projects\Final-Project\Main\client\modules\protocol.py", line 589, in connect_server
    sock.connect((self.ip, self.port))
ConnectionRefusedError: [WinError 10061] No connection could be made because the target machine actively refused it

During handling of the above exception, another exception occurred:

Traceback (most recent call last):
  File "c:\Users\idanh\Desktop\Cyber\My Projects\Final-Project\Main\client\modules\protocol.py", line 589, in connect_server
    sock.connect((self.ip, self.port))
ConnectionRefusedError: [WinError 10061] No connection could be made because the target machine actively refused it

During handling of the above exception, another exception occurred:

Traceback (most recent call last):
  File "c:\Users\idanh\Desktop\Cyber\My Projects\Final-Project\Main\client\modules\protocol.py", line 589, in connect_server
    sock.connect((self.ip, self.port))
ConnectionRefusedError: [WinError 10061] No connection could be made because the target machine actively refused it

During handling of the above exception, another exception occurred:

Traceback (most recent call last):
  File "c:\Users\idanh\Desktop\Cyber\My Projects\Final-Project\Main\client\modules\protocol.py", line 589, in connect_server
    sock.connect((self.ip, self.port))
ConnectionRefusedError: [WinError 10061] No connection could be made because the target machine actively refused it

During handling of the above exception, another exception occurred:

Traceback (most recent call last):
  File "c:\Users\idanh\Desktop\Cyber\My Projects\Final-Project\Main\client\modules\protocol.py", line 589, in connect_server
    sock.connect((self.ip, self.port))
ConnectionRefusedError: [WinError 10061] No connection could be made because the target machine actively refused it

During handling of the above exception, another exception occurred:

Traceback (most recent call last):
  File "c:\Users\idanh\Desktop\Cyber\My Projects\Final-Project\Main\client\modules\protocol.py", line 589, in connect_server
    sock.connect((self.ip, self.port))
ConnectionRefusedError: [WinError 10061] No connection could be made because the target machine actively refused it

During handling of the above exception, another exception occurred:

Traceback (most recent call last):
  File "c:\Users\idanh\Desktop\Cyber\My Projects\Final-Project\Main\client\modules\protocol.py", line 589, in connect_server
    sock.connect((self.ip, self.port))
ConnectionRefusedError: [WinError 10061] No connection could be made because the target machine actively refused it

During handling of the above exception, another exception occurred:

Traceback (most recent call last):
  File "c:\Users\idanh\Desktop\Cyber\My Projects\Final-Project\Main\client\modules\protocol.py", line 589, in connect_server
    sock.connect((self.ip, self.port))
ConnectionRefusedError: [WinError 10061] No connection could be made because the target machine actively refused it

During handling of the above exception, another exception occurred:

Traceback (most recent call last):
  File "c:\Users\idanh\Desktop\Cyber\My Projects\Final-Project\Main\client\modules\protocol.py", line 589, in connect_server
    sock.connect((self.ip, self.port))
ConnectionRefusedError: [WinError 10061] No connection could be made because the target machine actively refused it

During handling of the above exception, another exception occurred:

Traceback (most recent call last):
  File "c:\Users\idanh\Desktop\Cyber\My Projects\Final-Project\Main\client\modules\protocol.py", line 589, in connect_server
    sock.connect((self.ip, self.port))
ConnectionRefusedError: [WinError 10061] No connection could be made because the target machine actively refused it

During handling of the above exception, another exception occurred:

Traceback (most recent call last):
  File "c:\Users\idanh\Desktop\Cyber\My Projects\Final-Project\Main\client\modules\protocol.py", line 589, in connect_server
    sock.connect((self.ip, self.port))
ConnectionRefusedError: [WinError 10061] No connection could be made because the target machine actively refused it
2025-01-22 11:22:54 - No server found
2025-01-22 11:22:56 - Traceback (most recent call last):
  File "c:\Users\idanh\Desktop\Cyber\My Projects\Final-Project\Main\client\modules\protocol.py", line 589, in connect_server
    sock.connect((self.ip, self.port))
ConnectionRefusedError: [WinError 10061] No connection could be made because the target machine actively refused it

During handling of the above exception, another exception occurred:

Traceback (most recent call last):
  File "c:\Users\idanh\Desktop\Cyber\My Projects\Final-Project\Main\client\modules\protocol.py", line 589, in connect_server
    sock.connect((self.ip, self.port))
ConnectionRefusedError: [WinError 10061] No connection could be made because the target machine actively refused it

During handling of the above exception, another exception occurred:

Traceback (most recent call last):
  File "c:\Users\idanh\Desktop\Cyber\My Projects\Final-Project\Main\client\modules\protocol.py", line 589, in connect_server
    sock.connect((self.ip, self.port))
ConnectionRefusedError: [WinError 10061] No connection could be made because the target machine actively refused it

During handling of the above exception, another exception occurred:

Traceback (most recent call last):
  File "c:\Users\idanh\Desktop\Cyber\My Projects\Final-Project\Main\client\modules\protocol.py", line 589, in connect_server
    sock.connect((self.ip, self.port))
ConnectionRefusedError: [WinError 10061] No connection could be made because the target machine actively refused it

During handling of the above exception, another exception occurred:

Traceback (most recent call last):
  File "c:\Users\idanh\Desktop\Cyber\My Projects\Final-Project\Main\client\modules\protocol.py", line 589, in connect_server
    sock.connect((self.ip, self.port))
ConnectionRefusedError: [WinError 10061] No connection could be made because the target machine actively refused it

During handling of the above exception, another exception occurred:

Traceback (most recent call last):
  File "c:\Users\idanh\Desktop\Cyber\My Projects\Final-Project\Main\client\modules\protocol.py", line 589, in connect_server
    sock.connect((self.ip, self.port))
ConnectionRefusedError: [WinError 10061] No connection could be made because the target machine actively refused it

During handling of the above exception, another exception occurred:

Traceback (most recent call last):
  File "c:\Users\idanh\Desktop\Cyber\My Projects\Final-Project\Main\client\modules\protocol.py", line 589, in connect_server
    sock.connect((self.ip, self.port))
ConnectionRefusedError: [WinError 10061] No connection could be made because the target machine actively refused it

During handling of the above exception, another exception occurred:

Traceback (most recent call last):
  File "c:\Users\idanh\Desktop\Cyber\My Projects\Final-Project\Main\client\modules\protocol.py", line 589, in connect_server
    sock.connect((self.ip, self.port))
ConnectionRefusedError: [WinError 10061] No connection could be made because the target machine actively refused it

During handling of the above exception, another exception occurred:

Traceback (most recent call last):
  File "c:\Users\idanh\Desktop\Cyber\My Projects\Final-Project\Main\client\modules\protocol.py", line 589, in connect_server
    sock.connect((self.ip, self.port))
ConnectionRefusedError: [WinError 10061] No connection could be made because the target machine actively refused it

During handling of the above exception, another exception occurred:

Traceback (most recent call last):
  File "c:\Users\idanh\Desktop\Cyber\My Projects\Final-Project\Main\client\modules\protocol.py", line 589, in connect_server
    sock.connect((self.ip, self.port))
ConnectionRefusedError: [WinError 10061] No connection could be made because the target machine actively refused it

During handling of the above exception, another exception occurred:

Traceback (most recent call last):
  File "c:\Users\idanh\Desktop\Cyber\My Projects\Final-Project\Main\client\modules\protocol.py", line 589, in connect_server
    sock.connect((self.ip, self.port))
ConnectionRefusedError: [WinError 10061] No connection could be made because the target machine actively refused it

During handling of the above exception, another exception occurred:

Traceback (most recent call last):
  File "c:\Users\idanh\Desktop\Cyber\My Projects\Final-Project\Main\client\modules\protocol.py", line 589, in connect_server
    sock.connect((self.ip, self.port))
ConnectionRefusedError: [WinError 10061] No connection could be made because the target machine actively refused it

During handling of the above exception, another exception occurred:

Traceback (most recent call last):
  File "c:\Users\idanh\Desktop\Cyber\My Projects\Final-Project\Main\client\modules\protocol.py", line 589, in connect_server
    sock.connect((self.ip, self.port))
ConnectionRefusedError: [WinError 10061] No connection could be made because the target machine actively refused it
2025-01-22 11:22:59 - No server found
2025-01-22 11:23:01 - Traceback (most recent call last):
  File "c:\Users\idanh\Desktop\Cyber\My Projects\Final-Project\Main\client\modules\protocol.py", line 589, in connect_server
    sock.connect((self.ip, self.port))
ConnectionRefusedError: [WinError 10061] No connection could be made because the target machine actively refused it

During handling of the above exception, another exception occurred:

Traceback (most recent call last):
  File "c:\Users\idanh\Desktop\Cyber\My Projects\Final-Project\Main\client\modules\protocol.py", line 589, in connect_server
    sock.connect((self.ip, self.port))
ConnectionRefusedError: [WinError 10061] No connection could be made because the target machine actively refused it

During handling of the above exception, another exception occurred:

Traceback (most recent call last):
  File "c:\Users\idanh\Desktop\Cyber\My Projects\Final-Project\Main\client\modules\protocol.py", line 589, in connect_server
    sock.connect((self.ip, self.port))
ConnectionRefusedError: [WinError 10061] No connection could be made because the target machine actively refused it

During handling of the above exception, another exception occurred:

Traceback (most recent call last):
  File "c:\Users\idanh\Desktop\Cyber\My Projects\Final-Project\Main\client\modules\protocol.py", line 589, in connect_server
    sock.connect((self.ip, self.port))
ConnectionRefusedError: [WinError 10061] No connection could be made because the target machine actively refused it

During handling of the above exception, another exception occurred:

Traceback (most recent call last):
  File "c:\Users\idanh\Desktop\Cyber\My Projects\Final-Project\Main\client\modules\protocol.py", line 589, in connect_server
    sock.connect((self.ip, self.port))
ConnectionRefusedError: [WinError 10061] No connection could be made because the target machine actively refused it

During handling of the above exception, another exception occurred:

Traceback (most recent call last):
  File "c:\Users\idanh\Desktop\Cyber\My Projects\Final-Project\Main\client\modules\protocol.py", line 589, in connect_server
    sock.connect((self.ip, self.port))
ConnectionRefusedError: [WinError 10061] No connection could be made because the target machine actively refused it

During handling of the above exception, another exception occurred:

Traceback (most recent call last):
  File "c:\Users\idanh\Desktop\Cyber\My Projects\Final-Project\Main\client\modules\protocol.py", line 589, in connect_server
    sock.connect((self.ip, self.port))
ConnectionRefusedError: [WinError 10061] No connection could be made because the target machine actively refused it

During handling of the above exception, another exception occurred:

Traceback (most recent call last):
  File "c:\Users\idanh\Desktop\Cyber\My Projects\Final-Project\Main\client\modules\protocol.py", line 589, in connect_server
    sock.connect((self.ip, self.port))
ConnectionRefusedError: [WinError 10061] No connection could be made because the target machine actively refused it

During handling of the above exception, another exception occurred:

Traceback (most recent call last):
  File "c:\Users\idanh\Desktop\Cyber\My Projects\Final-Project\Main\client\modules\protocol.py", line 589, in connect_server
    sock.connect((self.ip, self.port))
ConnectionRefusedError: [WinError 10061] No connection could be made because the target machine actively refused it

During handling of the above exception, another exception occurred:

Traceback (most recent call last):
  File "c:\Users\idanh\Desktop\Cyber\My Projects\Final-Project\Main\client\modules\protocol.py", line 589, in connect_server
    sock.connect((self.ip, self.port))
ConnectionRefusedError: [WinError 10061] No connection could be made because the target machine actively refused it

During handling of the above exception, another exception occurred:

Traceback (most recent call last):
  File "c:\Users\idanh\Desktop\Cyber\My Projects\Final-Project\Main\client\modules\protocol.py", line 589, in connect_server
    sock.connect((self.ip, self.port))
ConnectionRefusedError: [WinError 10061] No connection could be made because the target machine actively refused it

During handling of the above exception, another exception occurred:

Traceback (most recent call last):
  File "c:\Users\idanh\Desktop\Cyber\My Projects\Final-Project\Main\client\modules\protocol.py", line 589, in connect_server
    sock.connect((self.ip, self.port))
ConnectionRefusedError: [WinError 10061] No connection could be made because the target machine actively refused it

During handling of the above exception, another exception occurred:

Traceback (most recent call last):
  File "c:\Users\idanh\Desktop\Cyber\My Projects\Final-Project\Main\client\modules\protocol.py", line 589, in connect_server
    sock.connect((self.ip, self.port))
ConnectionRefusedError: [WinError 10061] No connection could be made because the target machine actively refused it

During handling of the above exception, another exception occurred:

Traceback (most recent call last):
  File "c:\Users\idanh\Desktop\Cyber\My Projects\Final-Project\Main\client\modules\protocol.py", line 589, in connect_server
    sock.connect((self.ip, self.port))
ConnectionRefusedError: [WinError 10061] No connection could be made because the target machine actively refused it
2025-01-22 11:23:04 - No server found
2025-01-22 11:23:11 - No server found
2025-01-22 11:23:13 - Traceback (most recent call last):
  File "c:\Users\idanh\Desktop\Cyber\My Projects\Final-Project\Main\client\modules\protocol.py", line 589, in connect_server
    sock.connect((self.ip, self.port))
ConnectionRefusedError: [WinError 10061] No connection could be made because the target machine actively refused it
2025-01-22 11:23:16 - No server found
2025-01-22 11:23:18 - Traceback (most recent call last):
  File "c:\Users\idanh\Desktop\Cyber\My Projects\Final-Project\Main\client\modules\protocol.py", line 589, in connect_server
    sock.connect((self.ip, self.port))
ConnectionRefusedError: [WinError 10061] No connection could be made because the target machine actively refused it

During handling of the above exception, another exception occurred:

Traceback (most recent call last):
  File "c:\Users\idanh\Desktop\Cyber\My Projects\Final-Project\Main\client\modules\protocol.py", line 589, in connect_server
    sock.connect((self.ip, self.port))
ConnectionRefusedError: [WinError 10061] No connection could be made because the target machine actively refused it
2025-01-22 11:23:28 - No server found
2025-01-22 11:23:30 - Traceback (most recent call last):
  File "c:\Users\idanh\Desktop\Cyber\My Projects\Final-Project\Main\client\modules\protocol.py", line 589, in connect_server
    sock.connect((self.ip, self.port))
ConnectionRefusedError: [WinError 10061] No connection could be made because the target machine actively refused it
2025-01-22 11:23:35 - No server found
2025-01-22 11:23:37 - Traceback (most recent call last):
  File "c:\Users\idanh\Desktop\Cyber\My Projects\Final-Project\Main\client\modules\protocol.py", line 589, in connect_server
    sock.connect((self.ip, self.port))
ConnectionRefusedError: [WinError 10061] No connection could be made because the target machine actively refused it
2025-01-22 11:23:40 - No server found
2025-01-22 11:23:42 - Traceback (most recent call last):
  File "c:\Users\idanh\Desktop\Cyber\My Projects\Final-Project\Main\client\modules\protocol.py", line 589, in connect_server
    sock.connect((self.ip, self.port))
ConnectionRefusedError: [WinError 10061] No connection could be made because the target machine actively refused it

During handling of the above exception, another exception occurred:

Traceback (most recent call last):
  File "c:\Users\idanh\Desktop\Cyber\My Projects\Final-Project\Main\client\modules\protocol.py", line 589, in connect_server
    sock.connect((self.ip, self.port))
ConnectionRefusedError: [WinError 10061] No connection could be made because the target machine actively refused it
2025-01-22 11:23:56 - No server found
2025-01-22 11:23:58 - Traceback (most recent call last):
  File "c:\Users\idanh\Desktop\Cyber\My Projects\Final-Project\Main\client\modules\protocol.py", line 589, in connect_server
    sock.connect((self.ip, self.port))
ConnectionRefusedError: [WinError 10061] No connection could be made because the target machine actively refused it
2025-01-22 11:24:00 - Traceback (most recent call last):
  File "c:\Users\idanh\Desktop\Cyber\My Projects\Final-Project\Main\client\modules\protocol.py", line 589, in connect_server
    sock.connect((self.ip, self.port))
ConnectionRefusedError: [WinError 10061] No connection could be made because the target machine actively refused it

During handling of the above exception, another exception occurred:

Traceback (most recent call last):
  File "c:\Users\idanh\Desktop\Cyber\My Projects\Final-Project\Main\client\modules\protocol.py", line 589, in connect_server
    sock.connect((self.ip, self.port))
ConnectionRefusedError: [WinError 10061] No connection could be made because the target machine actively refused it
2025-01-22 11:24:25 - Traceback (most recent call last):
  File "c:\Users\idanh\Desktop\Cyber\My Projects\Final-Project\Main\client\modules\protocol.py", line 589, in connect_server
    sock.connect((self.ip, self.port))
ConnectionRefusedError: [WinError 10061] No connection could be made because the target machine actively refused it
2025-01-22 11:24:27 - Traceback (most recent call last):
  File "c:\Users\idanh\Desktop\Cyber\My Projects\Final-Project\Main\client\modules\protocol.py", line 589, in connect_server
    sock.connect((self.ip, self.port))
ConnectionRefusedError: [WinError 10061] No connection could be made because the target machine actively refused it

During handling of the above exception, another exception occurred:

Traceback (most recent call last):
  File "c:\Users\idanh\Desktop\Cyber\My Projects\Final-Project\Main\client\modules\protocol.py", line 589, in connect_server
    sock.connect((self.ip, self.port))
ConnectionRefusedError: [WinError 10061] No connection could be made because the target machine actively refused it
2025-01-22 11:26:51 - Server return an error: 024 Cookie is invalid
2025-01-22 11:27:06 - No server found
2025-01-22 11:27:08 - Traceback (most recent call last):
  File "c:\Users\idanh\Desktop\Cyber\My Projects\Final-Project\Main\client\modules\protocol.py", line 589, in connect_server
    sock.connect((self.ip, self.port))
ConnectionRefusedError: [WinError 10061] No connection could be made because the target machine actively refused it
2025-01-22 11:27:15 - Server return an error: 024 Cookie is invalid
2025-01-22 11:33:04 - Server return an error: 024 Cookie is invalid
2025-01-22 11:33:08 - Login was succesfull for user: a
2025-01-22 11:33:08 - File data recieved 0
2025-01-22 11:33:08 - Profile picture was recieved
2025-01-22 11:33:08 - Got files
2025-01-22 11:33:08 - Current used storage is 59.997
2025-01-22 11:33:08 - Got directories
2025-01-22 11:34:03 - Server return an error: 024 Cookie is invalid
2025-01-22 11:34:08 - Login was succesfull for user: a
2025-01-22 11:34:08 - File data recieved 0
2025-01-22 11:34:08 - Profile picture was recieved
2025-01-22 11:34:08 - Current used storage is 59.997
2025-01-22 11:34:08 - Cookie recieved
2025-01-22 11:34:08 - Got files
2025-01-22 11:34:08 - Got directories
2025-01-22 11:34:10 - Succesfully moved to
2025-01-22 11:34:10 - Got files
2025-01-22 11:34:10 - Got directories
2025-01-22 11:34:10 - Current used storage is 59.997
2025-01-22 11:34:12 - Succesfully moved to
2025-01-22 11:34:12 - Got files
2025-01-22 11:34:12 - Current used storage is 59.997
2025-01-22 11:34:12 - Got directories
2025-01-22 11:34:14 - Current used storage is 59.997
2025-01-22 11:34:14 - Got files
2025-01-22 11:34:14 - Got directories
2025-01-22 11:34:20 - Succesfully deleted 1 files
2025-01-22 11:34:20 - File IdanCloud.exe was deleted!
2025-01-22 11:34:20 - Current used storage is 59.997
2025-01-22 11:34:20 - Got files
2025-01-22 11:34:20 - Got directories
2025-01-22 11:34:26 - Current used storage is 59.997
2025-01-22 11:34:26 - Got files
2025-01-22 11:34:27 - Got directories
2025-01-22 11:34:30 - Got files
2025-01-22 11:34:30 - Current used storage is 59.997
2025-01-22 11:34:31 - Got directories
2025-01-22 11:34:32 - Current used storage is 59.997
2025-01-22 11:34:32 - Got files
2025-01-22 11:34:32 - Got directories
2025-01-22 11:34:36 - Got files
2025-01-22 11:34:36 - Current used storage is 59.997
2025-01-22 11:34:36 - Got directories
2025-01-22 11:39:02 - Server return an error: 024 Cookie is invalid
2025-01-22 11:39:46 - Login was succesfull for user: a
2025-01-22 11:39:46 - File data recieved 0
2025-01-22 11:39:46 - Profile picture was recieved
2025-01-22 11:39:46 - Current used storage is 59.997
2025-01-22 11:39:46 - Cookie recieved
2025-01-22 11:39:46 - Got files
2025-01-22 11:39:47 - Got directories
2025-01-22 11:39:52 - Current used storage is 59.997
2025-01-22 11:39:53 - Current used storage is 59.997
2025-01-22 11:39:53 - Got directories
2025-01-22 11:39:53 - Got files
2025-01-22 11:39:58 - start upload:
2025-01-22 11:39:58 - df6b3fd39a30485a852e299e7e679d70
2025-01-22 11:39:58 - Server return an error: 020 File exceeded max size of 50 MB
2025-01-22 11:39:59 - Unhandled exception:
Traceback (most recent call last):
  File "c:\Users\idanh\Desktop\Cyber\My Projects\Final-Project\Main\client\modules\gui.py", line 771, in stop_upload
    if self.active_threads != []:
       ^^^^^^^^^^^^^^^^^^^
AttributeError: 'MainWindow' object has no attribute 'active_threads'. Did you mean: 'receive_thread'?
2025-01-22 11:39:59 - Got files
2025-01-22 11:39:59 - Current used storage is 59.997
2025-01-22 11:39:59 - Got directories
2025-01-22 11:40:03 - Traceback (most recent call last):
  File "c:\Users\idanh\Desktop\Cyber\My Projects\Final-Project\Main\client\modules\protocol.py", line 302, in protocol_parse_reply
    file_id = fields[3]
              ~~~~~~^^^
IndexError: list index out of range
2025-01-22 11:40:03 - Server return an error: 014 File not found
2025-01-22 11:40:03 - Traceback (most recent call last):
  File "c:\Users\idanh\Desktop\Cyber\My Projects\Final-Project\Main\client\modules\protocol.py", line 302, in protocol_parse_reply
    file_id = fields[3]
              ~~~~~~^^^
IndexError: list index out of range
2025-01-22 11:40:03 - Server return an error: 014 File not found
2025-01-22 11:40:03 - Traceback (most recent call last):
  File "c:\Users\idanh\Desktop\Cyber\My Projects\Final-Project\Main\client\modules\protocol.py", line 302, in protocol_parse_reply
    file_id = fields[3]
              ~~~~~~^^^
IndexError: list index out of range
2025-01-22 11:40:03 - Server return an error: 014 File not found
2025-01-22 11:40:03 - Traceback (most recent call last):
  File "c:\Users\idanh\Desktop\Cyber\My Projects\Final-Project\Main\client\modules\protocol.py", line 302, in protocol_parse_reply
    file_id = fields[3]
              ~~~~~~^^^
IndexError: list index out of range
2025-01-22 11:40:03 - Server return an error: 014 File not found
2025-01-22 11:40:03 - Traceback (most recent call last):
  File "c:\Users\idanh\Desktop\Cyber\My Projects\Final-Project\Main\client\modules\protocol.py", line 302, in protocol_parse_reply
    file_id = fields[3]
              ~~~~~~^^^
IndexError: list index out of range
2025-01-22 11:40:03 - Server return an error: 014 File not found
2025-01-22 11:40:03 - Traceback (most recent call last):
  File "c:\Users\idanh\Desktop\Cyber\My Projects\Final-Project\Main\client\modules\protocol.py", line 302, in protocol_parse_reply
    file_id = fields[3]
              ~~~~~~^^^
IndexError: list index out of range
2025-01-22 11:40:03 - Server return an error: 014 File not found
2025-01-22 11:40:03 - Traceback (most recent call last):
  File "c:\Users\idanh\Desktop\Cyber\My Projects\Final-Project\Main\client\modules\protocol.py", line 302, in protocol_parse_reply
    file_id = fields[3]
              ~~~~~~^^^
IndexError: list index out of range
2025-01-22 11:40:03 - Server return an error: 014 File not found
2025-01-22 11:40:03 - Traceback (most recent call last):
  File "c:\Users\idanh\Desktop\Cyber\My Projects\Final-Project\Main\client\modules\protocol.py", line 302, in protocol_parse_reply
    file_id = fields[3]
              ~~~~~~^^^
IndexError: list index out of range
2025-01-22 11:40:03 - Server return an error: 014 File not found
2025-01-22 11:40:43 - Current used storage is 59.997
2025-01-22 11:40:43 - Got files
2025-01-22 11:40:43 - Got directories
2025-01-22 11:40:47 - File data recieved 0
2025-01-22 11:40:48 - File data recieved 524288
2025-01-22 11:40:48 - File data recieved 1048576
2025-01-22 11:40:48 - File data recieved 1572864
2025-01-22 11:40:48 - File data recieved 2097152
2025-01-22 11:40:49 - File data recieved 2621440
2025-01-22 11:40:49 - File data recieved 3145728
2025-01-22 11:40:49 - File data recieved 3670016
2025-01-22 11:40:49 - File data recieved 4194304
2025-01-22 11:40:49 - File data recieved 4718592
2025-01-22 11:40:50 - File data recieved 5242880
2025-01-22 11:40:50 - File data recieved 5767168
2025-01-22 11:40:50 - File data recieved 6291456
2025-01-22 11:40:50 - File data recieved 6815744
2025-01-22 11:40:50 - File data recieved 7340032
2025-01-22 11:40:51 - File data recieved 7864320
2025-01-22 11:40:51 - File data recieved 8388608
2025-01-22 11:40:52 - File data recieved 8912896
2025-01-22 11:40:52 - File data recieved 9437184
2025-01-22 11:40:53 - File data recieved 9961472
2025-01-22 11:40:53 - File data recieved 10485760
2025-01-22 11:40:53 - File data recieved 11010048
2025-01-22 11:40:53 - File data recieved 11534336
2025-01-22 11:40:54 - File data recieved 12058624
2025-01-22 11:40:54 - File data recieved 12582912
2025-01-22 11:40:54 - File data recieved 13107200
2025-01-22 11:40:54 - File data recieved 13631488
2025-01-22 11:40:55 - File data recieved 14155776
2025-01-22 11:40:55 - File data recieved 14680064
2025-01-22 11:40:55 - File data recieved 15204352
2025-01-22 11:40:55 - File data recieved 15728640
2025-01-22 11:40:56 - File data recieved 16252928
2025-01-22 11:40:56 - File data recieved 16777216
2025-01-22 11:40:56 - File data recieved 17301504
2025-01-22 11:40:56 - File data recieved 17825792
2025-01-22 11:40:57 - File data recieved 18350080
2025-01-22 11:40:57 - File data recieved 18874368
2025-01-22 11:40:57 - File data recieved 19398656
2025-01-22 11:40:57 - File data recieved 19922944
2025-01-22 11:40:58 - File data recieved 20447232
2025-01-22 11:40:58 - File data recieved 20971520
2025-01-22 11:40:58 - File data recieved 21495808
2025-01-22 11:40:58 - File data recieved 22020096
2025-01-22 11:40:59 - File data recieved 22544384
2025-01-22 11:40:59 - File data recieved 23068672
2025-01-22 11:40:59 - File data recieved 23592960
2025-01-22 11:41:00 - File data recieved 24117248
2025-01-22 11:41:00 - File data recieved 24641536
2025-01-22 11:41:00 - File data recieved 25165824
2025-01-22 11:41:00 - File data recieved 25690112
2025-01-22 11:41:01 - File data recieved 26214400
2025-01-22 11:41:01 - File data recieved 26738688
2025-01-22 11:41:01 - File data recieved 27262976
2025-01-22 11:41:01 - File data recieved 27787264
2025-01-22 11:41:02 - File data recieved 28311552
2025-01-22 11:41:02 - File data recieved 28835840
2025-01-22 11:41:03 - File data recieved 29360128
2025-01-22 11:41:03 - File data recieved 29884416
2025-01-22 11:41:04 - File data recieved 30408704
2025-01-22 11:41:04 - File data recieved 30932992
2025-01-22 11:41:05 - File data recieved 31457280
2025-01-22 11:41:05 - File data recieved 31981568
2025-01-22 11:41:05 - File data recieved 32505856
2025-01-22 11:41:06 - File data recieved 33030144
2025-01-22 11:41:06 - File data recieved 33554432
2025-01-22 11:41:07 - File data recieved 34078720
2025-01-22 11:41:07 - File data recieved 34603008
2025-01-22 11:41:08 - File data recieved 35127296
2025-01-22 11:41:08 - File data recieved 35651584
2025-01-22 11:41:09 - File data recieved 36175872
2025-01-22 11:41:09 - File data recieved 36700160
2025-01-22 11:41:10 - File data recieved 37224448
2025-01-22 11:41:10 - File data recieved 37748736
2025-01-22 11:41:11 - File data recieved 38273024
2025-01-22 11:41:11 - File data recieved 38797312
2025-01-22 11:41:11 - File data recieved 39321600
2025-01-22 11:41:12 - File data recieved 39845888
2025-01-22 11:41:12 - File data recieved 40370176
2025-01-22 11:41:13 - File data recieved 40894464
2025-01-22 11:41:13 - File data recieved 41418752
2025-01-22 11:41:14 - File data recieved 41943040
2025-01-22 11:41:14 - File data recieved 42467328
2025-01-22 11:41:15 - File data recieved 42991616
2025-01-22 11:41:15 - File data recieved 43515904
2025-01-22 11:41:15 - File data recieved 44040192
2025-01-22 11:41:16 - File data recieved 44564480
2025-01-22 11:41:16 - File IdanCloud.exe was downloaded
2025-01-22 11:41:26 - File data recieved 0
2025-01-22 11:41:26 - File data recieved 524288
2025-01-22 11:41:26 - File data recieved 1048576
2025-01-22 11:41:27 - File data recieved 1572864
2025-01-22 11:41:27 - File data recieved 2097152
2025-01-22 11:41:27 - File data recieved 2621440
2025-01-22 11:41:28 - File data recieved 3145728
2025-01-22 11:41:28 - File data recieved 3670016
2025-01-22 11:41:28 - File data recieved 4194304
2025-01-22 11:41:29 - File data recieved 4718592
2025-01-22 11:41:29 - File data recieved 5242880
2025-01-22 11:41:29 - File data recieved 5767168
2025-01-22 11:41:29 - File data recieved 6291456
2025-01-22 11:41:30 - File data recieved 6815744
2025-01-22 11:41:30 - File data recieved 7340032
2025-01-22 11:41:30 - File data recieved 7864320
2025-01-22 11:41:30 - File data recieved 8388608
2025-01-22 11:41:31 - File data recieved 8912896
2025-01-22 11:41:31 - File data recieved 9437184
2025-01-22 11:41:31 - File data recieved 9961472
2025-01-22 11:41:31 - File data recieved 10485760
2025-01-22 11:41:32 - File data recieved 11010048
2025-01-22 11:41:32 - File data recieved 11534336
2025-01-22 11:41:33 - File data recieved 12058624
2025-01-22 11:41:33 - File data recieved 12582912
2025-01-22 11:41:34 - File data recieved 13107200
2025-01-22 11:41:34 - File data recieved 13631488
2025-01-22 11:41:35 - File data recieved 14155776
2025-01-22 11:41:35 - File data recieved 14680064
2025-01-22 11:41:36 - File data recieved 15204352
2025-01-22 11:41:36 - File data recieved 15728640
2025-01-22 11:41:37 - File data recieved 16252928
2025-01-22 11:41:37 - File data recieved 16777216
2025-01-22 11:41:37 - File data recieved 17301504
2025-01-22 11:41:38 - File data recieved 17825792
2025-01-22 11:41:38 - File data recieved 18350080
2025-01-22 11:41:38 - File data recieved 18874368
2025-01-22 11:41:39 - File data recieved 19398656
2025-01-22 11:41:39 - File data recieved 19922944
2025-01-22 11:41:39 - File data recieved 20447232
2025-01-22 11:41:39 - File data recieved 20971520
2025-01-22 11:41:40 - File data recieved 21495808
2025-01-22 11:41:40 - File data recieved 22020096
2025-01-22 11:41:40 - File data recieved 22544384
2025-01-22 11:41:40 - File data recieved 23068672
2025-01-22 11:41:41 - File data recieved 23592960
2025-01-22 11:41:41 - File data recieved 24117248
2025-01-22 11:41:42 - File data recieved 24641536
2025-01-22 11:41:42 - File data recieved 25165824
2025-01-22 11:41:42 - File data recieved 25690112
2025-01-22 11:41:43 - File data recieved 26214400
2025-01-22 11:41:43 - File data recieved 26738688
2025-01-22 11:41:44 - File data recieved 27262976
2025-01-22 11:41:44 - File data recieved 27787264
2025-01-22 11:41:45 - File data recieved 28311552
2025-01-22 11:41:45 - File data recieved 28835840
2025-01-22 11:41:46 - File data recieved 29360128
2025-01-22 11:41:46 - File data recieved 29884416
2025-01-22 11:41:47 - File data recieved 30408704
2025-01-22 11:41:47 - File data recieved 30932992
2025-01-22 11:41:48 - File data recieved 31457280
2025-01-22 11:41:48 - File data recieved 31981568
2025-01-22 11:41:48 - File data recieved 32505856
2025-01-22 11:41:49 - File data recieved 33030144
2025-01-22 11:41:49 - File data recieved 33554432
2025-01-22 11:41:50 - File data recieved 34078720
2025-01-22 11:41:50 - File data recieved 34603008
2025-01-22 11:41:51 - File data recieved 35127296
2025-01-22 11:41:51 - File data recieved 35651584
2025-01-22 11:41:52 - File data recieved 36175872
2025-01-22 11:41:52 - File data recieved 36700160
2025-01-22 11:41:52 - File data recieved 37224448
2025-01-22 11:41:53 - File data recieved 37748736
2025-01-22 11:41:53 - File data recieved 38273024
2025-01-22 11:41:54 - File data recieved 38797312
2025-01-22 11:41:54 - File data recieved 39321600
2025-01-22 11:41:55 - File data recieved 39845888
2025-01-22 11:41:55 - File data recieved 40370176
2025-01-22 11:41:55 - File data recieved 40894464
2025-01-22 11:41:56 - File data recieved 41418752
2025-01-22 11:41:56 - File data recieved 41943040
2025-01-22 11:41:57 - File data recieved 42467328
2025-01-22 11:41:57 - File data recieved 42991616
2025-01-22 11:41:58 - File data recieved 43515904
2025-01-22 11:41:58 - File data recieved 44040192
2025-01-22 11:41:59 - File data recieved 44564480
2025-01-22 11:41:59 - File IdanCloud.exe was downloaded
2025-01-22 11:42:13 - start upload:
2025-01-22 11:42:13 - e4abb60f4e66416ab4790f8965663655
2025-01-22 11:42:13 - Server return an error: 020 File exceeded max size of 50 MB
2025-01-22 11:42:14 - start upload:
2025-01-22 11:42:14 - 8d5ddb432c8f482ca193f8cb3ec2b7c4
2025-01-22 11:42:14 - File IdanCloud.exe started uploading
2025-01-22 11:42:14 - Unhandled exception:
Traceback (most recent call last):
  File "c:\Users\idanh\Desktop\Cyber\My Projects\Final-Project\Main\client\modules\gui.py", line 771, in stop_upload
    if self.file_sending.active_threads != []:
       ^^^^^^^^^^^^^^^^^^^
AttributeError: 'MainWindow' object has no attribute 'active_threads'. Did you mean: 'receive_thread'?
2025-01-22 11:42:18 - Traceback (most recent call last):
  File "c:\Users\idanh\Desktop\Cyber\My Projects\Final-Project\Main\client\modules\protocol.py", line 302, in protocol_parse_reply
    file_id = fields[3]
              ~~~~~~^^^
IndexError: list index out of range
2025-01-22 11:42:18 - Server return an error: 014 File not found
2025-01-22 11:42:18 - Traceback (most recent call last):
  File "c:\Users\idanh\Desktop\Cyber\My Projects\Final-Project\Main\client\modules\protocol.py", line 302, in protocol_parse_reply
    file_id = fields[3]
              ~~~~~~^^^
IndexError: list index out of range
2025-01-22 11:42:18 - Server return an error: 014 File not found
2025-01-22 11:42:18 - Traceback (most recent call last):
  File "c:\Users\idanh\Desktop\Cyber\My Projects\Final-Project\Main\client\modules\protocol.py", line 302, in protocol_parse_reply
    file_id = fields[3]
              ~~~~~~^^^
IndexError: list index out of range
2025-01-22 11:42:18 - Server return an error: 014 File not found
2025-01-22 11:42:18 - Traceback (most recent call last):
  File "c:\Users\idanh\Desktop\Cyber\My Projects\Final-Project\Main\client\modules\protocol.py", line 302, in protocol_parse_reply
    file_id = fields[3]
              ~~~~~~^^^
IndexError: list index out of range
2025-01-22 11:42:18 - Server return an error: 014 File not found
2025-01-22 11:42:18 - Traceback (most recent call last):
  File "c:\Users\idanh\Desktop\Cyber\My Projects\Final-Project\Main\client\modules\protocol.py", line 302, in protocol_parse_reply
    file_id = fields[3]
              ~~~~~~^^^
IndexError: list index out of range
2025-01-22 11:42:18 - Server return an error: 014 File not found
2025-01-22 11:42:18 - Traceback (most recent call last):
  File "c:\Users\idanh\Desktop\Cyber\My Projects\Final-Project\Main\client\modules\protocol.py", line 302, in protocol_parse_reply
    file_id = fields[3]
              ~~~~~~^^^
IndexError: list index out of range
2025-01-22 11:42:18 - Server return an error: 014 File not found
2025-01-22 11:42:18 - Traceback (most recent call last):
  File "c:\Users\idanh\Desktop\Cyber\My Projects\Final-Project\Main\client\modules\protocol.py", line 302, in protocol_parse_reply
    file_id = fields[3]
              ~~~~~~^^^
IndexError: list index out of range
2025-01-22 11:42:18 - Server return an error: 014 File not found
2025-01-22 11:42:18 - Traceback (most recent call last):
  File "c:\Users\idanh\Desktop\Cyber\My Projects\Final-Project\Main\client\modules\protocol.py", line 302, in protocol_parse_reply
    file_id = fields[3]
              ~~~~~~^^^
IndexError: list index out of range
2025-01-22 11:42:18 - Server return an error: 014 File not found
2025-01-22 11:42:24 - Got files
2025-01-22 11:42:24 - Current used storage is 59.997
2025-01-22 11:42:25 - Got directories
2025-01-22 11:42:38 - File IdanCloud.exe was uploaded
2025-01-22 11:42:38 - Current used storage is 105.006
2025-01-22 11:42:38 - Got files
2025-01-22 11:42:38 - Got directories
2025-01-22 11:44:16 - start upload:
2025-01-22 11:44:16 - f079a18276fc41f0a3f87dea6129ca3b
2025-01-22 11:44:16 - Server return an error: 020 File exceeded max size of 50 MB
2025-01-22 11:44:17 - start upload:
2025-01-22 11:44:17 - aaa4cbcd49dd4833a1f70cdfa80ab78e
2025-01-22 11:44:17 - File IdanCloud.exe started uploading
2025-01-22 11:44:18 - Unhandled exception:
Traceback (most recent call last):
  File "c:\Users\idanh\Desktop\Cyber\My Projects\Final-Project\Main\client\modules\gui.py", line 771, in stop_upload
    if self.file_sending.active_threads != []:
       ^^^^^^^^^^^^^^^^^^^
AttributeError: 'MainWindow' object has no attribute 'active_threads'. Did you mean: 'receive_thread'?
2025-01-22 11:44:21 - Traceback (most recent call last):
  File "c:\Users\idanh\Desktop\Cyber\My Projects\Final-Project\Main\client\modules\protocol.py", line 302, in protocol_parse_reply
    file_id = fields[3]
              ~~~~~~^^^
IndexError: list index out of range
2025-01-22 11:44:21 - Server return an error: 014 File not found
2025-01-22 11:44:21 - Traceback (most recent call last):
  File "c:\Users\idanh\Desktop\Cyber\My Projects\Final-Project\Main\client\modules\protocol.py", line 302, in protocol_parse_reply
    file_id = fields[3]
              ~~~~~~^^^
IndexError: list index out of range
2025-01-22 11:44:21 - Server return an error: 014 File not found
2025-01-22 11:44:21 - Traceback (most recent call last):
  File "c:\Users\idanh\Desktop\Cyber\My Projects\Final-Project\Main\client\modules\protocol.py", line 302, in protocol_parse_reply
    file_id = fields[3]
              ~~~~~~^^^
IndexError: list index out of range
2025-01-22 11:44:21 - Server return an error: 014 File not found
2025-01-22 11:44:21 - Traceback (most recent call last):
  File "c:\Users\idanh\Desktop\Cyber\My Projects\Final-Project\Main\client\modules\protocol.py", line 302, in protocol_parse_reply
    file_id = fields[3]
              ~~~~~~^^^
IndexError: list index out of range
2025-01-22 11:44:21 - Server return an error: 014 File not found
2025-01-22 11:44:21 - Traceback (most recent call last):
  File "c:\Users\idanh\Desktop\Cyber\My Projects\Final-Project\Main\client\modules\protocol.py", line 302, in protocol_parse_reply
    file_id = fields[3]
              ~~~~~~^^^
IndexError: list index out of range
2025-01-22 11:44:21 - Server return an error: 014 File not found
2025-01-22 11:44:21 - Traceback (most recent call last):
  File "c:\Users\idanh\Desktop\Cyber\My Projects\Final-Project\Main\client\modules\protocol.py", line 302, in protocol_parse_reply
    file_id = fields[3]
              ~~~~~~^^^
IndexError: list index out of range
2025-01-22 11:44:21 - Server return an error: 014 File not found
2025-01-22 11:44:21 - Traceback (most recent call last):
  File "c:\Users\idanh\Desktop\Cyber\My Projects\Final-Project\Main\client\modules\protocol.py", line 302, in protocol_parse_reply
    file_id = fields[3]
              ~~~~~~^^^
IndexError: list index out of range
2025-01-22 11:44:21 - Server return an error: 014 File not found
2025-01-22 11:44:21 - Traceback (most recent call last):
  File "c:\Users\idanh\Desktop\Cyber\My Projects\Final-Project\Main\client\modules\protocol.py", line 302, in protocol_parse_reply
    file_id = fields[3]
              ~~~~~~^^^
IndexError: list index out of range
2025-01-22 11:44:21 - Server return an error: 014 File not found
2025-01-22 11:44:27 - start upload:
2025-01-22 11:44:27 - 760c4b96d9884366a97f19f36b19a2a3
2025-01-22 11:44:27 - File IdanCloud.exe started uploading
2025-01-22 11:44:30 - File IdanCloud.exe was uploaded
2025-01-22 11:44:30 - Current used storage is 150.016
2025-01-22 11:44:30 - Got files
2025-01-22 11:44:30 - Got directories
2025-01-22 11:44:37 - Got files
2025-01-22 11:44:37 - Current used storage is 150.016
2025-01-22 11:44:37 - Got directories
2025-01-22 11:44:45 - File IdanCloud.exe was uploaded
2025-01-22 11:44:45 - Got files
2025-01-22 11:44:45 - Current used storage is 195.025
2025-01-22 11:44:45 - Got directories
2025-01-22 11:44:58 - start upload:
2025-01-22 11:44:58 - 0ac80310a8ac41a0934609dc2c0e527d
2025-01-22 11:44:58 - Server return an error: 020 File exceeded max size of 50 MB
2025-01-22 11:44:59 - start upload:
2025-01-22 11:44:59 - 2cd9efff8fbd4237bfc998e5d5f47393
2025-01-22 11:44:59 - File IdanCloud.exe started uploading
2025-01-22 11:45:46 - Unhandled exception:
Traceback (most recent call last):
  File "c:\Users\idanh\Desktop\Cyber\My Projects\Final-Project\Main\client\modules\gui.py", line 771, in stop_upload
    if self.file_sending.active_threads != []:
       ^^^^^^^^^^^^^^^^^^^
AttributeError: 'MainWindow' object has no attribute 'active_threads'. Did you mean: 'receive_thread'?
2025-01-22 11:45:46 - Traceback (most recent call last):
  File "c:\Users\idanh\Desktop\Cyber\My Projects\Final-Project\Main\client\modules\protocol.py", line 302, in protocol_parse_reply
    file_id = fields[3]
              ~~~~~~^^^
IndexError: list index out of range
2025-01-22 11:45:46 - Server return an error: 014 File not found
2025-01-22 11:45:46 - Traceback (most recent call last):
  File "c:\Users\idanh\Desktop\Cyber\My Projects\Final-Project\Main\client\modules\protocol.py", line 302, in protocol_parse_reply
    file_id = fields[3]
              ~~~~~~^^^
IndexError: list index out of range
2025-01-22 11:45:46 - Server return an error: 014 File not found
2025-01-22 11:45:46 - Traceback (most recent call last):
  File "c:\Users\idanh\Desktop\Cyber\My Projects\Final-Project\Main\client\modules\protocol.py", line 302, in protocol_parse_reply
    file_id = fields[3]
              ~~~~~~^^^
IndexError: list index out of range
2025-01-22 11:45:46 - Server return an error: 014 File not found
2025-01-22 11:45:46 - Traceback (most recent call last):
  File "c:\Users\idanh\Desktop\Cyber\My Projects\Final-Project\Main\client\modules\protocol.py", line 302, in protocol_parse_reply
    file_id = fields[3]
              ~~~~~~^^^
IndexError: list index out of range
2025-01-22 11:45:46 - Server return an error: 014 File not found
2025-01-22 11:45:46 - Traceback (most recent call last):
  File "c:\Users\idanh\Desktop\Cyber\My Projects\Final-Project\Main\client\modules\protocol.py", line 302, in protocol_parse_reply
    file_id = fields[3]
              ~~~~~~^^^
IndexError: list index out of range
2025-01-22 11:45:46 - Server return an error: 014 File not found
2025-01-22 11:45:46 - Traceback (most recent call last):
  File "c:\Users\idanh\Desktop\Cyber\My Projects\Final-Project\Main\client\modules\protocol.py", line 302, in protocol_parse_reply
    file_id = fields[3]
              ~~~~~~^^^
IndexError: list index out of range
2025-01-22 11:45:46 - Server return an error: 014 File not found
2025-01-22 11:45:46 - Traceback (most recent call last):
  File "c:\Users\idanh\Desktop\Cyber\My Projects\Final-Project\Main\client\modules\protocol.py", line 302, in protocol_parse_reply
    file_id = fields[3]
              ~~~~~~^^^
IndexError: list index out of range
2025-01-22 11:45:46 - Server return an error: 014 File not found
2025-01-22 11:45:46 - Traceback (most recent call last):
  File "c:\Users\idanh\Desktop\Cyber\My Projects\Final-Project\Main\client\modules\protocol.py", line 302, in protocol_parse_reply
    file_id = fields[3]
              ~~~~~~^^^
IndexError: list index out of range
2025-01-22 11:45:46 - Server return an error: 014 File not found
2025-01-22 11:45:55 - start upload:
2025-01-22 11:45:55 - ab16740451354063a065edc05f9b01ab
2025-01-22 11:45:55 - File IdanCloud.exe started uploading
2025-01-22 11:46:05 - start upload:
2025-01-22 11:46:05 - db712dbb78694de8b095f94e924c05c7
2025-01-22 11:46:05 - File IdanCloud.exe started uploading
2025-01-22 11:46:07 - File IdanCloud.exe was uploaded
2025-01-22 11:46:07 - Got files
2025-01-22 11:46:08 - Current used storage is 240.034
2025-01-22 11:46:08 - Got directories
2025-01-22 11:46:11 - File IdanCloud.exe was uploaded
2025-01-22 11:46:11 - Got files
2025-01-22 11:46:11 - Got directories
2025-01-22 11:46:11 - Current used storage is 285.043
2025-01-22 11:46:16 - Got files
2025-01-22 11:46:16 - Current used storage is 285.043
2025-01-22 11:46:16 - Got directories
2025-01-22 11:46:19 - File IdanCloud.exe was uploaded
2025-01-22 11:46:19 - Current used storage is 330.053
2025-01-22 11:46:19 - Got files
2025-01-22 11:46:20 - Got directories
2025-01-22 11:46:55 - Login was succesfull for user: a
2025-01-22 11:46:55 - File data recieved 0
2025-01-22 11:46:55 - Profile picture was recieved
2025-01-22 11:46:56 - Got files
2025-01-22 11:46:56 - Current used storage is 330.053
2025-01-22 11:46:56 - Got directories
2025-01-22 11:47:03 - start upload:
2025-01-22 11:47:03 - 336ff790d4914a0c92d54fcc53735f5d
2025-01-22 11:47:03 - Server return an error: 020 File exceeded max size of 50 MB
2025-01-22 11:47:10 - Traceback (most recent call last):
  File "c:\Users\idanh\Desktop\Cyber\My Projects\Final-Project\Main\client\modules\protocol.py", line 302, in protocol_parse_reply
    file_id = fields[3]
              ~~~~~~^^^
IndexError: list index out of range
2025-01-22 11:47:10 - Server return an error: 014 File not found
2025-01-22 11:47:10 - Traceback (most recent call last):
  File "c:\Users\idanh\Desktop\Cyber\My Projects\Final-Project\Main\client\modules\protocol.py", line 302, in protocol_parse_reply
    file_id = fields[3]
              ~~~~~~^^^
IndexError: list index out of range
2025-01-22 11:47:10 - Server return an error: 014 File not found
2025-01-22 11:47:10 - Traceback (most recent call last):
  File "c:\Users\idanh\Desktop\Cyber\My Projects\Final-Project\Main\client\modules\protocol.py", line 302, in protocol_parse_reply
    file_id = fields[3]
              ~~~~~~^^^
IndexError: list index out of range
2025-01-22 11:47:10 - Server return an error: 014 File not found
2025-01-22 11:47:10 - Traceback (most recent call last):
  File "c:\Users\idanh\Desktop\Cyber\My Projects\Final-Project\Main\client\modules\protocol.py", line 302, in protocol_parse_reply
    file_id = fields[3]
              ~~~~~~^^^
IndexError: list index out of range
2025-01-22 11:47:10 - Server return an error: 014 File not found
2025-01-22 11:47:10 - Traceback (most recent call last):
  File "c:\Users\idanh\Desktop\Cyber\My Projects\Final-Project\Main\client\modules\protocol.py", line 302, in protocol_parse_reply
    file_id = fields[3]
              ~~~~~~^^^
IndexError: list index out of range
2025-01-22 11:47:10 - Server return an error: 014 File not found
2025-01-22 11:47:10 - Traceback (most recent call last):
  File "c:\Users\idanh\Desktop\Cyber\My Projects\Final-Project\Main\client\modules\protocol.py", line 302, in protocol_parse_reply
    file_id = fields[3]
              ~~~~~~^^^
IndexError: list index out of range
2025-01-22 11:47:10 - Server return an error: 014 File not found
2025-01-22 11:47:10 - Traceback (most recent call last):
  File "c:\Users\idanh\Desktop\Cyber\My Projects\Final-Project\Main\client\modules\protocol.py", line 302, in protocol_parse_reply
    file_id = fields[3]
              ~~~~~~^^^
IndexError: list index out of range
2025-01-22 11:47:10 - Server return an error: 014 File not found
2025-01-22 11:47:10 - Traceback (most recent call last):
  File "c:\Users\idanh\Desktop\Cyber\My Projects\Final-Project\Main\client\modules\protocol.py", line 302, in protocol_parse_reply
    file_id = fields[3]
              ~~~~~~^^^
IndexError: list index out of range
2025-01-22 11:47:10 - Server return an error: 014 File not found
2025-01-22 11:47:10 - Upload of None stopped
2025-01-22 11:47:10 - Current used storage is 330.053
2025-01-22 11:47:10 - Got files
2025-01-22 11:47:10 - Got directories
2025-01-22 11:47:34 - start upload:
2025-01-22 11:47:34 - 34ac1aece65348cea2649a87ea81a38f
2025-01-22 11:47:34 - Server return an error: 020 File exceeded max size of 50 MB
2025-01-22 11:47:35 - start upload:
2025-01-22 11:47:35 - 51fbe3e61e5b4376b9033cf9f3726598
2025-01-22 11:47:35 - Server return an error: 020 File exceeded max size of 50 MB
2025-01-22 11:47:36 - Current used storage is 330.053
2025-01-22 11:47:36 - Got files
2025-01-22 11:47:36 - Got directories
2025-01-22 11:49:51 - Login was succesfull for user: a
2025-01-22 11:49:51 - File data recieved 0
2025-01-22 11:49:51 - Profile picture was recieved
2025-01-22 11:49:51 - Current used storage is 330.053
2025-01-22 11:49:51 - Got files
2025-01-22 11:49:51 - Got directories
2025-01-22 11:50:03 - start upload:
2025-01-22 11:50:03 - a60f3f41837c4f198d97d06361bf7519
2025-01-22 11:50:03 - File catppuccin_22h2_by_niivu_df8rth3.zip started uploading
2025-01-22 11:50:04 - Upload of catppuccin_22h2_by_niivu_df8rth3.zip stopped
2025-01-22 11:50:05 - Current used storage is 330.053
2025-01-22 11:50:05 - Got files
2025-01-22 11:50:05 - Got directories
2025-01-22 11:50:08 - Current used storage is 330.053
2025-01-22 11:50:08 - Got files
2025-01-22 11:50:08 - Got directories
2025-01-22 11:50:10 - Current used storage is 330.053
2025-01-22 11:50:10 - Got files
2025-01-22 11:50:10 - Got directories
2025-01-22 11:50:15 - File data recieved 0
2025-01-22 11:50:16 - File data recieved 524288
2025-01-22 11:50:16 - File data recieved 1048576
2025-01-22 11:50:16 - File data recieved 1572864
2025-01-22 11:50:17 - File data recieved 2097152
2025-01-22 11:50:17 - File data recieved 2621440
2025-01-22 11:50:17 - File data recieved 3145728
2025-01-22 11:50:18 - File data recieved 3670016
2025-01-22 11:50:18 - File data recieved 4194304
2025-01-22 11:50:18 - File data recieved 4718592
2025-01-22 11:50:18 - File data recieved 5242880
2025-01-22 11:50:19 - File data recieved 5767168
2025-01-22 11:50:19 - File data recieved 6291456
2025-01-22 11:50:19 - File data recieved 6815744
2025-01-22 11:50:20 - File data recieved 7340032
2025-01-22 11:50:20 - File data recieved 7864320
2025-01-22 11:50:20 - File data recieved 8388608
2025-01-22 11:50:20 - File data recieved 8912896
2025-01-22 11:50:21 - File data recieved 9437184
2025-01-22 11:50:21 - File data recieved 9961472
2025-01-22 11:50:21 - File data recieved 10485760
2025-01-22 11:50:21 - File data recieved 11010048
2025-01-22 11:50:22 - File data recieved 11534336
2025-01-22 11:50:22 - File data recieved 12058624
2025-01-22 11:50:22 - File data recieved 12582912
2025-01-22 11:50:22 - File data recieved 13107200
2025-01-22 11:50:23 - File data recieved 13631488
2025-01-22 11:50:23 - File data recieved 14155776
2025-01-22 11:50:23 - File data recieved 14680064
2025-01-22 11:50:23 - File data recieved 15204352
2025-01-22 11:50:24 - File data recieved 15728640
2025-01-22 11:50:24 - File data recieved 16252928
2025-01-22 11:50:24 - File data recieved 16777216
2025-01-22 11:50:24 - File data recieved 17301504
2025-01-22 11:50:25 - File data recieved 17825792
2025-01-22 11:50:25 - File data recieved 18350080
2025-01-22 11:50:25 - File data recieved 18874368
2025-01-22 11:50:26 - File data recieved 19398656
2025-01-22 11:50:26 - File data recieved 19922944
2025-01-22 11:50:26 - File data recieved 20447232
2025-01-22 11:50:26 - File data recieved 20971520
2025-01-22 11:50:27 - File data recieved 21495808
2025-01-22 11:50:27 - File data recieved 22020096
2025-01-22 11:50:27 - File data recieved 22544384
2025-01-22 11:50:27 - File data recieved 23068672
2025-01-22 11:50:28 - File data recieved 23592960
2025-01-22 11:50:28 - File data recieved 24117248
2025-01-22 11:50:28 - File data recieved 24641536
2025-01-22 11:50:28 - File data recieved 25165824
2025-01-22 11:50:29 - File data recieved 25690112
2025-01-22 11:50:29 - File data recieved 26214400
2025-01-22 11:50:29 - File data recieved 26738688
2025-01-22 11:50:29 - File data recieved 27262976
2025-01-22 11:50:30 - File data recieved 27787264
2025-01-22 11:50:30 - File data recieved 28311552
2025-01-22 11:50:30 - File data recieved 28835840
2025-01-22 11:50:31 - File data recieved 29360128
2025-01-22 11:50:31 - File data recieved 29884416
2025-01-22 11:50:31 - File data recieved 30408704
2025-01-22 11:50:31 - File data recieved 30932992
2025-01-22 11:50:32 - File data recieved 31457280
2025-01-22 11:50:32 - File data recieved 31981568
2025-01-22 11:50:32 - File data recieved 32505856
2025-01-22 11:50:32 - File data recieved 33030144
2025-01-22 11:50:33 - File data recieved 33554432
2025-01-22 11:50:33 - File data recieved 34078720
2025-01-22 11:50:33 - File data recieved 34603008
2025-01-22 11:50:33 - File data recieved 35127296
2025-01-22 11:50:34 - File data recieved 35651584
2025-01-22 11:50:34 - File data recieved 36175872
2025-01-22 11:50:34 - File data recieved 36700160
2025-01-22 11:50:34 - File data recieved 37224448
2025-01-22 11:50:35 - File data recieved 37748736
2025-01-22 11:50:35 - File data recieved 38273024
2025-01-22 11:50:35 - File data recieved 38797312
2025-01-22 11:50:35 - File data recieved 39321600
2025-01-22 11:50:36 - File data recieved 39845888
2025-01-22 11:50:36 - File data recieved 40370176
2025-01-22 11:50:36 - File data recieved 40894464
2025-01-22 11:50:36 - File data recieved 41418752
2025-01-22 11:50:37 - File data recieved 41943040
2025-01-22 11:50:37 - File data recieved 42467328
2025-01-22 11:50:37 - File data recieved 42991616
2025-01-22 11:50:38 - File data recieved 43515904
2025-01-22 11:50:38 - File data recieved 44040192
2025-01-22 11:50:38 - File data recieved 44564480
2025-01-22 11:50:38 - File IdanCloud.exe was downloaded
2025-01-22 11:50:45 - Succesfully deleted 8 files
2025-01-22 11:50:45 - File IdanCloud.exe was deleted!
2025-01-22 11:50:45 - File IdanCloud.exe was deleted!
2025-01-22 11:50:45 - File IdanCloud.exe was deleted!
2025-01-22 11:50:45 - File English Recording.mp3 was deleted!
2025-01-22 11:50:45 - File IdanCloud.exe was deleted!
2025-01-22 11:50:45 - File IdanCloud.exe was deleted!
2025-01-22 11:50:45 - File IdanCloud.exe was deleted!
2025-01-22 11:50:45 - Current used storage is 330.053
2025-01-22 11:50:45 - File IdanCloud.exe was deleted!
2025-01-22 11:50:45 - Got files
2025-01-22 11:50:46 - Got directories
2025-01-22 11:50:46 - Succesfully moved to
2025-01-22 11:50:46 - Got directories
2025-01-22 11:50:46 - Got files
2025-01-22 11:50:46 - Current used storage is 330.053
2025-01-22 11:50:49 - Succesfully deleted 11 files
2025-01-22 11:50:49 - File IdanCloud.exe was deleted!
2025-01-22 11:50:49 - File IdanCloud.exe was deleted!
2025-01-22 11:50:49 - File app_log.txt was deleted!
2025-01-22 11:50:49 - File IdanCloud.exe was deleted!
2025-01-22 11:50:49 - File IdanCloud.exe was deleted!
2025-01-22 11:50:49 - File IdanCloud.exe was deleted!
2025-01-22 11:50:49 - File English Recording.mp3 was deleted!
2025-01-22 11:50:49 - Got directories
2025-01-22 11:50:49 - File important things.txt was deleted!
2025-01-22 11:50:49 - File app_log.txt was deleted!
2025-01-22 11:50:49 - Got files
2025-01-22 11:50:49 - File IdanCloud.exe was deleted!
2025-01-22 11:50:49 - File IdanCloud.exe was deleted!
2025-01-22 11:50:49 - Current used storage is 285.043
2025-01-22 11:50:51 - Succesfully moved to
2025-01-22 11:50:51 - Got files
2025-01-22 11:50:51 - Current used storage is 14.158
2025-01-22 11:50:51 - Got directories
2025-01-22 11:50:53 - Succesfully moved to
2025-01-22 11:50:53 - Got files
2025-01-22 11:50:53 - Got directories
2025-01-22 11:50:53 - Current used storage is 14.158
2025-01-22 11:50:54 - Succesfully moved to
2025-01-22 11:50:54 - Got files
2025-01-22 11:50:54 - Got directories
2025-01-22 11:50:54 - Current used storage is 14.158
2025-01-22 11:51:57 - Login was succesfull for user: a
2025-01-22 11:51:57 - File data recieved 0
2025-01-22 11:51:57 - Profile picture was recieved
2025-01-22 11:51:57 - Current used storage is 14.158
2025-01-22 11:51:57 - Got files
2025-01-22 11:51:57 - Got directories
2025-01-22 11:52:00 - start upload:
2025-01-22 11:52:00 - 280ab94082b349aaa0b4c92be3451819
2025-01-22 11:52:00 - File app_log.txt started uploading
2025-01-22 11:52:00 - Current used storage is 14.158
2025-01-22 11:52:00 - Got files
2025-01-22 11:52:00 - Got directories
2025-01-22 11:52:01 - File app_log.txt was uploaded
2025-01-22 11:52:01 - Got files
2025-01-22 11:52:01 - Got directories
2025-01-22 11:52:01 - Current used storage is 14.318
2025-01-22 11:52:06 - File data recieved 0
2025-01-22 11:52:06 - File \u05e9\u05d0\u05dc\u05d5\u05df \u05e2\u05d9\u05d3\u05df \u05d7\u05d6\u05d0\u05d9 330905159.docx was downloaded
2025-01-22 11:52:09 - Got files
2025-01-22 11:52:09 - Current used storage is 14.318
2025-01-22 11:52:09 - Got directories
2025-01-22 11:52:29 - Current used storage is 14.318
2025-01-22 11:52:29 - Got directories
2025-01-22 11:52:29 - Got files
2025-01-22 11:52:29 - Got files
2025-01-22 11:52:29 - Current used storage is 14.318
2025-01-22 11:52:29 - Got directories
2025-01-22 11:52:43 - File data recieved 0
2025-01-22 11:52:43 - File data recieved 524288
2025-01-22 11:52:43 - File data recieved 1048576
2025-01-22 11:52:43 - File data recieved 1572864
2025-01-22 11:52:43 - File data recieved 2097152
2025-01-22 11:52:43 - File data recieved 2621440
2025-01-22 11:52:43 - File data recieved 3145728
2025-01-22 11:52:43 - File data recieved 3670016
2025-01-22 11:52:43 - File data recieved 4194304
2025-01-22 11:52:43 - File data recieved 4718592
2025-01-22 11:52:43 - File data recieved 5242880
2025-01-22 11:52:43 - File data recieved 5767168
2025-01-22 11:52:43 - File data recieved 6291456
2025-01-22 11:52:43 - File data recieved 6815744
2025-01-22 11:52:43 - File data recieved 7340032
2025-01-22 11:52:43 - File data recieved 7864320
2025-01-22 11:52:43 - File data recieved 8388608
2025-01-22 11:52:43 - File data recieved 8912896
2025-01-22 11:52:43 - File data recieved 9437184
2025-01-22 11:52:43 - File data recieved 9961472
2025-01-22 11:52:44 - File data recieved 10485760
2025-01-22 11:52:44 - File data recieved 11010048
2025-01-22 11:52:44 - File data recieved 11534336
2025-01-22 11:52:44 - File data recieved 12058624
2025-01-22 11:52:44 - File data recieved 12582912
2025-01-22 11:52:44 - File data recieved 13107200
2025-01-22 11:52:44 - File aaa.zip was downloaded
2025-01-22 11:52:52 - Current used storage is 14.318
2025-01-22 11:52:52 - Got files
2025-01-22 11:52:52 - Got directories
2025-01-22 11:52:53 - Got files
2025-01-22 11:52:53 - Got directories
2025-01-22 11:52:53 - Current used storage is 14.318
2025-01-22 11:58:17 - Login was succesfull for user: a
2025-01-22 11:58:17 - File data recieved 0
2025-01-22 11:58:17 - Profile picture was recieved
2025-01-22 11:58:17 - Got files
2025-01-22 11:58:17 - Current used storage is 14.318
2025-01-22 11:58:17 - Got directories
2025-01-22 11:58:23 - Current used storage is 14.318
2025-01-22 11:58:23 - Got files
2025-01-22 11:58:23 - Got directories
2025-01-22 11:58:24 - Current used storage is 14.318
2025-01-22 11:58:24 - Got files
2025-01-22 11:58:24 - Got directories
2025-01-22 11:58:28 - Got files
2025-01-22 11:58:28 - Current used storage is 14.318
2025-01-22 11:58:28 - Got directories
2025-01-22 11:58:29 - Logout succesfull
2025-01-22 11:58:31 - Server return an error: 101 Cannot have an empty field
2025-01-22 11:58:33 - Server return an error: 101 Cannot have an empty field
2025-01-22 11:58:45 - Password reset code was sent to idanh3102@gmail.com
2025-01-22 11:59:01 - Password was reset for user: idanh3102@gmail.com, new password: Idan1234
2025-01-22 11:59:01 - Logout succesfull
2025-01-22 11:59:10 - Password reset code was sent to idanh3102@gmail.com
2025-01-22 11:59:14 - Password reset code was sent to idanh3102@gmail.com
2025-01-22 11:59:34 - Password reset code was sent to idanh3102@gmail.com
2025-01-22 15:47:53 - Server return an error: 024 Cookie is invalid
2025-01-22 15:48:06 - Server return an error: 003 Please check your password and email/username and try again.
2025-01-22 15:48:08 - Unhandled exception:
Traceback (most recent call last):
  File "C:\Users\idanh\Desktop\Cyber\My Projects\Final-Project\Main\client\modules\gui.py", line 232, in <lambda>
    self.login_button.clicked.connect(lambda: self.protocol.login(self.credi.text(), self.password.text(), self.remember.isChecked()))
                                                                                                           ^^^^^^^^^^^^^^^^^^^^^^^
AttributeError: 'bool' object has no attribute 'isChecked'
2025-01-22 15:48:22 - Unhandled exception:
Traceback (most recent call last):
  File "C:\Users\idanh\Desktop\Cyber\My Projects\Final-Project\Main\client\modules\gui.py", line 232, in <lambda>
    self.login_button.clicked.connect(lambda: self.protocol.login(self.credi.text(), self.password.text(), self.remember.isChecked()))
                                                                                                           ^^^^^^^^^^^^^^^^^^^^^^^
AttributeError: 'bool' object has no attribute 'isChecked'
2025-01-22 15:48:51 - Server return an error: 024 Cookie is invalid
2025-01-22 15:49:00 - Server return an error: 003 Please check your password and email/username and try again.
2025-01-22 15:49:04 - Unhandled exception:
Traceback (most recent call last):
  File "c:\Users\idanh\Desktop\Cyber\My Projects\Final-Project\Main\client\modules\gui.py", line 232, in <lambda>
    self.login_button.clicked.connect(lambda: self.protocol.login(self.credi.text(), self.password.text(), self.remember.isChecked()))
                                                                                                           ^^^^^^^^^^^^^^^^^^^^^^^
AttributeError: 'bool' object has no attribute 'isChecked'
2025-01-22 15:50:10 - Server return an error: 024 Cookie is invalid
2025-01-22 15:50:19 - Login was succesfull for user: Test
2025-01-22 15:50:19 - File data recieved 0
2025-01-22 15:50:20 - File data recieved 524288
2025-01-22 15:50:20 - Got files
2025-01-22 15:50:20 - Got directories
2025-01-22 15:50:20 - File data recieved 1048576
2025-01-22 15:50:21 - File data recieved 1572864
2025-01-22 15:50:21 - File data recieved 2097152
2025-01-22 15:50:21 - File data recieved 2621440
2025-01-22 15:50:22 - File data recieved 3145728
2025-01-22 15:50:22 - File data recieved 3670016
2025-01-22 15:50:22 - File data recieved 4194304
2025-01-22 15:50:23 - File data recieved 4718592
2025-01-22 15:50:23 - File data recieved 5242880
2025-01-22 15:50:24 - File data recieved 5767168
2025-01-22 15:50:24 - File data recieved 6291456
2025-01-22 15:50:24 - File data recieved 6815744
2025-01-22 15:50:24 - Current used storage is 0.0
2025-01-22 15:50:25 - File data recieved 7340032
2025-01-22 15:50:25 - File data recieved 7864320
2025-01-22 15:50:26 - File data recieved 8388608
2025-01-22 15:50:27 - File data recieved 8912896
2025-01-22 15:50:27 - File data recieved 9437184
2025-01-22 15:50:27 - Cookie recieved
2025-01-22 15:50:28 - File data recieved 9961472
2025-01-22 15:50:29 - File data recieved 10485760
2025-01-22 15:50:29 - File data recieved 11010048
2025-01-22 15:50:30 - File data recieved 11534336
2025-01-22 15:50:30 - File data recieved 12058624
2025-01-22 15:50:31 - File data recieved 12582912
2025-01-22 15:50:31 - File data recieved 13107200
2025-01-22 15:50:32 - File data recieved 13631488
2025-01-22 15:50:32 - File data recieved 14155776
2025-01-22 15:50:33 - File data recieved 14680064
2025-01-22 15:50:33 - File data recieved 15204352
2025-01-22 15:50:34 - File data recieved 15728640
2025-01-22 15:50:34 - File data recieved 16252928
2025-01-22 15:50:35 - File data recieved 16777216
2025-01-22 15:50:35 - File data recieved 17301504
2025-01-22 15:50:36 - File data recieved 17825792
2025-01-22 15:50:36 - File data recieved 18350080
2025-01-22 15:50:37 - File data recieved 18874368
2025-01-22 15:50:37 - File data recieved 19398656
2025-01-22 15:50:38 - File data recieved 19922944
2025-01-22 15:50:38 - File data recieved 20447232
2025-01-22 15:50:39 - File data recieved 20971520
2025-01-22 15:50:39 - File data recieved 21495808
2025-01-22 15:50:40 - File data recieved 22020096
2025-01-22 15:50:40 - File data recieved 22544384
2025-01-22 15:50:41 - File data recieved 23068672
2025-01-22 15:50:41 - File data recieved 23592960
2025-01-22 15:50:42 - File data recieved 24117248
2025-01-22 15:50:43 - File data recieved 24641536
2025-01-22 15:50:43 - File data recieved 25165824
2025-01-22 15:50:44 - File data recieved 25690112
2025-01-22 15:50:44 - File data recieved 26214400
2025-01-22 15:50:45 - File data recieved 26738688
2025-01-22 15:50:45 - File data recieved 27262976
2025-01-22 15:50:46 - File data recieved 27787264
2025-01-22 15:50:47 - File data recieved 28311552
2025-01-22 15:50:47 - File data recieved 28835840
2025-01-22 15:50:48 - File data recieved 29360128
2025-01-22 15:50:48 - File data recieved 29884416
2025-01-22 15:50:49 - File data recieved 30408704
2025-01-22 15:50:49 - File data recieved 30932992
2025-01-22 15:50:50 - File data recieved 31457280
2025-01-22 15:50:50 - File data recieved 31981568
2025-01-22 15:50:51 - File data recieved 32505856
2025-01-22 15:50:51 - File data recieved 33030144
2025-01-22 15:50:52 - File data recieved 33554432
2025-01-22 15:50:52 - File data recieved 34078720
2025-01-22 15:50:53 - File data recieved 34603008
2025-01-22 15:50:54 - File data recieved 35127296
2025-01-22 15:50:54 - File data recieved 35651584
2025-01-22 15:50:55 - File data recieved 36175872
2025-01-22 15:50:55 - File data recieved 36700160
2025-01-22 15:50:56 - File data recieved 37224448
2025-01-22 15:50:56 - File data recieved 37748736
2025-01-22 15:50:57 - File data recieved 38273024
2025-01-22 15:50:57 - File data recieved 38797312
2025-01-22 15:50:58 - File data recieved 39321600
2025-01-22 15:50:58 - File data recieved 39845888
2025-01-22 15:50:59 - File data recieved 40370176
2025-01-22 15:50:59 - File data recieved 40894464
2025-01-22 15:51:00 - File data recieved 41418752
2025-01-22 15:51:00 - File data recieved 41943040
2025-01-22 15:51:01 - File data recieved 42467328
2025-01-22 15:51:01 - File data recieved 42991616
2025-01-22 15:51:01 - File data recieved 43515904
2025-01-22 15:51:02 - File data recieved 44040192
2025-01-22 15:51:02 - File data recieved 44564480
2025-01-22 15:51:03 - Profile picture was recieved
2025-01-22 15:51:03 - Succesfully moved to
2025-01-22 15:51:03 - Got files
2025-01-22 15:51:03 - Got directories
2025-01-22 15:51:03 - Current used storage is 0.0
2025-01-22 15:51:06 - Succesfully moved to
2025-01-22 15:51:06 - Got files
2025-01-22 15:51:06 - Got directories
2025-01-22 15:51:06 - Current used storage is 0.0
2025-01-22 15:51:15 - start upload:
2025-01-22 15:51:15 - 7d6b4988dbed4df9a39e62f48b8a80e0
2025-01-22 15:51:15 - Profile icon started uploading succefully!
2025-01-22 15:51:15 - Got files
2025-01-22 15:51:15 - Got directories
2025-01-22 15:51:15 - Current used storage is 0.0
2025-01-22 15:51:16 - File 3813e258ef0543728bac758fafc18421 was uploaded
2025-01-22 15:51:16 - Got files
2025-01-22 15:51:16 - Got directories
2025-01-22 15:51:16 - Current used storage is 0.0
2025-01-22 15:51:34 - Succesfully moved to
2025-01-22 15:51:34 - Got files
2025-01-22 15:51:34 - Got directories
2025-01-22 15:51:34 - Current used storage is 0.0
2025-01-22 15:51:35 - Succesfully moved to
2025-01-22 15:51:35 - Got directories
2025-01-22 15:51:35 - Got files
2025-01-22 15:51:35 - Current used storage is 0.0
2025-01-22 15:51:37 - Logout succesfull
2025-01-22 15:51:51 - Login was succesfull for user: Test
2025-01-22 15:51:51 - Got files
2025-01-22 15:51:51 - File data recieved 0
2025-01-22 15:51:51 - Profile picture was recieved
2025-01-22 15:51:52 - Got directories
2025-01-22 15:51:52 - Current used storage is 0.0
2025-01-22 15:51:55 - Unhandled exception:
Traceback (most recent call last):
  File "c:\Users\idanh\Desktop\Cyber\My Projects\Final-Project\Main\client\modules\gui.py", line 73, in keyPressEvent
    self.delete()
    ^^^^^^^^^^^
AttributeError: 'MainWindow' object has no attribute 'delete'. Did you mean: 'deleted'?
2025-01-22 15:52:41 - Login was succesfull for user: Test
2025-01-22 15:52:41 - File data recieved 0
2025-01-22 15:52:41 - Profile picture was recieved
2025-01-22 15:52:41 - Got files
2025-01-22 15:52:41 - Got directories
2025-01-22 15:52:41 - Current used storage is 0.0
2025-01-22 15:52:44 - Succesfully deleted 1 files
2025-01-22 15:52:44 - File 3813e258ef0543728bac758fafc18421 was deleted!
2025-01-22 15:52:44 - Got files
2025-01-22 15:52:44 - Got directories
2025-01-22 15:52:44 - Current used storage is 0.0
2025-01-22 15:52:46 - Succesfully moved to
2025-01-22 15:52:46 - Got files
2025-01-22 15:52:46 - Got directories
2025-01-22 15:52:46 - Current used storage is 0.0
2025-01-22 15:52:47 - Succesfully moved to
2025-01-22 15:52:47 - Got files
2025-01-22 15:52:47 - Got directories
2025-01-22 15:52:47 - Current used storage is 0.0
2025-01-22 15:53:22 - Server return an error: 026 You don't have the permission to perform this action
2025-01-22 15:53:28 - Logout succesfull
2025-01-22 15:53:33 - Login was succesfull for user: a
2025-01-22 15:53:33 - File data recieved 0
2025-01-22 15:53:33 - Profile picture was recieved
2025-01-22 15:53:33 - Current used storage is 104.255
2025-01-22 15:53:33 - Got files
2025-01-22 15:53:33 - Got directories
2025-01-22 15:53:34 - Got files
2025-01-22 15:53:34 - Current used storage is 104.255
2025-01-22 15:53:34 - Got directories
2025-01-22 15:53:35 - Current used storage is 104.255
2025-01-22 15:53:35 - Got files
2025-01-22 15:53:35 - Got directories
2025-01-22 15:53:47 - Current used storage is 104.255
2025-01-22 15:53:47 - Got files
2025-01-22 15:53:47 - Got directories
2025-01-22 15:53:54 - Logout succesfull
2025-01-22 15:54:01 - Login was succesfull for user: Test
2025-01-22 15:54:01 - File data recieved 0
2025-01-22 15:54:01 - Profile picture was recieved
2025-01-22 15:54:01 - Got files
2025-01-22 15:54:01 - Got directories
2025-01-22 15:54:01 - Current used storage is 0.0
2025-01-22 15:54:01 - Unhandled exception:
Traceback (most recent call last):
  File "c:\Users\idanh\Desktop\Cyber\My Projects\Final-Project\Main\client\modules\gui.py", line 488, in scroll_changed
    if self.scroll_progress/total_scroll_height > 0.95 and len(self.directories) + len(self.files) < int(self.items_amount):
       ~~~~~~~~~~~~~~~~~~~~^~~~~~~~~~~~~~~~~~~~
ZeroDivisionError: division by zero
2025-01-22 15:54:05 - Succesfully moved to
2025-01-22 15:54:05 - Got files
2025-01-22 15:54:05 - Got directories
2025-01-22 15:54:05 - Current used storage is 0.0
2025-01-22 15:54:06 - Succesfully moved to
2025-01-22 15:54:06 - Got files
2025-01-22 15:54:06 - Got directories
2025-01-22 15:54:06 - Current used storage is 0.0
2025-01-22 15:54:11 - start upload:
2025-01-22 15:54:11 - 8dbae7d5e42e4e5fb852ada0d124b388
2025-01-22 15:54:11 - File app_log.txt started uploading
2025-01-22 15:54:11 - Got files
2025-01-22 15:54:11 - Got directories
2025-01-22 15:54:11 - Current used storage is 0.0
2025-01-22 15:54:12 - File app_log.txt was uploaded
2025-01-22 15:54:12 - Got files
2025-01-22 15:54:12 - Got directories
2025-01-22 15:54:12 - Current used storage is 0.175
2025-01-22 15:54:18 - Username changed to Test1
2025-01-22 15:54:26 - User testtest@gmail.com was deleted
2025-01-22 15:54:43 - Server return an error: 003 Please check your password and email/username and try again.
2025-01-22 15:54:46 - Login was succesfull for user: idan
2025-01-22 15:54:46 - File data recieved 0
2025-01-22 15:54:46 - Profile picture was recieved
2025-01-22 15:54:46 - Got files
2025-01-22 15:54:46 - Current used storage is 1.083
2025-01-22 15:54:46 - Got directories
2025-01-22 15:54:51 - Succesfully deleted 9 files
2025-01-22 15:54:51 - File hello a please see this file was deleted!
2025-01-22 15:54:51 - File vencord-settings-backup.jsonggjgjerigjeroigjreughjtiughtriughjturighjrtiuhjgrt was deleted!
2025-01-22 15:54:51 - File VSCode.css was deleted!
2025-01-22 15:54:51 - Got files
2025-01-22 15:54:51 - Folder dewdew was deleted!
2025-01-22 15:54:51 - Folder all - 1 was deleted!
2025-01-22 15:54:51 - File English Recording.mp3 was deleted!
2025-01-22 15:54:51 - Folder jj was deleted!
2025-01-22 15:54:51 - Folder idan was deleted!
2025-01-22 15:54:51 - Folder share was deleted!
2025-01-22 15:54:51 - Got directories
2025-01-22 15:54:51 - Current used storage is 1.083
2025-01-22 15:54:53 - Succesfully moved to
2025-01-22 15:54:53 - Got files
2025-01-22 15:54:53 - Current used storage is 1.083
2025-01-22 15:54:53 - Got directories
2025-01-22 15:54:54 - Succesfully moved to
2025-01-22 15:54:54 - Got files
2025-01-22 15:54:54 - Got directories
2025-01-22 15:54:54 - Current used storage is 1.083
2025-01-22 15:55:05 - start upload:
2025-01-22 15:55:05 - 5997d78407204feb824555477bdc6ffb
2025-01-22 15:55:05 - Profile icon started uploading succefully!
2025-01-22 15:55:05 - start upload:
2025-01-22 15:55:05 - fcfe7015404f4ccea65e9fdd914ac5a4
2025-01-22 15:55:05 - Profile icon started uploading succefully!
2025-01-22 15:55:05 - Got files
2025-01-22 15:55:05 - Got directories
2025-01-22 15:55:06 - File 285498b0131743c8a2a1617070b8d571 was uploaded
2025-01-22 15:55:06 - Current used storage is 1.083
2025-01-22 15:55:06 - Got directories
2025-01-22 15:55:06 - Got files
2025-01-22 15:55:06 - Current used storage is 1.083
2025-01-22 15:55:06 - File 285498b0131743c8a2a1617070b8d571 was uploaded
2025-01-22 15:55:09 - Succesfully moved to
2025-01-22 15:55:09 - Got files
2025-01-22 15:55:09 - Current used storage is 1.083
2025-01-22 15:55:09 - Got directories
2025-01-22 15:55:11 - Got files
2025-01-22 15:55:11 - Current used storage is 1.083
2025-01-22 15:55:11 - Got directories
2025-01-22 15:55:11 - Logout succesfull
2025-01-22 15:55:18 - Login was succesfull for user: idan
2025-01-22 15:55:18 - File data recieved 0
2025-01-22 15:55:18 - File data recieved 524288
2025-01-22 15:55:18 - File data recieved 1048576
2025-01-22 15:55:18 - Got files
2025-01-22 15:55:18 - File data recieved 1572864
2025-01-22 15:55:19 - Profile picture was recieved
2025-01-22 15:55:19 - Got directories
2025-01-22 15:55:19 - Current used storage is 1.083
2025-01-22 15:55:25 - start upload:
2025-01-22 15:55:25 - 0b4e7cbc84314cb696dbdbbaf8082ba4
2025-01-22 15:55:25 - start upload:
2025-01-22 15:55:25 - 8b0b3254013445f7bbbf1f58544de838
2025-01-22 15:55:25 - File app_log.txt started uploading
2025-01-22 15:55:25 - File 2A5EDC98-5EF3-4396-BFAE-47DF77EE2629.jpg started uploading
2025-01-22 15:55:25 - start upload:
2025-01-22 15:55:25 - 7e2d022d1f594b42857eb2a0c467fc47
2025-01-22 15:55:26 - Got directories
2025-01-22 15:55:26 - Got files
2025-01-22 15:55:26 - File 3c1753ee-d37c-455a-8de9-5a89f3c0e9e1.jpg started uploading
2025-01-22 15:55:26 - Current used storage is 1.083
2025-01-22 15:55:27 - File app_log.txt was uploaded
2025-01-22 15:55:27 - Got directories
2025-01-22 15:55:27 - Got files
2025-01-22 15:55:27 - Current used storage is 1.262
2025-01-22 15:55:27 - File 3c1753ee-d37c-455a-8de9-5a89f3c0e9e1.jpg was uploaded
2025-01-22 15:55:27 - File 2A5EDC98-5EF3-4396-BFAE-47DF77EE2629.jpg was uploaded
2025-01-22 15:55:36 - File app_log.txt was viewed
2025-01-22 15:55:36 - File viewing released
2025-01-22 15:55:39 - File data recieved 0
2025-01-22 15:55:44 - start upload:
2025-01-22 15:55:44 - e7ecd3333d244fdca14d8c152809e13c
2025-01-22 15:55:44 - start upload:
2025-01-22 15:55:44 - 681a954e08654c4f8d3d00370cff1374
2025-01-22 15:55:44 - start upload:
2025-01-22 15:55:44 - 25a0106e052c443c8d3df4d2fe4ff1c1
2025-01-22 15:55:44 - start upload:
2025-01-22 15:55:44 - b97b0dfbe6c249c5beea07faf1a5a24b
2025-01-22 15:55:44 - Got files
2025-01-22 15:55:44 - File app_log.txt started uploading
2025-01-22 15:55:44 - Got directories
2025-01-22 15:55:44 - File 2A5EDC98-5EF3-4396-BFAE-47DF77EE2629.jpg started uploading
2025-01-22 15:55:44 - File 3c1753ee-d37c-455a-8de9-5a89f3c0e9e1.jpg started uploading
2025-01-22 15:55:44 - File 3a87bbb0-760b-42db-90cb-baf7acc28b5a.jpg started uploading
2025-01-22 15:55:44 - Current used storage is 3.311
2025-01-22 15:55:45 - File app_log.txt was uploaded
2025-01-22 15:55:45 - Got files
2025-01-22 15:55:45 - Got directories
2025-01-22 15:55:45 - File 3c1753ee-d37c-455a-8de9-5a89f3c0e9e1.jpg was uploaded
2025-01-22 15:55:45 - File 2A5EDC98-5EF3-4396-BFAE-47DF77EE2629.jpg was uploaded
2025-01-22 15:55:46 - File 3a87bbb0-760b-42db-90cb-baf7acc28b5a.jpg was uploaded
2025-01-22 15:55:46 - Current used storage is 3.491
2025-01-22 15:56:54 - Server return an error: 024 Cookie is invalid
2025-01-22 15:57:04 - Login was succesfull for user: idan
2025-01-22 15:57:04 - File data recieved 0
2025-01-22 15:57:04 - File data recieved 524288
2025-01-22 15:57:04 - File data recieved 1048576
2025-01-22 15:57:04 - File data recieved 1572864
2025-01-22 15:57:04 - Profile picture was recieved
2025-01-22 15:57:04 - Got files
2025-01-22 15:57:04 - Got directories
2025-01-22 15:57:04 - Current used storage is 5.713
2025-01-22 15:57:04 - Cookie recieved
2025-01-22 15:57:07 - Succesfully deleted 7 files
2025-01-22 15:57:07 - File app_log.txt was deleted!
2025-01-22 15:57:07 - File 3c1753ee-d37c-455a-8de9-5a89f3c0e9e1.jpg was deleted!
2025-01-22 15:57:07 - File 2A5EDC98-5EF3-4396-BFAE-47DF77EE2629.jpg was deleted!
2025-01-22 15:57:07 - File 2A5EDC98-5EF3-4396-BFAE-47DF77EE2629.jpg was deleted!
2025-01-22 15:57:07 - File app_log.txt was deleted!
2025-01-22 15:57:07 - File 3c1753ee-d37c-455a-8de9-5a89f3c0e9e1.jpg was deleted!
2025-01-22 15:57:07 - Got directories
2025-01-22 15:57:07 - File 3a87bbb0-760b-42db-90cb-baf7acc28b5a.jpg was deleted!
2025-01-22 15:57:07 - Got files
2025-01-22 15:57:07 - Current used storage is 5.713
2025-01-22 15:57:13 - start upload:
2025-01-22 15:57:13 - d339c88c84b0427fa5983f73f9606302
2025-01-22 15:57:13 - Got directories
2025-01-22 15:57:13 - Got files
2025-01-22 15:57:13 - File app_log.txt started uploading
2025-01-22 15:57:13 - Current used storage is 5.713
2025-01-22 15:57:14 - File app_log.txt was uploaded
2025-01-22 15:57:14 - Got files
2025-01-22 15:57:14 - Got directories
2025-01-22 15:57:14 - Current used storage is 5.895
2025-01-22 15:57:18 - start upload:
2025-01-22 15:57:18 - 197ef52f46bc44fabb8fa20f9d10e03e
2025-01-22 15:57:18 - Got files
2025-01-22 15:57:18 - File client.pyw started uploading
2025-01-22 15:57:18 - Got directories
2025-01-22 15:57:18 - Current used storage is 5.895
2025-01-22 15:57:20 - File client.pyw was uploaded
2025-01-22 15:57:20 - Got files
2025-01-22 15:57:20 - Got directories
2025-01-22 15:57:20 - Current used storage is 5.899
2025-01-22 15:57:34 - start upload:
2025-01-22 15:57:34 - 615b2dff918b433faa16344bd04f3e8c
2025-01-22 15:57:34 - Profile icon started uploading succefully!
2025-01-22 15:57:34 - Got files
2025-01-22 15:57:34 - Got directories
2025-01-22 15:57:34 - Current used storage is 5.899
2025-01-22 15:57:35 - File 285498b0131743c8a2a1617070b8d571 was uploaded
2025-01-22 15:57:35 - Got directories
2025-01-22 15:57:35 - Got files
2025-01-22 15:57:35 - Current used storage is 5.899
2025-01-22 15:57:55 - start upload:
2025-01-22 15:57:55 - 3ec29ffc297e4da597e572009f5e6552
2025-01-22 15:57:55 - File Gali Game.exe started uploading
2025-01-22 15:57:58 - Succesfully moved to
2025-01-22 15:57:58 - Got files
2025-01-22 15:57:58 - Got directories
2025-01-22 15:57:58 - Current used storage is 5.899
2025-01-22 15:58:00 - Succesfully moved to
2025-01-22 15:58:00 - Got files
2025-01-22 15:58:00 - Got directories
2025-01-22 15:58:00 - Current used storage is 5.899
2025-01-22 15:58:03 - Got files
2025-01-22 15:58:03 - Got directories
2025-01-22 15:58:03 - Current used storage is 5.899
2025-01-22 15:58:03 - Got files
2025-01-22 15:58:03 - Got directories
2025-01-22 15:58:03 - Current used storage is 5.899
2025-01-22 15:58:07 - File Gali Game.exe was uploaded
2025-01-22 15:58:07 - Got files
2025-01-22 15:58:07 - Got directories
2025-01-22 15:58:07 - Current used storage is 40.336
2025-01-22 15:58:17 - File data recieved 0
2025-01-22 15:58:17 - File data recieved 524288
2025-01-22 15:58:18 - File data recieved 1048576
2025-01-22 15:58:18 - File data recieved 1572864
2025-01-22 15:58:18 - File data recieved 2097152
2025-01-22 15:58:19 - File data recieved 2621440
2025-01-22 15:58:19 - File data recieved 3145728
2025-01-22 15:58:19 - File data recieved 3670016
2025-01-22 15:58:19 - File data recieved 4194304
2025-01-22 15:58:20 - File data recieved 4718592
2025-01-22 15:58:20 - File data recieved 5242880
2025-01-22 15:58:20 - File data recieved 5767168
2025-01-22 15:58:21 - File data recieved 6291456
2025-01-22 15:58:21 - File data recieved 6815744
2025-01-22 15:58:22 - File data recieved 7340032
2025-01-22 15:58:22 - File data recieved 7864320
2025-01-22 15:58:22 - File data recieved 8388608
2025-01-22 15:58:23 - File data recieved 8912896
2025-01-22 15:58:23 - File data recieved 9437184
2025-01-22 15:58:24 - File data recieved 9961472
2025-01-22 15:58:24 - File data recieved 10485760
2025-01-22 15:58:25 - File data recieved 11010048
2025-01-22 15:58:25 - File data recieved 11534336
2025-01-22 15:58:25 - File data recieved 12058624
2025-01-22 15:58:26 - File data recieved 12582912
2025-01-22 15:58:26 - File data recieved 13107200
2025-01-22 15:58:27 - File data recieved 13631488
2025-01-22 15:58:27 - File data recieved 14155776
2025-01-22 15:58:28 - File data recieved 14680064
2025-01-22 15:58:28 - File data recieved 15204352
2025-01-22 15:58:29 - File data recieved 15728640
2025-01-22 15:58:29 - File data recieved 16252928
2025-01-22 15:58:30 - File data recieved 16777216
2025-01-22 15:58:30 - File data recieved 17301504
2025-01-22 15:58:31 - File data recieved 17825792
2025-01-22 15:58:32 - File data recieved 18350080
2025-01-22 15:58:32 - File data recieved 18874368
2025-01-22 15:58:33 - File data recieved 19398656
2025-01-22 15:58:33 - File data recieved 19922944
2025-01-22 15:58:34 - File data recieved 20447232
2025-01-22 15:58:34 - File data recieved 20971520
2025-01-22 15:58:35 - File data recieved 21495808
2025-01-22 15:58:36 - File data recieved 22020096
2025-01-22 15:58:36 - File data recieved 22544384
2025-01-22 15:58:37 - File data recieved 23068672
2025-01-22 15:58:37 - File data recieved 23592960
2025-01-22 15:58:38 - File data recieved 24117248
2025-01-22 15:58:38 - File data recieved 24641536
2025-01-22 15:58:39 - File data recieved 25165824
2025-01-22 15:58:39 - File data recieved 25690112
2025-01-22 15:58:40 - File data recieved 26214400
2025-01-22 15:58:40 - File data recieved 26738688
2025-01-22 15:58:41 - File data recieved 27262976
2025-01-22 15:58:41 - File data recieved 27787264
2025-01-22 15:58:42 - File data recieved 28311552
2025-01-22 15:58:42 - File data recieved 28835840
2025-01-22 15:58:43 - File data recieved 29360128
2025-01-22 15:58:43 - File data recieved 29884416
2025-01-22 15:58:44 - File data recieved 30408704
2025-01-22 15:58:44 - File data recieved 30932992
2025-01-22 15:58:45 - File data recieved 31457280
2025-01-22 15:58:45 - File data recieved 31981568
2025-01-22 15:58:46 - File data recieved 32505856
2025-01-22 15:58:46 - File data recieved 33030144
2025-01-22 15:58:47 - File data recieved 33554432
2025-01-22 15:58:47 - File data recieved 34078720
2025-01-22 15:58:47 - File Gali Game.exe was downloaded
2025-01-22 15:58:48 - Succesfully moved to
2025-01-22 15:58:48 - Got files
2025-01-22 15:58:48 - Current used storage is 40.336
2025-01-22 15:58:48 - Got directories
2025-01-22 15:58:51 - Succesfully moved to
2025-01-22 15:58:51 - Got files
2025-01-22 15:58:51 - Got directories
2025-01-22 15:58:51 - Current used storage is 40.336
2025-01-22 15:58:53 - Succesfully moved to
2025-01-22 15:58:53 - Got files
2025-01-22 15:58:53 - Current used storage is 40.336
2025-01-22 15:58:53 - Got directories
2025-01-22 15:58:57 - Current used storage is 40.336
2025-01-22 15:58:57 - Got files
2025-01-22 15:58:57 - Got directories
2025-01-22 15:59:01 - Got files
2025-01-22 15:59:01 - Current used storage is 40.336
2025-01-22 15:59:02 - Got directories
2025-01-22 15:59:06 - Succesfully deleted 20 files
2025-01-22 15:59:06 - File 3c1753ee-d37c-455a-8de9-5a89f3c0e9e1.jpg was deleted!
2025-01-22 15:59:06 - File 2A5EDC98-5EF3-4396-BFAE-47DF77EE2629.jpg was deleted!
2025-01-22 15:59:06 - File 2A5EDC98-5EF3-4396-BFAE-47DF77EE2629.jpg was deleted!
2025-01-22 15:59:06 - File vencord-settings-backup.jsonggjgjerigjeroigjreughjtiughtriughjturighjrtiuhjgrt was deleted!
2025-01-22 15:59:06 - File app_log.txt was deleted!
2025-01-22 15:59:06 - File hello a please see this file was deleted!
2025-01-22 15:59:06 - File 3c1753ee-d37c-455a-8de9-5a89f3c0e9e1.jpg was deleted!
2025-01-22 15:59:06 - File VSCode.css was deleted!
2025-01-22 15:59:06 - Folder dewdew was deleted!
2025-01-22 15:59:06 - Folder jj was deleted!
2025-01-22 15:59:06 - Got files
2025-01-22 15:59:06 - File app_log.txt was deleted!
2025-01-22 15:59:06 - Server return an error: 014 File not found
2025-01-22 15:59:06 - File English Recording.mp3 was deleted!
2025-01-22 15:59:06 - Server return an error: 001 General error
2025-01-22 15:59:06 - File 3a87bbb0-760b-42db-90cb-baf7acc28b5a.jpg was deleted!
2025-01-22 15:59:06 - Folder dwdqwdq was deleted!
2025-01-22 15:59:06 - Folder all - 1 was deleted!
2025-01-22 15:59:06 - Folder idan was deleted!
2025-01-22 15:59:06 - Folder delete was deleted!
2025-01-22 15:59:06 - Folder hi was deleted!
2025-01-22 15:59:06 - Server return an error: 001 General error
2025-01-22 15:59:06 - Current used storage is 39.772
2025-01-22 15:59:15 - Succesfully moved to
2025-01-22 15:59:15 - Got files
2025-01-22 15:59:15 - Got directories
2025-01-22 15:59:15 - Current used storage is 34.622
2025-01-22 15:59:17 - Succesfully moved to
2025-01-22 15:59:17 - Got files
2025-01-22 15:59:17 - Got directories
2025-01-22 15:59:17 - Current used storage is 34.622
2025-01-22 15:59:19 - Succesfully moved to
2025-01-22 15:59:19 - Got files
2025-01-22 15:59:19 - Got directories
2025-01-22 15:59:19 - Current used storage is 34.622
2025-01-22 15:59:22 - Succesfully deleted 3 files
2025-01-22 15:59:22 - File Gali Game.exe was deleted!
2025-01-22 15:59:22 - File app_log.txt was deleted!
2025-01-22 15:59:22 - Got directories
2025-01-22 15:59:22 - File client.pyw was deleted!
2025-01-22 15:59:22 - Got files
2025-01-22 15:59:22 - Current used storage is 34.622
2025-01-22 15:59:33 - Got files
2025-01-22 15:59:33 - Got directories
2025-01-22 15:59:33 - Current used storage is 34.622
2025-01-22 15:59:36 - Got files
2025-01-22 15:59:36 - Got directories
2025-01-22 15:59:36 - Current used storage is 34.622
2025-01-22 15:59:41 - Folder hello gays was created
2025-01-22 15:59:41 - Got files
2025-01-22 15:59:41 - Got directories
2025-01-22 15:59:41 - Current used storage is 34.622
2025-01-22 15:59:44 - Got files
2025-01-22 15:59:44 - Got directories
2025-01-22 15:59:44 - Current used storage is 34.622
2025-01-22 15:59:45 - Succesfully moved to hello gays\
2025-01-22 15:59:45 - Got files
2025-01-22 15:59:45 - Got directories
2025-01-22 15:59:45 - Current used storage is 34.622
2025-01-22 15:59:53 - start upload:
2025-01-22 15:59:53 - 635c3b932fae41ed8cfa27c1f0f3b4d9
2025-01-22 15:59:53 - start upload:
2025-01-22 15:59:53 - 7f5d4894217849cda7aca8021a2566a3
2025-01-22 15:59:53 - File Zoom_aMx6bGM4b7.png started uploading
2025-01-22 15:59:54 - File \u05de\u05d9\u05d5\u05df \u05d0\u05d9\u05e9\u05d9\u05d5\u05ea.txt started uploading
2025-01-22 15:59:54 - Got files
2025-01-22 15:59:54 - Got directories
2025-01-22 15:59:54 - Current used storage is 34.622
2025-01-22 15:59:55 - File Zoom_aMx6bGM4b7.png was uploaded
2025-01-22 15:59:55 - Got files
2025-01-22 15:59:55 - Got directories
2025-01-22 15:59:55 - File \u05de\u05d9\u05d5\u05df \u05d0\u05d9\u05e9\u05d9\u05d5\u05ea.txt was uploaded
2025-01-22 15:59:55 - Current used storage is 34.989
2025-01-22 15:59:59 - Succesfully moved to
2025-01-22 15:59:59 - Got files
2025-01-22 15:59:59 - Got directories
2025-01-22 15:59:59 - Current used storage is 34.989
2025-01-22 16:00:00 - Succesfully moved to hello gays\
2025-01-22 16:00:00 - Got files
2025-01-22 16:00:00 - Got directories
2025-01-22 16:00:00 - Current used storage is 34.989
2025-01-22 16:00:02 - File \u05de\u05d9\u05d5\u05df \u05d0\u05d9\u05e9\u05d9\u05d5\u05ea.txt was viewed
2025-01-22 16:00:02 - File viewing released
2025-01-22 16:00:03 - File data recieved 0
2025-01-22 16:00:07 - Got files
2025-01-22 16:00:07 - Got directories
2025-01-22 16:00:07 - Current used storage is 34.989
2025-01-22 16:00:08 - Got files
2025-01-22 16:00:08 - Got directories
2025-01-22 16:00:08 - Current used storage is 34.989
2025-01-22 16:00:11 - File \u05de\u05d9\u05d5\u05df \u05d0\u05d9\u05e9\u05d9\u05d5\u05ea.txt was viewed
2025-01-22 16:00:11 - File viewing released
2025-01-22 16:00:29 - File data recieved 0
2025-01-22 16:00:29 - start upload:
2025-01-22 16:00:29 - 9f2ef832362347fb9b9607b66bde865b
2025-01-22 16:00:30 - Got files
2025-01-22 16:00:30 - Got directories
2025-01-22 16:00:30 - Succefully saved changes to file 076a29c079ff42908786430f9f146936
2025-01-22 16:00:30 - Current used storage is 34.989
2025-01-22 16:00:30 - Got files
2025-01-22 16:00:30 - Got directories
2025-01-22 16:00:30 - Current used storage is 34.989
2025-01-22 16:00:31 - File 076a29c079ff42908786430f9f146936 was uploaded
2025-01-22 16:00:31 - Got directories
2025-01-22 16:00:31 - Got files
2025-01-22 16:00:31 - Current used storage is 34.989
2025-01-22 16:00:35 - File \u05de\u05d9\u05d5\u05df \u05d0\u05d9\u05e9\u05d9\u05d5\u05ea.txt was viewed
2025-01-22 16:00:35 - File viewing released
2025-01-22 16:00:36 - File data recieved 0
2025-01-22 16:00:37 - Succesfully moved to
2025-01-22 16:00:37 - Got files
2025-01-22 16:00:37 - Got directories
2025-01-22 16:00:37 - Current used storage is 34.989
2025-01-22 16:00:39 - Logout succesfull
2025-01-22 16:00:42 - Server acknowledged the exit message
2025-01-22 16:00:42 - Succefully exit
2025-01-22 16:09:58 - Traceback (most recent call last):
  File "c:\Users\idanh\Desktop\Cyber\My Projects\Final-Project\Main\client\modules\protocol.py", line 615, in send_data
    try: self.network.send_data_wrap(bdata, encryption)
         ^^^^^^^^^^^^^^^^^^^^^^^^^^^^^^^^^^^^^^^^^^^^^^
  File "c:\Users\idanh\Desktop\Cyber\My Projects\Final-Project\Main\client\modules\networking.py", line 44, in send_data_wrap
    encrypted_data = self.encryption(bdata, self.shared_secret)
                     ^^^^^^^^^^^^^^^^^^^^^^^^^^^^^^^^^^^^^^^^^^
TypeError: 'Encryption' object is not callable
2025-01-22 16:10:19 - Login was succesfull for user: idan
2025-01-22 16:10:19 - Got files
2025-01-22 16:10:19 - Got directories
2025-01-22 16:10:19 - File data recieved 0
2025-01-22 16:10:19 - Profile picture was recieved
2025-01-22 16:10:19 - Current used storage is 34.989
2025-01-22 16:10:21 - Got directories
2025-01-22 16:10:21 - Current used storage is 34.989
2025-01-22 16:10:21 - Got files
2025-01-22 16:10:24 - start upload:
2025-01-22 16:10:24 - 8decae4d8810463ab5e4450e3e192c52
2025-01-22 16:10:24 - File app_log.txt started uploading
2025-01-22 16:10:24 - Got files
2025-01-22 16:10:24 - Current used storage is 34.989
2025-01-22 16:10:24 - File app_log.txt was uploaded
2025-01-22 16:10:24 - Got directories
2025-01-22 16:10:24 - Got files
2025-01-22 16:10:24 - Got directories
2025-01-22 16:10:24 - Current used storage is 35.184
2025-01-22 16:10:27 - Got files
2025-01-22 16:10:27 - Got directories
2025-01-22 16:10:27 - Current used storage is 35.184
2025-01-22 16:10:30 - start upload:
2025-01-22 16:10:30 - d2ad0d0b706c4d33b272c9a616dc8dcf
